Workbook

Sheet Ozet
A1: ŞANLIURFA HRS 1. ETAP – ASANSÖR / SİNYALİZASYON / ELEKTRİFİKASYON BÜTÇE ÇALIŞMASI
A2: İKN 2026/1327584 • Teklif sahibi: ÖZVER İNŞAAT A.Ş. • Hazırlayan: MEP Center • 06.10.2026 • EUR, KDV hariç, montaj+test+devreye alma dahil (taşeron fiyatı), Şanlıurfa şantiye teslim. Miktarlar RFQ cetvelleri + idare cevapları (05.10.2026) ile düzeltilmiştir.
A4: Disiplin | B4: Cetvel sıraları | C4: Kalem bazlı bütçe (düzeltilmiş) EUR | D4: Risk payı % | E4: Önerilen bütçe EUR | F4: Önerilen bütçe USD | G4: Önerilen bütçe TL | H4: RFQ miktarlarıyla (düzeltmesiz) EUR | I4: Referans / teklif kıyası EUR | J4: Kıyas kaynağı | K4: Açıklama
A5: Asansör | B5: 364–365 | C5: ='Asansor'!$H$13 | D5: =Varsayimlar!$B$14 | E5: =C5*(1+D5) | F5: =E5*Varsayimlar!$B$4 | G5: =E5*Varsayimlar!$B$5 | H5: ='Asansor'!$H$14 | I5: =Teklifler!F5 | J5: En düşük teklif (TK Elevator) | K5: 13 asansör; Schindler + TK ortalaması (bakım hariç). Ref. kalem bazlı 647.200 €
A6: Sinyalizasyon + AVLS | B6: 228–235 | C6: ='Sinyal'!$H$102 | D6: =Varsayimlar!$B$15 | E6: =C6*(1+D6) | F6: =E6*Varsayimlar!$B$4 | G6: =E6*Varsayimlar!$B$5 | H6: ='Sinyal'!$H$103 | I6: =Teklifler!F7 | J6: Sistem bazlı ref. (makas başı) | K6: Point Link/CASCO 7,28 M€ (DAP, gümrük hariç) aykırı – kıyas dışı
A7: Elektrifikasyon – Katener | B7: 220–226 | C7: ='Katener'!$H$96 | D7: =Varsayimlar!$B$16 | E7: =C7*(1+D7) | F7: =E7*Varsayimlar!$B$4 | G7: =E7*Varsayimlar!$B$5 | H7: ='Katener'!$H$97 | I7: =Teklifler!F9 | J7: Sistem bazlı ref. (km başı) | K7: Direk temelleri inşaat kapsamında; lente yok; depo direkleri cetvel direk kalemlerinde
A8: Elektrifikasyon – Cer gücü / enerji temini | B8: 169–179, 187–189, 197, 200–210, 219, 227 (+TM UPS) | C8: ='Cer_Guc'!$H$128 | D8: =Varsayimlar!$B$17 | E8: =C8*(1+D8) | F8: =E8*Varsayimlar!$B$4 | G8: =E8*Varsayimlar!$B$5 | H8: ='Cer_Guc'!$H$129 | I8: =Teklifler!F11 | J8: Sistem bazlı ref. (5 TM; yalnız OG+trafo+DC) | K8: OG ring + TEİAŞ bağlantı kabloları (transe dahil), kompanzasyon, 5 cer TM, TM yardımcı sistemleri
A9: TOPLAM | C9: =SUM(C5:C8) | E9: =SUM(E5:E8) | F9: =SUM(F5:F8) | G9: =SUM(G5:G8) | H9: =SUM(H5:H8) | I9: =SUM(I5:I8)
A10: Elektrifikasyon ara toplamı (Katener + Cer gücü) | C10: =C7+C8 | E10: =E7+E8 | F10: =F7+F8 | G10: =G7+G8 | H10: =H7+H8
A12: CETVEL SIRASI BAZINDA DÖKÜM (risk payı hariç, EUR)
A13: Disiplin | B13: Sıra | C13: Kalem | D13: Tutar EUR
A14: Asansör | B14: 364 | C14: 2 Duraklı 13 Kişilik Asansör (12 adet – 4 üst geçit × 3) | D14: ='Asansor'!H5
A15: Asansör | B15: 365 | C15: 2 Duraklı 10 Kişilik 800 kg Asansör (D01 idari bina) | D15: ='Asansor'!H10
A16: Sinyalizasyon + AVLS | B16: 228 | C16: Sinyalizasyon Sistemi Tasarımı | D16: ='Sinyal'!H5
A17: Sinyalizasyon + AVLS | B17: 229 | C17: Hat Boyu Sinyalizasyon Sistemi | D17: ='Sinyal'!H7
A18: Sinyalizasyon + AVLS | B18: 230 | C18: Depo Sahası ve Tesisleri Sinyalizasyon Sistemi | D18: ='Sinyal'!H47
A19: Sinyalizasyon + AVLS | B19: 231 | C19: Araç Üstü Sinyalizasyon Sistemi | D19: ='Sinyal'!H66
A20: Sinyalizasyon + AVLS | B20: 232 | C20: Sinyalizasyon Merkez Donanımı & Sistem Yazılımları | D20: ='Sinyal'!H74
A21: Sinyalizasyon + AVLS | B21: 233 | C21: Araç Takip Sistemi (AVLS) – araç üstü ve saha | D21: ='Sinyal'!H88
A22: Sinyalizasyon + AVLS | B22: 234 | C22: Tramvay Araç Takip Sistemi Merkezi Donanımı ve Yazılımı | D22: ='Sinyal'!H97
A23: Sinyalizasyon + AVLS | B23: 235 | C23: Araç Takip Sistemi Tasarımı | D23: ='Sinyal'!H99
A24: Katener | B24: 220 | C24: Hat Boyu ve Depo Bağlantı Hatları Katener Sistemi | D24: ='Katener'!H5
A25: Katener | B25: 221 | C25: Depo Sahası ve Tesisleri Katener Sistemi | D25: ='Katener'!H42
A26: Katener | B26: 222 | C26: T1-A Tipi Katener Direği (114 adet) | D26: ='Katener'!H75
A27: Katener | B27: 223 | C27: T2-B Tipi Katener Direği (17 adet) | D27: ='Katener'!H79
A28: Katener | B28: 224 | C28: T2-B1 Tipi Katener Direği (4 adet) | D28: ='Katener'!H83
A29: Katener | B29: 225 | C29: T3-D Tipi Katener Direği (33 adet) | D29: ='Katener'!H87
A30: Katener | B30: 226 | C30: T3-C Tipi Katener Direği (60 adet) | D30: ='Katener'!H91
A31: Cer gücü | B31: 169 | C31: Güç Temini ve Cer Gücü Tasarımı | D31: ='Cer_Guc'!H5
A32: Cer gücü | B32: 170 | C32: OG Ring Şebekesi 3×1×240/25 mm² 20,3/35 kV Al XLPE | D32: ='Cer_Guc'!H8
A33: Cer gücü | B33: 171 | C33: TEİAŞ Bağlantısı 2×4×(1×400+35) mm² 20,3/35 kV – transe dahil | D33: ='Cer_Guc'!H16
A34: Cer gücü | B34: 172 | C34: Enerji Kalitesi ve Yönetimi Sistemi | D34: ='Cer_Guc'!H31
A35: Cer gücü | B35: 173 | C35: Ring Giriş/Çıkış 34,5 kV Şalt Panosu (12 hücre) | D35: ='Cer_Guc'!H43
A36: Cer gücü | B36: 174 | C36: Cer Trafo Besleme 34,5 kV Şalt Panosu (5 hücre) | D36: ='Cer_Guc'!H45
A37: Cer gücü | B37: 175 | C37: İç İhtiyaç Trafo Besleme 34,5 kV Şalt Panosu (6 hücre) | D37: ='Cer_Guc'!H49
A38: Cer gücü | B38: 176 | C38: Ölçü 34,5 kV Şalt Panosu | D38: ='Cer_Guc'!H53
A39: Cer gücü | B39: 177 | C39: TEİAŞ Giriş 34,5 kV Şalt Panosu (mevcut TM-4'te fider ilavesi) | D39: ='Cer_Guc'!H57
A40: Cer gücü | B40: 178 | C40: Hat TM İç İhtiyaç Trafosu 250 kVA (4 adet) | D40: ='Cer_Guc'!H59
A41: Cer gücü | B41: 179 | C41: Depo TM İç İhtiyaç Trafosu 2000 kVA (2 adet) | D41: ='Cer_Guc'!H61
A42: Cer gücü | B42: 187 | C42: Hat Trafo Binaları AG Ana Dağıtım Panoları (4 set) | D42: ='Cer_Guc'!H63
...

Sheet Varsayimlar
A1: VARSAYIMLAR (sarı hücreler değiştirilebilir; tüm sayfalar formülle bağlıdır)
A3: Parametre | B3: Değer | C3: Kaynak / açıklama
A4: EUR/USD kuru | B4: 1.146 | C4: 21.09.2026 piyasa kapanışı (USD/EUR 0,8723). Teklif günü TCMB/ECB kuru ile güncelleyin.
A5: EUR/TRY kuru | B5: 56.1 | C5: 20.09.2026 TCMB efektif satış ~56,11. Teklif günü kuru ile güncelleyin.
A6: Hat uzunluğu – RFQ kabulü (km) | B6: 6.56 | C6: Katener şartnamesi; RFQ cetvellerinde kullanıldı
A7: Hat uzunluğu – idare cevabı (km) | B7: 6.44 | C7: İdare cevabı 05.10.2026, soru 18
A8: Hat boyu uzunluk düzeltme oranı | B8: =B6/B5 | C8: Hat boyu iletken/kablo uzunluklarına uygulanır
A9: Araç sayısı – RFQ kabulü | B9: 15 | C9: Sinyal RFQ kabul 5
A10: Araç sayısı – idare cevabı | B10: 14 | C10: İdare cevabı soru 2 (araçlar ayrı ihale; arayüz yüklenicide)
A11: OG ring güzergahı – RFQ (m) | B11: 7000 | C11: Sıra 170 RFQ
A12: OG ring güzergahı – idare cevabı (m) | B12: 7964 | C12: İdare cevabı soru 21 (tüm kesitler)
A13: Galvanizli katener direği çeliği, imalat+galvaniz+dikim (EUR/kg) | B13: 2.2 | C13: Referans medyanı 1,80 €/kg (2013–2016 tramvay) + yerli üretim/montaj payı; Mitaş teklifi gelince güncelleyin
A14: Risk/belirsizlik payı – Asansör | B14: 0.05 | C14: 2 firma teklifi var, kapsam net
A15: Risk/belirsizlik payı – Sinyalizasyon + AVLS | B15: 0.15 | C15: Ayrı sinyal projesi yok; miktarlar öngörü ağırlıklı; tek teklif (Point Link) aykırı
A16: Risk/belirsizlik payı – Katener | B16: 0.1 | C16: Proje var; fiyatlar referans + tahmin
A17: Risk/belirsizlik payı – Cer gücü / enerji temini | B17: 0.1 | C17: Proje var; teklif yok (Best Transformer, Alfanar bütçe bekleniyor)
A18: Fiyat esası | B18: EUR, Ekim 2026, KDV hariç, Şanlıurfa şantiye teslim, montaj+test+devreye alma dahil (taşeron fiyatı)

Sheet Teklifler
A1: GELEN TEKLİFLER VE REFERANS KIYASLAR (06.10.2026 itibarıyla)
A3: Disiplin | B3: Firma | C3: Kapsam / not | D3: Tutar (orijinal) | E3: Para birimi | F3: Tutar (EUR) | G3: Birim fiyat (EUR) 1000 kg | H3: Birim fiyat (EUR) 800 kg | I3: Değerlendirme
A4: Asansör | B4: Schindler (Mert Can Oğlakkaya) | C4: 12 × 37.000 USD (işçilik dahil) + 1 × 800 kg 36.000 USD; bakım hariç | D4: 480000 | E4: USD | F4: =D4/Varsayimlar!$B$4 | G4: =37000/Varsayimlar!$B$4 | H4: =36000/Varsayimlar!$B$4 | I4: Şartnameye uygun kabul; bütçede kullanıldı
A5: Asansör | B5: TK Elevator (Betül Okay) | C5: 12 × (24.000 malzeme + 8.000 işçilik) + 1 × 30.200; anti-vandal CAT-2 | D5: 414200 | E5: EUR | F5: =D5 | G5: 32000 | H5: 30200 | I5: Şartnameye uygun kabul; bütçede kullanıldı
A6: Sinyalizasyon + AVLS | B6: Point Link / CASCO (Çin) | C6: Sıra 228–235; DAP şantiye; KDV ve gümrük hariç; AI asistan imzalı yanıt | D6: 7281784 | E6: EUR | F6: =D6 | I6: Referanslara göre ~2,3 kat yüksek; kalem dökümü alınmadan bütçeye esas alınmadı (üst sınır kıyası)
A7: Sinyalizasyon | B7: Referans – sistem bazlı (makas başı) | C7: İzmir tramvay H&K 64.862 €/makas, Eminönü Elektroline 46.638 €/makas; ort. 55.750 €/makas × 56 | D7: 3121990 | E7: EUR | F7: =D7 | I7: EM_Butce_Tahmini Sistem sayfası (EUR Ağu-2026)
A8: Sinyalizasyon | B8: Referans – kalem bazlı (fiyatı bulunan 5/8 ana kalem) | C8: 228, 229, 230, 231, 234 sıraları; 232, 233, 235 fiyatsız | D8: 1802246 | E8: EUR | F8: =D8 | I8: EM_Butce_Tahmini Ozet sayfası
A9: Katener | B9: Referans – sistem bazlı (hat-km başı) | C9: İzmir (Usluel, Siemens), Samsun (Usluel, BBR) ort. 356.767 €/km × 6,56 km | D9: 2340390 | E9: EUR | F9: =D9 | I9: EM_Butce_Tahmini Sistem sayfası
A10: Katener | B10: Referans – kalem bazlı (6/7 ana kalem) | C10: 220 için konsol, iletken, gergi; 221 kısmi; direkler kg bazlı | D10: 2590010 | E10: EUR | F10: =D10 | I10: EM_Butce_Tahmini Ozet sayfası
A11: Cer gücü | B11: Referans – sistem bazlı (TM başı) | C11: İzmir Siemens, Bursa Haluk/MET, Kocaeli; ort. 672.038 €/TM × 5 (OG+trafo+redresör+DC; kablo hariç) | D11: 3360189 | E11: EUR | F11: =D11 | I11: EM_Butce_Tahmini Sistem sayfası
A12: Asansör | B12: Referans – kalem bazlı (metro/tramvay asansör referansları medyanı) | C12: 1000 kg medyan 50.992 €, 800 kg 35.293 € | D12: 647200 | E12: EUR | F12: =D12 | G12: 50992 | H12: 35293 | I12: Metro referansları ağırlıklı; teklifler daha düşük
A14: Bekleyen / bütçe fiyatı istenen: Edoux, Adakon-Orona (asansör); Contirail/Mukan Rail (AVLS), Hanning & Kahl, Pintsch, INIT, Frauscher (sinyal); Mitaş, DeSA/Arthur Flury, Erbakır, Kambeton, La Farga, Galland, Revenga (katener); Best Transformer, Alfanar, Savronik, Alstom, Met-Eng, Tema (enerji).

Sheet Asansor
A1: ASANSÖR – Sıra 364–365 (13 asansör)
A2: Birim fiyatlar EUR, KDV hariç, montaj+test+devreye alma dahil. Sarı: değiştirilebilir. Turuncu miktar: idare cevabı (05.10.2026) ile RFQ'dan farklılaşan kalem. Kaynak kodları: REF = EM_Butce_Tahmini referans BF (geçmiş teklifler, HICP ile Ağu-2026); TEKLİF = 2026 firma teklifi; TAHMİN = mühendislik tahmini (referans yok).
A4: Sıra | B4: Poz | C4: Kalem / Alt kalem | D4: Birim | E4: Miktar (RFQ) | F4: Miktar (idare cevabına göre) | G4: Birim fiyat EUR (montaj dahil) | H4: Tutar EUR | I4: Fiyat kaynağı | J4: Düzeltme / not
A5: 364 | B5: 5010.A | C5: 2 Duraklı 13 Kişilik Asansör (12 adet – 4 üst geçit × 3) | E5: RFQ tutarı → | F5: =SUMPRODUCT(E6:E9,G6:G9) | H5: =SUM(H6:H9)
B6: 5010.A | C6: Asansör 1000 kg, 2 durak, MRL dişlisiz, VVVF, 1 m/s, cam+paslanmaz kabin – S09 Hızmalı Köprüsü | D6: adet | E6: 3 | F6: 3 | G6: =AVERAGE(Teklifler!$G$4,Teklifler!$G$5) | H6: =F6*G6 | I6: TEKLİF ort. (Schindler, TK Elevator) | J6: Bakım hariç; yeşil etiket, eğitim dahil
B7: 5010.A | C7: Asansör 1000 kg – S10 Balıklıgöl | D7: adet | E7: 3 | F7: 3 | G7: =AVERAGE(Teklifler!$G$4,Teklifler!$G$5) | H7: =F7*G7 | I7: TEKLİF ort.
B8: 5010.A | C8: Asansör 1000 kg – S11 Eyyüp Peygamber | D8: adet | E8: 3 | F8: 3 | G8: =AVERAGE(Teklifler!$G$4,Teklifler!$G$5) | H8: =F8*G8 | I8: TEKLİF ort.
B9: 5010.A | C9: Asansör 1000 kg – S12 Rasathane | D9: adet | E9: 3 | F9: 3 | G9: =AVERAGE(Teklifler!$G$4,Teklifler!$G$5) | H9: =F9*G9 | I9: TEKLİF ort.
A10: 365 | B10: 5010.B | C10: 2 Duraklı 10 Kişilik 800 kg Asansör (D01 idari bina) | E10: RFQ tutarı → | F10: =SUMPRODUCT(E11:E11,G11:G11) | H10: =SUM(H11:H11)
B11: 5010.B | C11: Asansör 800 kg, 2 durak (zemin/1. kat), MRL, VVVF, 1 m/s – D01 | D11: adet | E11: 1 | F11: 1 | G11: =AVERAGE(Teklifler!$H$4,Teklifler!$H$5) | H11: =F11*G11 | I11: TEKLİF ort.
C13: TOPLAM (idare cevaplarına göre düzeltilmiş) | H13: =H5+H10
C14: Karşılaştırma: RFQ miktarlarıyla aynı birim fiyatlardan tutar | H14: =F5+F10
C15: İdare cevaplarının net etkisi | H15: =H13-H14

Sheet Sinyal
A1: SİNYALİZASYON VE ARAÇ TAKİP (AVLS) – Sıra 228–235
A2: Birim fiyatlar EUR, KDV hariç, montaj+test+devreye alma dahil. Sarı: değiştirilebilir. Turuncu miktar: idare cevabı (05.10.2026) ile RFQ'dan farklılaşan kalem. Kaynak kodları: REF = EM_Butce_Tahmini referans BF (geçmiş teklifler, HICP ile Ağu-2026); TEKLİF = 2026 firma teklifi; TAHMİN = mühendislik tahmini (referans yok).
A4: Sıra | B4: Poz | C4: Kalem / Alt kalem | D4: Birim | E4: Miktar (RFQ) | F4: Miktar (idare cevabına göre) | G4: Birim fiyat EUR (montaj dahil) | H4: Tutar EUR | I4: Fiyat kaynağı | J4: Düzeltme / not
A5: 228 | B5: 3001 | C5: Sinyalizasyon Sistemi Tasarımı | E5: RFQ tutarı → | F5: =SUMPRODUCT(E6:E6,G6:G6) | H5: =SUM(H6:H6)
B6: 3001 | C6: Tasarım paketi: simülasyon, mimari/kilitleme tabloları, uygulama ve kablo projeleri, RAMS/Safety Case (SIL3/SIL2), ISA, test prosedürleri, KET izin dosyası | D6: set | E6: 1 | F6: 1 | G6: 207246 | H6: =F6*G6 | I6: REF (4 ref; seçilen BF) | J6: İdare: sıra 228 yalnız tasarım; ekipman 229–232'den
A7: 229 | B7: 3001.A | C7: Hat Boyu Sinyalizasyon Sistemi | E7: RFQ tutarı → | F7: =SUMPRODUCT(E8:E46,G8:G46) | H7: =SUM(H8:H46)
B8: 3001.A | C8: Elektrikli makas motoru (IP67, iç kilitli, uç konum dedektörlü) – ana hat | D8: takım | E8: 12 | F8: 16 | G8: 17785 | H8: =F8*G8 | I8: REF (CONTEC CSV24 / H&K HW61 / Elektroline TSH102: 15.255–19.316) | J8: İdare soru 3: ana hattaki tüm makaslar motorlu (+4, C4 kruvazmanı)
B9: 3001.A | C9: Makas motoru tahrik/dedeksiyon çubukları + dil kilidi seti | D9: takım | E9: 12 | F9: 16 | G9: 2969 | H9: =F9*G9 | I9: REF (Bombardier bars) | J9: Motor adedine bağlı
B10: 3001.A | C10: Manuel makas hareket mekanizması (ana hat) | D10: takım | E10: 4 | F10: 0 | G10: 5484 | H10: =F10*G10 | I10: REF | J10: İdare soru 3: manuel makas yok
B11: 3001.A | C11: Manuel makas konum izleme kutusu (IO/RTU) | D11: adet | E11: 1 | F11: 0 | G11: 3000 | H11: =F11*G11 | I11: TAHMİN | J11: Manuel makas kalmadı
B12: 3001.A | C12: Lokal kontrol ve kumanda kabini SKP (SIL3, GRP IP54) | D12: adet | E12: 3 | F12: 4 | G12: 88734 | H12: =F12*G12 | I12: REF (12 ref, medyan) | J12: C4 kruvazmanı motorlu olduğundan ilave kontrol birimi (temkinli kabul)
B13: 3001.A | C13: Sorgulayıcı (interrogator) birimi – SKP içi | D13: adet | E13: 4 | F13: 5 | G13: 6000 | H13: =F13*G13 | I13: TAHMİN | J13: SKP ile birlikte +1
B14: 3001.A | C14: Alıcı endüktif lup (güzergah talep) – makas bölgeleri | D14: adet | E14: 11 | F14: 11 | G14: 2814 | H14: =F14*G14 | I14: REF (4 ref)
B15: 3001.A | C15: Ray devresi / kütle dedektörü (makas kilitleme, bölge meşgul) | D15: adet | E15: 34 | F15: 34 | G15: 5614 | H15: =F15*G15 | I15: REF (4 ref)
B16: 3001.A | C16: Ana hat makas sinyal lambası 3 ışıklı LED + talep alındı lambası | D16: takım | E16: 11 | F16: 11 | G16: 5173 | H16: =F16*G16 | I16: REF (3 ref)
B17: 3001.A | C17: Sinyal lamba direği – makas bölgeleri | D17: adet | E17: 11 | F17: 11 | G17: 1200 | H17: =F17*G17 | I17: TAHMİN
B18: 3001.A | C18: Lokal talep anahtarı – makas bölgeleri | D18: adet | E18: 11 | F18: 11 | G18: 800 | H18: =F18*G18 | I18: TAHMİN
B19: 3001.A | C19: Karayolu kavşağı sinyalizasyon kontrol kabini TSP (tramvay öncelik) | D19: adet | E19: 5 | F19: 5 | G19: 8627 | H19: =F19*G19 | I19: REF (3 ref) | J19: Tramvay tarafı; kapsamda kalır
B20: 3001.A | C20: Alıcı endüktif lup (ON/OFF öncelik talep) – kavşaklar | D20: adet | E20: 24 | F20: 24 | G20: 2814 | H20: =F20*G20 | I20: REF (makas lupu BF)
B21: 3001.A | C21: Tramvay sinyal lambası 2 ışıklı LED – kavşaklar | D21: adet | E21: 12 | F21: 12 | G21: 3600 | H21: =F21*G21 | I21: TAHMİN (tek ref 7.268 aykırı)
B22: 3001.A | C22: Tramvay sinyal direği – kavşaklar | D22: adet | E22: 12 | F22: 12 | G22: 1200 | H22: =F22*G22 | I22: TAHMİN
B23: 3001.A | C23: Lokal kumanda anahtarı – kavşaklar | D23: adet | E23: 12 | F23: 12 | G23: 800 | H23: =F23*G23 | I23: TAHMİN
B24: 3001.A | C24: Yaya geçidi tramvay uyarı seti (flaşör + levha) | D24: adet | E24: 6 | F24: 6 | G24: 2500 | H24: =F24*G24 | I24: TAHMİN
B25: 3001.A | C25: Yaya geçidi uyarı kontrol kutusu + aktivasyon lupu | D25: takım | E25: 3 | F25: 3 | G25: 6000 | H25: =F25*G25 | I25: TAHMİN
B26: 3001.A | C26: TSKP karayolu kavşak kontrol cihazı | D26: adet | E26: 6 | F26: 0 | G26: 18000 | H26: =F26*G26 | I26: TAHMİN | J26: İdare soru 1: TSKP kapsam dışı
B27: 3001.A | C27: Karayolu trafik lambası 300'lük başüstü | D27: adet | E27: 20 | F27: 0 | G27: 900 | H27: =F27*G27 | I27: TAHMİN | J27: İdare soru 1: kapsam dışı
B28: 3001.A | C28: Karayolu trafik lambası 200'lük direk tipi | D28: adet | E28: 44 | F28: 0 | G28: 450 | H28: =F28*G28 | I28: TAHMİN | J28: İdare soru 1: kapsam dışı
B29: 3001.A | C29: Yaya lambası + yaya butonu | D29: takım | E29: 44 | F29: 0 | G29: 500 | H29: =F29*G29 | I29: TAHMİN | J29: İdare soru 1: kapsam dışı
B30: 3001.A | C30: Trafik lambası direği 3,5 m / 6 m konsollu | D30: adet | E30: 64 | F30: 0 | G30: 900 | H30: =F30*G30 | I30: TAHMİN | J30: İdare soru 1: kapsam dışı
B31: 3001.A | C31: Karayolu trafik sinyal kabloları (TSKP–lambalar) | D31: m | E31: 2695 | F31: 0 | G31: 6 | H31: =F31*G31 | I31: TAHMİN | J31: İdare soru 1: kapsam dışı
B32: 3001.A | C32: Karayolu sinyal kablo borusu HDPE Ø63 | D32: m | E32: 1210 | F32: 0 | G32: 4 | H32: =F32*G32 | I32: TAHMİN | J32: İdare soru 1: kapsam dışı
B33: 3001.A | C33: Lup besleme kablosu 2x2x1,0 ekranlı | D33: m | E33: 5468 | F33: =5468*Varsayimlar!$B$8 | G33: 4 | H33: =F33*G33 | I33: TAHMİN | J33: Hat boyu 6,44/6,56
B34: 3001.A | C34: Lup kablosu (hat yatağı içi iletken + koruma kanalı) | D34: adet | E34: 41 | F34: 41 | G34: 400 | H34: =F34*G34 | I34: TAHMİN
B35: 3001.A | C35: Ray devresi / dedektör kablosu 2x2x1,0 | D35: m | E35: 2673 | F35: =2673*Varsayimlar!$B$8 | G35: 4 | H35: =F35*G35 | I35: TAHMİN | J35: Hat boyu oranı
B36: 3001.A | C36: Makas motoru güç+kumanda kablosu 12x2,5 | D36: m | E36: 541 | F36: =ROUND(541*16/12,0) | G36: 9 | H36: =F36*G36 | I36: TAHMİN | J36: +4 motor oranında
B37: 3001.A | C37: Sinyal lambası kablosu 12x1,5 | D37: m | E37: 1348 | F37: =1348*Varsayimlar!$B$8 | G37: 7 | H37: =F37*G37 | I37: TAHMİN
B38: 3001.A | C38: Lokal kumanda anahtarı kablosu 7x1,5 | D38: m | E38: 1348 | F38: =1348*Varsayimlar!$B$8 | G38: 4.5 | H38: =F38*G38 | I38: TAHMİN
B39: 3001.A | C39: TSP/SKP–TSKP arayüz kablosu 19x1,5 | D39: m | E39: 198 | F39: 198 | G39: 10 | H39: =F39*G39 | I39: TAHMİN | J39: İdare: irtibat kablolaması kapsamda
B40: 3001.A | C40: Manuel makas konum kontağı kablosu 7x1,5 | D40: m | E40: 117 | F40: 0 | G40: 4.5 | H40: =F40*G40 | I40: TAHMİN | J40: Manuel makas yok
B41: 3001.A | C41: Yaya geçidi flaş lamba kablosu 3x1,5 | D41: m | E41: 264 | F41: 264 | G41: 2.5 | H41: =F41*G41 | I41: TAHMİN
...

Sheet Katener
A1: ELEKTRİFİKASYON (1) – KATENER – Sıra 220–226
A2: Birim fiyatlar EUR, KDV hariç, montaj+test+devreye alma dahil. Sarı: değiştirilebilir. Turuncu miktar: idare cevabı (05.10.2026) ile RFQ'dan farklılaşan kalem. Kaynak kodları: REF = EM_Butce_Tahmini referans BF (geçmiş teklifler, HICP ile Ağu-2026); TEKLİF = 2026 firma teklifi; TAHMİN = mühendislik tahmini (referans yok).
A4: Sıra | B4: Poz | C4: Kalem / Alt kalem | D4: Birim | E4: Miktar (RFQ) | F4: Miktar (idare cevabına göre) | G4: Birim fiyat EUR (montaj dahil) | H4: Tutar EUR | I4: Fiyat kaynağı | J4: Düzeltme / not
A5: 220 | B5: 2012.A | C5: Hat Boyu ve Depo Bağlantı Hatları Katener Sistemi | E5: RFQ tutarı → | F5: =SUMPRODUCT(E6:E41,G6:G41) | H5: =SUM(H6:H41)
B6: 2012.A | C6: Kontak teli 120 mm² Cu ETP (EN 50149, Ø13,2) – çekme dahil | D6: m | E6: 18748.5 | F6: =18748.5*Varsayimlar!$B$8 | G6: 18 | H6: =F6*G6 | I6: REF BF 16 €/m (31 ref) + montaj | J6: Hat boyu 6,44/6,56 (Erbakır teklifi bekleniyor)
B7: 2012.A | C7: Destek iletkeni 2×120 mm² Cu (iletken metresi) | D7: m | E7: 37497 | F7: =37497*Varsayimlar!$B$8 | G7: 16 | H7: =F7*G7 | I7: REF medyan 14 €/m + montaj | J7: Hat boyu oranı
B8: 2012.A | C8: Konsol hoban komplesi (çift yalıtımlı) – hat | D8: adet | E8: 358 | F8: 358 | G8: 1116 | H8: =F8*G8 | I8: REF medyan (22 ref)
B9: 2012.A | C9: Konsol hoban komplesi – depo bağlantı hattı | D9: adet | E9: 40 | F9: 40 | G9: 1116 | H9: =F9*G9 | I9: REF
B10: 2012.A | C10: Otomatik gerdirme tertibatı (ağırlıklı, kontak + 2 destek) | D10: takım | E10: 48 | F10: 48 | G10: 2500 | H10: =F10*G10 | I10: REF BF (49 ref)
B11: 2012.A | C11: Antişöminman (mid-point) düzenlemesi | D11: takım | E11: 24 | F11: 24 | G11: 1164 | H11: =F11*G11 | I11: REF BF (28 ref)
B12: 2012.A | C12: Ankraj lentesi teçhizatı (ana hat) | D12: takım | E12: 66 | F12: 0 | G12: 485 | H12: =F12*G12 | I12: REF | J12: İdare soru 6: ana hatta lente yok
B13: 2012.A | C13: Ankraj lentesi temeli – kazı (ana hat) | D13: m³ | E13: 1014.8 | F13: 0 | G13: 8 | H13: =F13*G13 | I13: TAHMİN | J13: İdare soru 6
B14: 2012.A | C14: Ankraj lentesi temeli – grobeton C16 | D14: m³ | E14: 48.1 | F14: 0 | G14: 75 | H14: =F14*G14 | I14: TAHMİN | J14: İdare soru 6
B15: 2012.A | C15: Ankraj lentesi temeli – C25/30 beton | D15: m³ | E15: 618.8 | F15: 0 | G15: 95 | H15: =F15*G15 | I15: TAHMİN | J15: İdare soru 6
B16: 2012.A | C16: Ankraj lentesi temeli – kalıp | D16: m² | E16: 990 | F16: 0 | G16: 15 | H16: =F16*G16 | I16: TAHMİN | J16: İdare soru 6
B17: 2012.A | C17: Ankraj lentesi temeli – donatı B500C | D17: kg | E17: 37125 | F17: 0 | G17: 0.9 | H17: =F17*G17 | I17: TAHMİN | J17: İdare soru 6
B18: 2012.A | C18: Ankraj lentesi temeli – ankraj çubuğu/gömme plaka M36 | D18: takım | E18: 66 | F18: 0 | G18: 250 | H18: =F18*G18 | I18: TAHMİN | J18: İdare soru 6
B19: 2012.A | C19: Ankraj lentesi temeli – geri dolgu | D19: m³ | E19: 348 | F19: 0 | G19: 6 | H19: =F19*G19 | I19: TAHMİN | J19: İdare soru 6
B20: 2012.A | C20: Ankraj direk başı bağlantı (ankraj konsolu, gergi klemensi) | D20: adet | E20: 78 | F20: 78 | G20: 600 | H20: =F20*G20 | I20: TAHMİN | J20: Lentesiz ankraj: T3-D direkleri
B21: 2012.A | C21: Hava aralıklı overlap (mekanik, izolesiz) | D21: adet | E21: 12 | F21: 12 | G21: 3000 | H21: =F21*G21 | I21: TAHMİN
B22: 2012.A | C22: Hava aralıklı izoleli seksiyon overlap (TM önü) | D22: adet | E22: 10 | F22: 10 | G22: 4000 | H22: =F22*G22 | I22: TAHMİN
B23: 2012.A | C23: Makas bölgesi hava makası | D23: adet | E23: 16 | F23: 16 | G23: 2500 | H23: =F23*G23 | I23: TAHMİN
B24: 2012.A | C24: Kruvazman katener kesişmesi | D24: adet | E24: 2 | F24: 2 | G24: 5000 | H24: =F24*G24 | I24: TAHMİN
B25: 2012.A | C25: Yaylı gerdirme tertibatı (makas diyagonalleri) | D25: takım | E25: 12 | F25: 12 | G25: 1481 | H25: =F25*G25 | I25: REF BF (10 ref)
B26: 2012.A | C26: Seksiyon izolatörü ünitesi | D26: adet | E26: 8 | F26: 8 | G26: 2070 | H26: =F26*G26 | I26: REF BF (21 ref) | J26: DeSA / Arthur Flury teklifi bekleniyor
B27: 2012.A | C27: Motorlu yük ayırıcı 4000 A DC, direk tipi, SCADA arabirimli | D27: adet | E27: 13 | F27: 13 | G27: 6000 | H27: =F27*G27 | I27: REF medyan 4.825 + motor tahrik payı
B28: 2012.A | C28: Aşırı gerilim koruyucu VLD (ray–direk) | D28: adet | E28: 13 | F28: 13 | G28: 594 | H28: =F28*G28 | I28: REF medyan (5 ref)
B29: 2012.A | C29: Besleme (fider) bağlantı düzeneği (bara izolatörü, 1×300 çıkış) | D29: takım | E29: 16 | F29: 16 | G29: 1500 | H29: =F29*G29 | I29: TAHMİN
B30: 2012.A | C30: Parafudr 1 kV DC 10 kA + toprak elektrodu | D30: takım | E30: 20 | F30: 20 | G30: 744 | H30: =F30*G30 | I30: REF medyan (4 ref)
B31: 2012.A | C31: Akım köprüsü 95 mm² örgülü Cu | D31: adet | E31: 59 | F31: 59 | G31: 461 | H31: =F31*G31 | I31: REF
B32: 2012.A | C32: Elektriksel jumper seti 95 mm² | D32: adet | E32: 44 | F32: 44 | G32: 299 | H32: =F32*G32 | I32: REF
B33: 2012.A | C33: 95 mm² örgülü esnek Cu iletken | D33: m | E33: 339.9 | F33: 339.9 | G33: 25 | H33: =F33*G33 | I33: TAHMİN
B34: 2012.A | C34: Gömülü destek iletkeni 150 mm² Cu | D34: m | E34: 246.4 | F34: 246.4 | G34: 35 | H34: =F34*G34 | I34: TAHMİN
B35: 2012.A | C35: Destek iletkeni ekleri, pabuçlar, direk çıkış aparatları | D35: adet | E35: 16 | F35: 16 | G35: 150 | H35: =F35*G35 | I35: TAHMİN
B36: 2012.A | C36: Tünel/köprü taşıyıcı destek elemanı | D36: adet | E36: 2 | F36: 2 | G36: 2000 | H36: =F36*G36 | I36: TAHMİN
B37: 2012.A | C37: Direk numaralandırma levhası | D37: adet | E37: 228 | F37: 228 | G37: 37 | H37: =F37*G37 | I37: REF (3 ref)
B38: 2012.A | C38: Ayırıcı motor enerji kablosu 3×2,5 NYY | D38: m | E38: 935 | F38: 935 | G38: 4 | H38: =F38*G38 | I38: TAHMİN
... B40: 2012.A | C40: Katener uygulama projesi, EN 50119 hesapları, direk statiği | D40: set | E40: 1 | F40: 1 | G40: 47158 | H40: =F40*G40 | I40: REF medyan (4 ref)
B41: 2012.A | C41: Test, ölçüm, enerjilendirme, devreye alma; 2 yıllık yedek parça | D41: set | E41: 1 | F41: 1 | G41: 60000 | H41: =F41*G41 | I41: TAHMİN | J41: İdare: yedek parça listesi bağlayıcı (sıra 384)
A42: 221 | B42: 2012.B | C42: Depo Sahası ve Tesisleri Katener Sistemi | E42: RFQ tutarı → | F42: =SUMPRODUCT(E43:E74,G43:G74) | H42: =SUM(H43:H74)
...

Sheet Cer_Guc
A1: ELEKTRİFİKASYON (2) – CER GÜCÜ / ENERJİ TEMİNİ (5 TM, OG ring, TEİAŞ bağlantısı)
A2: Birim fiyatlar EUR, KDV hariç, montaj+test+devreye alma dahil. Sarı: değiştirilebilir. Turuncu miktar: idare cevabı (05.10.2026) ile RFQ'dan farklılaşan kalem. Kaynak kodları: REF = EM_Butce_Tahmini referans BF (geçmiş teklifler, HICP ile Ağu-2026); TEKLİF = 2026 firma teklifi; TAHMİN = mühendislik tahmini (referans yok).
A4: Sıra | B4: Poz | C4: Kalem / Alt kalem | D4: Birim | E4: Miktar (RFQ) | F4: Miktar (idare cevabına göre) | G4: Birim fiyat EUR (montaj dahil) | H4: Tutar EUR | I4: Fiyat kaynağı | J4: Düzeltme / not
A5: 169 | B5: 2001 | C5: Güç Temini ve Cer Gücü Tasarımı | E5: RFQ tutarı → | F5: =SUMPRODUCT(E6:E7,G6:G7) | H5: =SUM(H6:H7)
B6: 2001 | C6: Uygulama projeleri (OG ring, TEİAŞ bağlantısı, 5 TM), cer gücü simülasyonu, kısa devre/selektivite, topraklama ve kaçak akım (EN 50122), kompanzasyon raporları, as-built | D6: set | E6: 1 | F6: 1 | G6: 150000 | H6: =F6*G6 | I6: REF (metro: 133.738–620.171; tramvay ölçeğine indirildi)
B7: 2001 | C7: DEDAŞ/TEİAŞ bağlantı projesi onayı ve kurum masrafları | D7: set | E7: 1 | F7: 1 | G7: 40000 | H7: =F7*G7 | I7: TAHMİN
A8: 170 | B8: 2002.A | C8: OG Ring Şebekesi 3×1×240/25 mm² 20,3/35 kV Al XLPE | E8: RFQ tutarı → | F8: =SUMPRODUCT(E9:E15,G9:G15) | H8: =SUM(H9:H15)
B9: 2002.A | C9: YAXC7V-R (NA2XSY) 1×240/25 Al XLPE LSHF tek damar kablo – çekme dahil | D9: m | E9: 21000 | F9: =3*Varsayimlar!$B$12 | G9: 14 | H9: =F9*G9 | I9: REF (Prysmian 1×400 15 €/m; Haluk 1×150 11 €/m) | J9: İdare soru 21: güzergah 7.964 m
B10: 2002.A | C10: 36 kV 1×240 kablo başlığı | D10: adet | E10: 24 | F10: 24 | G10: 450 | H10: =F10*G10 | I10: TAHMİN
B11: 2002.A | C11: 36 kV 1×240 ek mufu | D11: adet | E11: 33 | F11: =ROUND(33*Varsayimlar!$B$12/Varsayimlar!$B$11,0) | G11: 400 | H11: =F11*G11 | I11: TAHMİN | J11: Güzergah oranında
B12: 2002.A | C12: Trefoil kelepçe / kanal içi askı | D12: adet | E12: 6500 | F12: =ROUND(6500*Varsayimlar!$B$12/Varsayimlar!$B$11,0) | G12: 6 | H12: =F12*G12 | I12: TAHMİN | J12: Güzergah oranında
B13: 2002.A | C13: Yangın durdurucu (TM geçişleri) | D13: adet | E13: 10 | F13: 10 | G13: 200 | H13: =F13*G13 | I13: TAHMİN
B14: 2002.A | C14: Kablo etiket / güzergah markörü | D14: adet | E14: 140 | F14: =ROUND(140*Varsayimlar!$B$12/Varsayimlar!$B$11,0) | G14: 15 | H14: =F14*G14 | I14: TAHMİN
B15: 2002.A | C15: OG kablo saha testleri (VLF, kılıf) | D15: set | E15: 4 | F15: 4 | G15: 3000 | H15: =F15*G15 | I15: TAHMİN
A16: 171 | B16: 2002.B | C16: TEİAŞ Bağlantısı 2×4×(1×400+35) mm² 20,3/35 kV – transe dahil | E16: RFQ tutarı → | F16: =SUMPRODUCT(E17:E30,G17:G30) | H16: =SUM(H17:H30)
B17: 2002.B | C17: YAXC7V-R 1×400/35 Al XLPE zırhlı LSHF – çekme dahil | D17: m | E17: 35424 | F17: 35424 | G17: 20 | H17: =F17*G17 | I17: REF (Prysmian 15 €/m malzeme) + çekme | J17: İdare: 8.856 m × 4 kablo – uyumlu
B18: 2002.B | C18: 36 kV 1×400 kablo başlığı | D18: adet | E18: 16 | F18: 16 | G18: 600 | H18: =F18*G18 | I18: TAHMİN
B19: 2002.B | C19: 36 kV 1×400 ek mufu | D19: adet | E19: 68 | F19: 68 | G19: 550 | H19: =F19*G19 | I19: TAHMİN
B20: 2002.B | C20: Kablo kanalı kazısı 0,80×1,40 m | D20: m³ | E20: 9919 | F20: 9919 | G20: 8 | H20: =F20*G20 | I20: TAHMİN
B21: 2002.B | C21: HDPE/koruge boru Ø160 (her damar ayrı) | D21: m | E21: 38966.4 | F21: 38966.4 | G21: 6 | H21: =F21*G21 | I21: TAHMİN
B22: 2002.B | C22: Yol geçişleri yedek boş boru Ø160 | D22: m | E22: 4383.72 | F22: 4383.72 | G22: 6 | H22: =F22*G22 | I22: TAHMİN
B23: 2002.B | C23: Dolgu kumu | D23: m³ | E23: 3542 | F23: 3542 | G23: 18 | H23: =F23*G23 | I23: TAHMİN
B24: 2002.B | C24: Harman tuğlası | D24: adet | E24: 44280 | F24: 44280 | G24: 0.25 | H24: =F24*G24 | I24: TAHMİN
B25: 2002.B | C25: Plastik ikaz bandı | D25: m | E25: 19483.2 | F25: 19483.2 | G25: 0.3 | H25: =F25*G25 | I25: TAHMİN
B26: 2002.B | C26: C14 koruma betonu | D26: m³ | E26: 709 | F26: 709 | G26: 75 | H26: =F26*G26 | I26: TAHMİN
B27: 2002.B | C27: Yol/kaldırım kaplamasının eski haline getirilmesi | D27: m² | E27: 6200 | F27: 6200 | G27: 25 | H27: =F27*G27 | I27: TAHMİN
B28: 2002.B | C28: Kazı fazlası nakli | D28: m³ | E28: 4430 | F28: 4430 | G28: 6 | H28: =F28*G28 | I28: TAHMİN
B29: 2002.B | C29: Güzergah işaret taşı | D29: adet | E29: 180 | F29: 180 | G29: 30 | H29: =F29*G29 | I29: TAHMİN
B30: 2002.B | C30: OG kablo saha testleri | D30: set | E30: 2 | F30: 2 | G30: 4000 | H30: =F30*G30 | I30: TAHMİN
A31: 172 | B31: 2003 | C31: Enerji Kalitesi ve Yönetimi Sistemi | E31: RFQ tutarı → | F31: =SUMPRODUCT(E32:E42,G32:G42) | H31: =SUM(H32:H42)
B32: 2003 | C32: AG tristörlü kompanzasyon kademesi 50 kVAr 690 V | D32: adet | E32: 12 | F32: 12 | G32: 1500 | H32: =F32*G32 | I32: TAHMİN
B33: 2003 | C33: AG tristörlü kompanzasyon kademesi 25 kVAr 690 V | D33: adet | E33: 8 | F33: 8 | G33: 1000 | H33: =F33*G33 | I33: TAHMİN
B34: 2003 | C34: Kompanzasyon panosu (röle, Modbus, fan) – her TM 1 | D34: adet | E34: 5 | F34: 5 | G34: 6000 | H34: =F34*G34 | I34: TAHMİN
B35: 2003 | C35: MCCB 3×250 A + besleme kablosu 3×70 | D35: set | E35: 1 | F35: 1 | G35: 12300 | H35: =F35*G35 | I35: TAHMİN | J35: 10 MCCB + 143 m kablo
B36: 2003 | C36: OG şönt reaktör sistemi (TM-4 çıkışı) | D36: set | E36: 1 | F36: 1 | G36: 60000 | H36: =F36*G36 | I36: TAHMİN
B37: 2003 | C37: 36 kV 630 A kesicili kompanzasyon fider hücresi | D37: adet | E37: 1 | F37: 1 | G37: 28000 | H37: =F37*G37 | I37: REF (36 kV kesicili hücre)
B38: 2003 | C38: 34,5/0,4 kV 630 kVA kuru tip kompanzasyon trafosu | D38: adet | E38: 1 | F38: 1 | G38: 18000 | H38: =F38*G38 | I38: REF (Aktif 630 kVA 22.231 Al)
B39: 2003 | C39: Enerji kalite kaydedicisi Class A | D39: adet | E39: 5 | F39: 5 | G39: 4000 | H39: =F39*G39 | I39: TAHMİN
B40: 2003 | C40: AG enerji analizörü + Modbus ağ geçidi | D40: set | E40: 1 | F40: 1 | G40: 12400 | H40: =F40*G40 | I40: TAHMİN | J40: 6 analizör + 11 gateway
B41: 2003 | C41: Enerji yönetim yazılımı (ISO 50001) + TCC operatör | D41: set | E41: 1 | F41: 1 | G41: 25000 | H41: =F41*G41 | I41: TAHMİN
...

Sheet Idare_Duzeltme
A1: İDARE CEVAPLARI (05.10.2026) – BU BÜTÇEYE UYGULANAN DÜZELTMELER
A3: No | B3: Konu | C3: RFQ kabulü | D3: İdare cevabı | E3: Bütçeye etkisi | F3: Sayfa
A4: 1 | B4: Kavşak sinyal (229) | C4: TSKP + 64 trafik lambası + 64 direk + 2.695 m kablo dahil | D4: TSKP ve lambalar kapsam dışı; irtibat kablolaması kapsamda | E4: Düşüldü (TSP, lup, arayüz kablosu kalır) | F4: Sinyal
A5: 2 | B5: Araç adedi (231, 233) | C5: 15 araç | D5: 14 araç; araçlar ayrı ihale | E5: Araç başı kalemler 14'e indirildi | F5: Sinyal
A6: 3 | B6: Ana hat makasları | C6: 12 motorlu + 4 manuel | D6: Tüm makaslar motorlu | E6: +4 motor, +çubuk seti, +1 SKP (temkinli); manuel kalemler sıfır | F6: Sinyal
A7: 4 | B7: Depo makasları | C7: 20 motorlu + 20 manuel | D7: Tamamı motorlu | E7: +20 motor, +20 lamba, +16 dedektör, kablolar ×2; manuel sıfır | F7: Sinyal
A8: 6 | B8: Ana hat lentesi | C8: 66 lente + 68 temel | D8: Kullanılmayacak | E8: Lente teçhizatı ve temelleri düşüldü | F8: Katener
A9: 7 | B9: Depo direkleri | C9: 221 setinde 77 direk + temeller | D9: Cetvel direk kalemleri + sıra 13 | E9: Depo direk/temel kalemleri düşüldü (çift sayım) | F9: Katener
A10: 11 | B10: İstasyon UPS | C10: 2 saat | D10: İstasyon 20 dk; TM 2 saat | E10: Bu bütçede yalnız TM UPS'leri var (2 saat korundu) | F10: Cer_Guc
A11: 17 | B11: Mevcut sistem entegrasyonu | C11: Dahil | D11: Mevcut sistem yok | E11: Düşüldü | F11: Sinyal
A12: 18 | B12: Hat uzunluğu | C12: 6,56 km | D12: 6,44 km | E12: Hat boyu iletken/kablolar × 0,9817 | F12: Katener, Sinyal
A13: 21 | B13: OG ring (170) | C13: 7.000 m | D13: Tüm kesitler 7.964 m | E13: Kablo, muf, kelepçe güzergah oranında artırıldı | F13: Cer_Guc
A14: 22 | B14: TEİAŞ kablosu (171) | C14: 4 kablo/güzergah, 35.424 m | D14: Aynı | E14: Değişiklik yok | F14: Cer_Guc
A15: — | B15: İç ihtiyaç trafoları | C15: Belirtilmemişti | D15: Cu/Cu sargı zorunlu | E15: 250 / 2000 kVA trafolar Cu/Cu fiyatlandı | F15: Cer_Guc
A16: — | B16: Sıra 228 | C16: Tasarım | D16: Yalnız tasarım; ekipman 229–232 | E16: Uyumlu | F16: Sinyal
A17: — | B17: Garanti / yedek parça | C17: — | D17: 24 ay; 2 yıllık yedek parça sıra 384'ten | E17: Katener test kalemine yedek parça payı dahil; sinyal yedekleri sıra 384'te | F17: —
