Workbook

Sheet Ozet
A1: ŞANLIURFA HRS 1. ETAP – MEP BÜTÇE ÇALIŞMASI (ELEKTRİK, MEKANİK, ASANSÖR, SİNYALİZASYON, ELEKTRİFİKASYON)
A2: İKN 2026/1327584 • Teklif sahibi: ÖZVER İNŞAAT A.Ş. • Hazırlayan: MEP Center • 06.10.2026 • EUR, KDV hariç, montaj+test+devreye alma dahil (taşeron fiyatı), Şanlıurfa şantiye teslim. Miktarlar RFQ cetvelleri + idare cevapları (05.10.2026) ile düzeltilmiştir.
A4: Disiplin | B4: Kapsam | C4: Kalem bazlı bütçe EUR | D4: Risk payı EUR | E4: Önerilen bütçe EUR | F4: Önerilen bütçe USD | G4: Önerilen bütçe TL | H4: Pay % | I4: RFQ cetvel miktarlarıyla (şişirmeli) EUR | J4: Referans / teklif kıyası EUR | K4: Teklife dayanan % | L4: Geçmiş teklif uyarlaması % | M4: Mühendislik tahmini %
A5: 1 ELEKTRİK | B5: AG tesisat, aydınlatma, yangın ihbar, topraklama, kontrol-haberleşme, SCADA | C5: =SUMIF($A$15:$A$21,$A5,D$15:D$21) | D5: =E5-C5 | E5: =SUMIF($A$15:$A$21,$A5,F$15:F$21) | F5: =E5*Varsayimlar!$B$4 | G5: =E5*Varsayimlar!$B$5 | H5: =E5/$E$10 | I5: =SUMIF($A$15:$A$21,$A5,G$15:G$21) | J5: =SUMIF($A$15:$A$21,$A5,H$15:H$21) | K5: =IF(C5=0,0,SUMIF($A$15:$A$21,$A5,K$15:K$21)/C5) | L5: =IF(C5=0,0,SUMIF($A$15:$A$21,$A5,L$15:L$21)/C5) | M5: =IF(C5=0,0,SUMIF($A$15:$A$21,$A5,M$15:M$21)/C5)
A6: 2 MEKANİK | B6: HVAC, yangın söndürme, drenaj, sıhhi tesisat, basınçlı hava | C6: =SUMIF($A$15:$A$21,$A6,D$15:D$21) | D6: =E6-C6 | E6: =SUMIF($A$15:$A$21,$A6,F$15:F$21) | F6: =E6*Varsayimlar!$B$4 | G6: =E6*Varsayimlar!$B$5 | H6: =E6/$E$10 | I6: =SUMIF($A$15:$A$21,$A6,G$15:G$21) | J6: =SUMIF($A$15:$A$21,$A6,H$15:H$21) | K6: =IF(C6=0,0,SUMIF($A$15:$A$21,$A6,K$15:K$21)/C6) | L6: =IF(C6=0,0,SUMIF($A$15:$A$21,$A6,L$15:L$21)/C6) | M6: =IF(C6=0,0,SUMIF($A$15:$A$21,$A6,M$15:M$21)/C6)
A7: 3 ASANSÖR | B7: 13 asansör | C7: =SUMIF($A$15:$A$21,$A7,D$15:D$21) | D7: =E7-C7 | E7: =SUMIF($A$15:$A$21,$A7,F$15:F$21) | F7: =E7*Varsayimlar!$B$4 | G7: =E7*Varsayimlar!$B$5 | H7: =E7/$E$10 | I7: =SUMIF($A$15:$A$21,$A7,G$15:G$21) | J7: =SUMIF($A$15:$A$21,$A7,H$15:H$21) | K7: =IF(C7=0,0,SUMIF($A$15:$A$21,$A7,K$15:K$21)/C7) | L7: =IF(C7=0,0,SUMIF($A$15:$A$21,$A7,L$15:L$21)/C7) | M7: =IF(C7=0,0,SUMIF($A$15:$A$21,$A7,M$15:M$21)/C7)
A8: 4 SİNYALİZASYON | B8: Sinyalizasyon + araç takip (AVLS) | C8: =SUMIF($A$15:$A$21,$A8,D$15:D$21) | D8: =E8-C8 | E8: =SUMIF($A$15:$A$21,$A8,F$15:F$21) | F8: =E8*Varsayimlar!$B$4 | G8: =E8*Varsayimlar!$B$5 | H8: =E8/$E$10 | I8: =SUMIF($A$15:$A$21,$A8,G$15:G$21) | J8: =SUMIF($A$15:$A$21,$A8,H$15:H$21) | K8: =IF(C8=0,0,SUMIF($A$15:$A$21,$A8,K$15:K$21)/C8) | L8: =IF(C8=0,0,SUMIF($A$15:$A$21,$A8,L$15:L$21)/C8) | M8: =IF(C8=0,0,SUMIF($A$15:$A$21,$A8,M$15:M$21)/C8)
A9: 5 ELEKTRİFİKASYON | B9: Güç temini/cer gücü + katener | C9: =SUMIF($A$15:$A$21,$A9,D$15:D$21) | D9: =E9-C9 | E9: =SUMIF($A$15:$A$21,$A9,F$15:F$21) | F9: =E9*Varsayimlar!$B$4 | G9: =E9*Varsayimlar!$B$5 | H9: =E9/$E$10 | I9: =SUMIF($A$15:$A$21,$A9,G$15:G$21) | J9: =SUMIF($A$15:$A$21,$A9,H$15:H$21) | K9: =IF(C9=0,0,SUMIF($A$15:$A$21,$A9,K$15:K$21)/C9) | L9: =IF(C9=0,0,SUMIF($A$15:$A$21,$A9,L$15:L$21)/C9) | M9: =IF(C9=0,0,SUMIF($A$15:$A$21,$A9,M$15:M$21)/C9)
A10: TOPLAM MEP | C10: =SUM(C5:C9) | D10: =SUM(D5:D9) | E10: =SUM(E5:E9) | F10: =SUM(F5:F9) | G10: =SUM(G5:G9) | H10: =SUM(H5:H9) | I10: =SUM(I5:I9) | J10: =SUM(J5:J9) | K10: =SUMPRODUCT(C5:C9,K5:K9)/C10 | L10: =SUMPRODUCT(C5:C9,L5:L9)/C10 | M10: =SUMPRODUCT(C5:C9,M5:M9)/C10
A13: ALT KIRILIM (disiplin içi)
A14: Disiplin | B14: Alt kalem | C14: Cetvel sıraları | D14: Kalem bazlı EUR | E14: Risk % | F14: Önerilen EUR | G14: RFQ miktarlarıyla EUR | H14: Kıyas EUR | I14: Kıyas kaynağı | J14: Açıklama | K14: 2026 teklifine dayanan EUR | L14: Geçmiş teklif uyarlaması EUR | M14: Mühendislik tahmini EUR
A15: 1 ELEKTRİK | B15: AG dağıtım, AG kablolar, iç tesisat-aydınlatma, UPS, yangın ihbar, topraklama | C15: 180–186, 190–196, 198–199, 211–218, 322–342 | D15: ='Elektrik_AG'!$J$675 | E15: =Varsayimlar!$B$19 | F15: =D15*(1+E15) | G15: ='Elektrik_AG'!$J$676 | J15: İstasyon/depo ADP, AG besleme kabloları, aydınlatma, UPS'ler, yangın ihbar | K15: ='Elektrik_AG'!$J$680 | L15: ='Elektrik_AG'!$J$681 | M15: ='Elektrik_AG'!$J$682
A16: 1 ELEKTRİK | B16: Kontrol ve haberleşme (fiber, telefon, telsiz, anons, CCTV, saat, erişim, SCADA, YBS, turnike) | C16: 236–321 | D16: ='Haberlesme'!$J$543 | E16: =Varsayimlar!$B$20 | F16: =D16*(1+E16) | G16: ='Haberlesme'!$J$544 | H16: =Teklifler!F14 | I16: Referans kalem bazlı | J16: ON Elektronik (saat+YBS) ve Teknomaks (CCTV) teklifleri ekte/bekleniyor | K16: ='Haberlesme'!$J$548 | L16: ='Haberlesme'!$J$549 | M16: ='Haberlesme'!$J$550
A17: 2 MEKANİK | B17: Isıtma-soğutma, havalandırma, yangın söndürme, drenaj, sıhhi tesisat, basınçlı hava | C17: 159–168, 343–363 | D17: ='Mekanik'!$J$321 | E17: =Varsayimlar!$B$18 | F17: =D17*(1+E17) | G17: ='Mekanik'!$J$322 | J17: Asansör hariç (ayrı disiplin) | K17: ='Mekanik'!$J$326 | L17: ='Mekanik'!$J$327 | M17: ='Mekanik'!$J$328
A18: 3 ASANSÖR | B18: 13 asansör (12 üst geçit 1000 kg + 1 idari bina 800 kg) | C18: 364–365 | D18: ='Asansor'!$J$13 | E18: =Varsayimlar!$B$14 | F18: =D18*(1+E18) | G18: ='Asansor'!$J$14 | H18: =MIN(Teklifler!F4:F6) | I18: En düşük teklif (Emlift, sapmalı) | J18: 3 teklifin medyanı (Schindler 480.000 USD, TK 414.200 EUR, Emlift 19,5 M TL); bakım hariç | K18: ='Asansor'!$J$18 | L18: ='Asansor'!$J$19 | M18: ='Asansor'!$J$20
A19: 4 SİNYALİZASYON | B19: Hat boyu + depo sinyalizasyon, araç üstü, merkez, araç takip (AVLS) | C19: 228–235 | D19: ='Sinyal'!$J$95 | E19: =Varsayimlar!$B$15 | F19: =D19*(1+E19) | G19: ='Sinyal'!$J$96 | H19: =Teklifler!F8 | I19: Sistem bazlı ref. (makas başı) | J19: AVLS 233–235 Mukan Rail teklifiyle; Point Link 7,28 M€ kıyas dışı (Gmail'de bulunamadı) | K19: ='Sinyal'!$J$100 | L19: ='Sinyal'!$J$101 | M19: ='Sinyal'!$J$102
A20: 5 ELEKTRİFİKASYON | B20: Güç temini ve cer gücü (OG ring, TEİAŞ bağlantısı, 34,5 kV hücreler, 5 cer TM, kaçak akım) | C20: 169–179, 187–189, 197, 200–210, 219, 227 | D20: ='Cer_Guc'!$J$125 | E20: =Varsayimlar!$B$17 | F20: =D20*(1+E20) | G20: ='Cer_Guc'!$J$126 | H20: =Teklifler!F12 | I20: Sistem bazlı ref. (5 TM; yalnız OG+trafo+DC) | K20: ='Cer_Guc'!$J$130 | L20: ='Cer_Guc'!$J$131 | M20: ='Cer_Guc'!$J$132
A21: 5 ELEKTRİFİKASYON | B21: Katener (hat boyu, depo, direkler) | C21: 220–226 | D21: ='Katener'!$J$96 | E21: =Varsayimlar!$B$16 | F21: =D21*(1+E21) | G21: ='Katener'!$J$97 | H21: =Teklifler!F10 | I21: Sistem bazlı ref. (km başı) | J21: Direk temelleri inşaatta; ana hatta lente yok | K21: ='Katener'!$J$101 | L21: ='Katener'!$J$102 | M21: ='Katener'!$J$103
A24: CETVEL SIRASI BAZINDA DÖKÜM (risk payı hariç, EUR)
A25: Disiplin | B25: Sıra | C25: Kalem | D25: Tutar EUR
A26: 1 Elektrik – AG/aydınlatma/yangın | B26: 180 | C26: Göbekli Tepe İstasyonu Ag Ana Dağıtım Panoları (400 V) (1 set) | D26: ='Elektrik_AG'!J5
A27: 1 Elektrik – AG/aydınlatma/yangın | B27: 181 | C27: Hızmalı Köprüsü İstasyonu Ag Ana Dağıtım Panoları (400 V) (1 set) | D27: ='Elektrik_AG'!J14
A28: 1 Elektrik – AG/aydınlatma/yangın | B28: 182 | C28: Balıklıgöl İstasyonu Ag Ana Dağıtım Panoları (400 V) (1 set) | D28: ='Elektrik_AG'!J22
A29: 1 Elektrik – AG/aydınlatma/yangın | B29: 183 | C29: Eyüp Peygamber İstasyonu Ag Ana Dağıtım Panoları (400 V) (1 set) | D29: ='Elektrik_AG'!J30
A30: 1 Elektrik – AG/aydınlatma/yangın | B30: 184 | C30: Rasathane İstasyonu Ag Ana Dağıtım Panoları (400 V) (1 set) | D30: ='Elektrik_AG'!J38
A31: 1 Elektrik – AG/aydınlatma/yangın | B31: 185 | C31: Harran İstasyonu Ag Ana Dağıtım Panoları (400 V) (1 set) | D31: ='Elektrik_AG'!J46
A32: 1 Elektrik – AG/aydınlatma/yangın | B32: 186 | C32: Depo Sahası ve Tesisleri Ag Ana Dağıtım Panoları (400 V) (1 set) | D32: ='Elektrik_AG'!J54
A33: 1 Elektrik – AG/aydınlatma/yangın | B33: 190 | C33: Göbekli Tepe İstasyonu Topraklama Tesisatı (1 set) | D33: ='Elektrik_AG'!J71
A34: 1 Elektrik – AG/aydınlatma/yangın | B34: 191 | C34: Hızmalı Köprüsü İstasyonu Topraklama Tesisatı (1 set) | D34: ='Elektrik_AG'!J80
A35: 1 Elektrik – AG/aydınlatma/yangın | B35: 192 | C35: Balıklıgöl İstasyonu Topraklama Tesisatı (1 set) | D35: ='Elektrik_AG'!J89
A36: 1 Elektrik – AG/aydınlatma/yangın | B36: 193 | C36: Eyüp Peygamber İstasyonu Topraklama Tesisatı (1 set) | D36: ='Elektrik_AG'!J98
A37: 1 Elektrik – AG/aydınlatma/yangın | B37: 194 | C37: Rasathane İstasyonu Topraklama Tesisatı (1 set) | D37: ='Elektrik_AG'!J107
A38: 1 Elektrik – AG/aydınlatma/yangın | B38: 195 | C38: Depo Sahası ve Topraklama Tesisatı (1 set) | D38: ='Elektrik_AG'!J116
A39: 1 Elektrik – AG/aydınlatma/yangın | B39: 196 | C39: Harran İstasyonu Topraklama Tesisatı (1 set) | D39: ='Elektrik_AG'!J134
A40: 1 Elektrik – AG/aydınlatma/yangın | B40: 198 | C40: Sanat Yapıları (Üst Geçit) Topraklama Tesisatı (4 set) | D40: ='Elektrik_AG'!J143
A41: 1 Elektrik – AG/aydınlatma/yangın | B41: 199 | C41: Hat Boyu Topraklama Tesisatı (1 set) | D41: ='Elektrik_AG'!J151
A42: 1 Elektrik – AG/aydınlatma/yangın | B42: 211 | C42: Göbekli Tepe İstasyonu Alçak Gerilim Besleme-Dağıtım Kabloları ve Kablo Taşıma Sistemleri (1 set) | D42: ='Elektrik_AG'!J159
A43: 1 Elektrik – AG/aydınlatma/yangın | B43: 212 | C43: Hızmalı Köprüsü İstasyonu Alçak Gerilim Besleme-Dağıtım Kabloları ve Kablo Taşıma Sistemleri (1 set) | D43: ='Elektrik_AG'!J169
A44: 1 Elektrik – AG/aydınlatma/yangın | B44: 213 | C44: Balıklıgöl İstasyonu Alçak Gerilim Besleme-Dağıtım Kabloları ve Kablo Taşıma Sistemleri (1 set) | D44: ='Elektrik_AG'!J182
A45: 1 Elektrik – AG/aydınlatma/yangın | B45: 214 | C45: Eyüp Peygamber İstasyonu Alçak Gerilim Besleme-Dağıtım Kabloları ve Kablo Taşıma Sistemleri (1 set) | D45: ='Elektrik_AG'!J195
...

Sheet Teklif_Degerlendirme
A1: GELEN TEKLİFLERİN DEĞERLENDİRMESİ (06.10.2026 itibarıyla okunabilen teklifler)
A2: Tutarlar KDV hariç. EUR karşılığı Varsayımlar sayfasındaki kurla. 'Bütçe karşılığı' = aynı kapsam için bu çalışmadaki kalem bazlı tutar (net metraj, idare cevaplarına göre). Fark = teklif / bütçe − 1.
A4: Disiplin | B4: Firma | C4: Tarih | D4: Kapsam (cetvel sıra) | E4: Teklif tutarı | F4: PB | G4: Teklif EUR | H4: Bütçe karşılığı EUR | I4: Fark % | J4: Birim fiyat (EUR) | K4: Teknik uygunluk / sapmalar | L4: Ticari şartlar | M4: Bütçede kullanımı | N4: Değerlendirme
A5: Asansör | B5: Schindler Türkeli | C5: 01.10.2026 | D5: 364–365 (13 asansör) | E5: 480000 | F5: USD | G5: =E5/Varsayimlar!$B$4 | H5: ='Asansor'!$J$13 | I5: =IF(H5=0,"",G5/H5-1) | J5: 1000 kg: 37.000 USD; 800 kg: 36.000 USD | K5: Şartnameye uygun beyan; bakım hariç | L5: Geçerlilik/ödeme Excel'de belirtilmemiş | M5: Medyan hesabına dahil | N5: En yüksek teklif; kapsam tam
A6: Asansör | B6: TK Elevator | C6: 02.10.2026 | D6: 364–365 (13 asansör) | E6: 414200 | F6: EUR | G6: =E6 | H6: ='Asansor'!$J$13 | I6: =IF(H6=0,"",G6/H6-1) | J6: 1000 kg: 32.000 (24.000 malz.+8.000 işç.); 800 kg: 30.200 | K6: Antivandal CAT-2, dış ortam; kapı 900×2000 (talep 1100×2100); seyir 6 m (proje ~7,46 m) | L6: Geçerlilik 30 gün (talep 180); ödeme %50/%40/%10; teslim 8 ay; çelik işleri hariç; bakım 120 €/ay/adet | M6: Medyan = TK birim fiyatı (bütçe esası) | N6: Teknik olarak en uygun; geçerlilik süresi uzatılmalı, kapı ölçüsü teyit
A7: Asansör | B7: Emlift | C7: 05.10.2026 | D7: 364–365 (13 asansör) | E7: 19500000 | F7: TRY | G7: =E7/Varsayimlar!$B$5 | H7: ='Asansor'!$J$13 | I7: =IF(H7=0,"",G7/H7-1) | J7: 1.500.000 TL/adet (≈26.700 €) | K7: Teknik föy başka işten kopya (15 m seyir, 135×145 kabin); antivandal/dış ortam yok; kapı 900×2000 | L7: Geçerlilik ve ödeme şartı yok; kuyu aydınlatma, topraklama, MMO/belediye harçları hariç | M7: Medyan hesabına dahil (alt sınır) | N7: En düşük ama şartname sapmalı; teknik föy yenilenmeli
A8: Sinyalizasyon – AVLS | B8: Mukan Rail | C8: 06.10.2026 | D8: 233–235 (araç takip) | E8: 788000 | F8: EUR | G8: =E8 | H8: ='Sinyal'!J88+'Sinyal'!J90+'Sinyal'!J92 | I8: =IF(H8=0,"",G8/H8-1) | J8: Araç başı 21.300; merkez 314.500 (yazılım+lisans 172.500); tasarım 154.000 | K8: 11 soruya verilen varsayımlar esas; 2 sunucu + NAS; konum güncelleme ≤3 sn | L8: Bütçesel; 180 gün; %20 avans/%70 hakediş/%10 kabul; kabin, UPS, omurga, işletme SIM, yedek parça hariç | M8: Bütçeye işlendi (233: 14 araç) | N8: Tek teklif; H&K İzmir referansının ~2 katı – pazarlık payı var
A9: Elektrik – saat sistemi | B9: ON Elektronik (RayON) | C9: 06.10.2026 | D9: 281–289 (MSS) | E9: 81600 | F9: EUR | G9: =E10 | H9: ='Haberlesme'!J324+'Haberlesme'!J327+'Haberlesme'!J331+'Haberlesme'!J335+'Haberlesme'!J339+'Haberlesme'!J343+'Haberlesme'!J347+'Haberlesme'!J351+'Haberlesme'!J357 | I9: =IF(H9=0,"",G9/H9-1) | J9: Peron saati 3.000; master saat (Mobatime) 4.500; duvar saati 850–1.500 | K9: Üretici; şartnameye uygun beyan | L9: Kablolar ana yüklenicide (bütçede ayrıca var); geçerlilik belirtilmemiş | M9: Kalem kalem bütçeye işlendi | N9: Mevcut depo entegrasyonu (2.500) idare cevabıyla düşüldü
A10: Elektrik – yolcu bilgilendirme | B10: ON Elektronik (RayON) | C10: 06.10.2026 | D10: 310–317 (YBS) | E10: 171000 | F10: EUR | G10: =E11 | H10: ='Haberlesme'!J461+'Haberlesme'!J464+'Haberlesme'!J469+'Haberlesme'!J474+'Haberlesme'!J479+'Haberlesme'!J484+'Haberlesme'!J489+'Haberlesme'!J494 | I10: =IF(H10=0,"",G10/H10-1) | J10: 55" dış ortam ekran 3.500; askı 1.250; yazılım 25.000; tasarım+doküman 26.000 | K10: Medya oynatıcı ekrana dahil | L10: Kablolar ana yüklenicide; geçerlilik belirtilmemiş | M10: Kalem kalem bütçeye işlendi | N10: Mevcut depo entegrasyonu (11.000) idare cevabıyla düşüldü
A11: Sinyalizasyon (tümü) | B11: Point Link / CASCO (Çin) | C11: devir notu | D11: 228–235 | E11: 7281784 | F11: EUR | G11: =E12 | H11: ='Sinyal'!$J$95 | I11: =IF(H11=0,"",G11/H11-1) | J11: Kalem dökümü yok | K11: Yanıt 'AI asistan Eva' imzalı; mail Gmail'de bulunamadı | L11: DAP şantiye; KDV ve gümrük hariç | M11: Kullanılmadı | N11: Bütçenin ~1,8 katı; dökümsüz – yalnız üst sınır göstergesi
A12: Bilgi – MEP dışı | B12: Rayba Yapı (demiryolu üstyapı) | C12: 02.10 / 05.10.2026 | D12: Ray, makas, kruvazman; S-LINE bağlantı | E12: 19108311 | F12: EUR | J12: 42×R50 + 2×R100 makas + 3 kruvazman (= 56 makas, sinyal kabulüyle uyumlu); 17.231 m oluklu ray | K12: Beton/donatı hariç; 31.12.2026'ya kadar geçerli | M12: MEP bütçesine dahil değil | N12: Makas adedi sinyalizasyon/katener metrajını teyit ediyor
A14: TEKLİF DURUMU ÖZETİ (Gmail, 29.09–06.10.2026)
A15: Elektrik: ON Elektronik saat (81.600 €) ve YBS (171.000 €) teklifleri işlendi. Teknomaks (CCTV) ve Lev Müh. (yangın ihbar) çalışıyor; Best Transformer (trafo) dönmedi. Alfanar, Tema, EVA, DC Group vermiyor (Alfanar'dan RMU bütçesi istendi).
A16: Mekanik: Fiyatlı teklif yok. Ekura en geç 09.10 verecek; Protek (FM200) soru sordu. MET, Demta, Birleşim, Genç Müh. vermiyor.
A17: Asansör: 3 teklif (Schindler, TK, Emlift). Edoux verecek; Adakon (Orona) ithal ürünle bütçe verecek; KONE dönmedi.
A18: Sinyalizasyon: Mukan (AVLS) teklifi geldi. Hugotek ve İntetra dönecek; Alstom ve Savronik vermiyor (bütçe istendi); Hanning & Kahl dönmedi.
A19: Elektrifikasyon: Fiyatlı teklif yok. Mitaş (direk) verecek; DeSA (seksiyon izolatörü), Erbakır (iletken), Kambeton (beton direk) sorularına cevap verildi; Doruk ve KAM vermiyor.
A20: Ulaşmayan adres: 26 (mailer-daemon). Ayrıntı: Teklif_Durumu sayfası.

Sheet Elektrik_AG
A1: 1 ELEKTRİK (A) – AG dağıtım, topraklama, AG kablolar, AG tesisat-aydınlatma, yangın ihbar
A2: EUR, KDV hariç, montaj+test+devreye alma dahil (taşeron fiyatı), Ekim 2026. Turuncu miktar: idare cevabıyla (05.10.2026) değişen kalem. Metraj payı: RFQ'daki bilinçli şişirmenin (%10 fire, dağıtık malzemede %30) bütçeden geri alınması. Fiyat türü renkleri: yeşil = 2026 firma teklifi; mavi = geçmiş tekliften uyarlama (ECB kuru + Euro Bölgesi HICP ile Ağu-2026'ya taşınmış, gerekirse montaj/boyut düzeltmeli); sarı = mühendislik tahmini (emsal yok); gri = idare cevabıyla kapsam dışı.
A4: Sıra | B4: Poz | C4: Kalem / Alt kalem | D4: Birim | E4: Miktar (RFQ cetveli) | F4: Miktar (idare cevabına göre) | G4: Metraj payı geri alınan | H4: Net miktar (bütçe) | I4: Birim fiyat EUR (montaj dahil) | J4: Tutar EUR | K4: Fiyat türü | L4: Fiyat kaynağı / emsal (proje, firma, yıl, uyarlama) | M4: Not / düzeltme
A5: 180 | B5: 2006.A | C5: Göbekli Tepe İstasyonu Ag Ana Dağıtım Panoları (400 V) (1 set) | H5: RFQ tutarı → | I5: =SUMPRODUCT(E6:E13,I6:I13) | J5: =SUM(J6:J13)
B6: 2006.A | C6: ADP panosu: metal mahfazalı, TS EN 61439, IP54, 20x5 Cu bara | D6: adet | E6: 1 | F6: 1 | G6: - | H6: =F6 | I6: 2200 | J6: =H6*I6 | K6: MÜHENDİSLİK TAHMİNİ | L6: TAHMIN | M6: Boş pano gövdesi+bara
B7: 2006.A | C7: Ana giriş TMŞ 3x50 A 10 kA + RCD-D 300 mA | D7: adet | E7: 1 | F7: 1 | G7: - | H7: =F7 | I7: 350 | J7: =H7*I7 | K7: MÜHENDİSLİK TAHMİNİ | L7: TAHMIN | M7: TMŞ 50A+RCD-D
B8: 2006.A | C8: Çıkış TMŞ 3x32 A (APP-1, APP-2, SK-1, SK-2) | D8: adet | E8: 4 | F8: 4 | G8: - | H8: =F8 | I8: 130 | J8: =H8*I8 | K8: MÜHENDİSLİK TAHMİNİ | L8: TAHMIN | M8: Çıkış TMŞ 32A montajlı
B9: 2006.A | C9: Çıkış TMŞ 3x40 A (2 yedek + UPS besleme) | D9: adet | E9: 3 | F9: 3 | G9: - | H9: =F9 | I9: 140 | J9: =H9*I9 | K9: MÜHENDİSLİK TAHMİNİ | L9: TAHMIN | M9: Çıkış TMŞ 40A montajlı
B10: 2006.A | C10: UPS ana dağıtım panosu (UDP): giriş TMŞ 3x32 A, 20x5 Cu bara, UK1-UK2 TMŞ 3x32 A, UK3 AOS 1x10 A, UK4 TMŞ 1x10 A, UK5-UK7 TMŞ 3x25 A | D10: adet | E10: 1 | F10: 1 | G10: - | H10: =F10 | I10: 2000 | J10: =H10*I10 | K10: MÜHENDİSLİK TAHMİNİ | L10: TAHMIN | M10: UDP komple
B11: 2006.A | C11: UPS-1 / UPS-2 dağıtım panoları (peron başına, UK01-UK13 AOS 1x10/16 A + KAKŞ) | D11: adet | E11: 2 | F11: 2 | G11: - | H11: =F11 | I11: 1200 | J11: =H11*I11 | K11: MÜHENDİSLİK TAHMİNİ | L11: TAHMIN | M11: Peron UPS tali panosu
B12: 2006.A | C12: Parafudr Tip 1+2 (giriş) | D12: adet | E12: 1 | F12: 1 | G12: - | H12: =F12 | I12: 650 | J12: =H12*I12 | K12: MÜHENDİSLİK TAHMİNİ | L12: TAHMIN | M12: SPD Tip1+2
B13: 2006.A | C13: Pano montaj, iç kablaj, test | D13: set | E13: 1 | F13: 1 | G13: - | H13: =F13 | I13: 800 | J13: =H13*I13 | K13: MÜHENDİSLİK TAHMİNİ | L13: TAHMIN | M13: Montaj/test götürü
A14: 181 | B14: 2006.B | C14: Hızmalı Köprüsü İstasyonu Ag Ana Dağıtım Panoları (400 V) (1 set) | H14: RFQ tutarı → | I14: =SUMPRODUCT(E15:E21,I15:I21) | J14: =SUM(J15:J21)
B15: 2006.B | C15: ADP panosu: metal mahfazalı, TS EN 61439-1/2, IP54, 20x5 Cu bara 3P+N+PE | D15: adet | E15: 1 | F15: 1 | G15: - | H15: =F15 | I15: 2500 | J15: =H15*I15 | K15: MÜHENDİSLİK TAHMİNİ | L15: TAHMIN | M15: Boş pano gövdesi+bara
B16: 2006.B | C16: Ana giriş TMŞ 3x125 A 10 kA + RCD-D 300 mA (toroid) | D16: adet | E16: 1 | F16: 1 | G16: - | H16: =F16 | I16: 550 | J16: =H16*I16 | K16: MÜHENDİSLİK TAHMİNİ | L16: TAHMIN | M16: TMŞ 125A+RCD-D toroid
B17: 2006.B | C17: Çıkış TMŞ 3x32 A (APP, UPS, SK, YMP-01/02/03, ASP-01/02/03) | D17: adet | E17: 9 | F17: 9 | G17: - | H17: =F17 | I17: 130 | J17: =H17*I17 | K17: MÜHENDİSLİK TAHMİNİ | L17: TAHMIN | M17: Çıkış TMŞ 32A montajlı
B18: 2006.B | C18: Çıkış TMŞ 3x40 A (yedek) | D18: adet | E18: 3 | F18: 3 | G18: - | H18: =F18 | I18: 140 | J18: =H18*I18 | K18: MÜHENDİSLİK TAHMİNİ | L18: TAHMIN | M18: Çıkış TMŞ 40A montajlı
B19: 2006.B | C19: Parafudr Tip 1+2 3+N+PE (giriş) | D19: adet | E19: 1 | F19: 1 | G19: - | H19: =F19 | I19: 650 | J19: =H19*I19 | K19: MÜHENDİSLİK TAHMİNİ | L19: TAHMIN | M19: SPD Tip1+2
B20: 2006.B | C20: UPS ana dağıtım panosu (UPS çıkışı, UK01-UK12): giriş AOS 3x25 A, 2 x KAKŞ 4x25 A 30 mA, ~12 AOS 1x10/16 A, 4 yedek | D20: adet | E20: 1 | F20: 1 | G20: - | H20: =F20 | I20: 1800 | J20: =H20*I20 | K20: MÜHENDİSLİK TAHMİNİ | L20: TAHMIN | M20: UDP komple
B21: 2006.B | C21: Pano montaj/kaide, etiketleme, iç kablaj, test ve devreye alma | D21: set | E21: 1 | F21: 1 | G21: - | H21: =F21 | I21: 800 | J21: =H21*I21 | K21: MÜHENDİSLİK TAHMİNİ | L21: TAHMIN | M21: Montaj/test götürü
A22: 182 | B22: 2006.C | C22: Balıklıgöl İstasyonu Ag Ana Dağıtım Panoları (400 V) (1 set) | H22: RFQ tutarı → | I22: =SUMPRODUCT(E23:E29,I23:I29) | J22: =SUM(J23:J29)
B23: 2006.C | C23: ADP panosu: metal mahfazalı, TS EN 61439-1/2, IP54, 20x5 Cu bara 3P+N+PE | D23: adet | E23: 1 | F23: 1 | G23: - | H23: =F23 | I23: 2500 | J23: =H23*I23 | K23: MÜHENDİSLİK TAHMİNİ | L23: TAHMIN | M23: Boş pano gövdesi+bara
B24: 2006.C | C24: Ana giriş TMŞ 3x125 A 10 kA + RCD-D 300 mA (toroid) | D24: adet | E24: 1 | F24: 1 | G24: - | H24: =F24 | I24: 550 | J24: =H24*I24 | K24: MÜHENDİSLİK TAHMİNİ | L24: TAHMIN | M24: TMŞ 125A+RCD-D toroid
B25: 2006.C | C25: Çıkış TMŞ 3x32 A (APP, UPS, SK, YMP-01/02/03, ASP-01/02/03) | D25: adet | E25: 9 | F25: 9 | G25: - | H25: =F25 | I25: 130 | J25: =H25*I25 | K25: MÜHENDİSLİK TAHMİNİ | L25: TAHMIN | M25: Çıkış TMŞ 32A montajlı
B26: 2006.C | C26: Çıkış TMŞ 3x40 A (yedek) | D26: adet | E26: 3 | F26: 3 | G26: - | H26: =F26 | I26: 140 | J26: =H26*I26 | K26: MÜHENDİSLİK TAHMİNİ | L26: TAHMIN | M26: Çıkış TMŞ 40A montajlı
B27: 2006.C | C27: Parafudr Tip 1+2 3+N+PE (giriş) | D27: adet | E27: 1 | F27: 1 | G27: - | H27: =F27 | I27: 650 | J27: =H27*I27 | K27: MÜHENDİSLİK TAHMİNİ | L27: TAHMIN | M27: SPD Tip1+2
B28: 2006.C | C28: UPS ana dağıtım panosu (UPS çıkışı, UK01-UK12): giriş AOS 3x25 A, 2 x KAKŞ 4x25 A 30 mA, ~12 AOS 1x10/16 A, 4 yedek | D28: adet | E28: 1 | F28: 1 | G28: - | H28: =F28 | I28: 1800 | J28: =H28*I28 | K28: MÜHENDİSLİK TAHMİNİ | L28: TAHMIN | M28: UDP komple
B29: 2006.C | C29: Pano montaj/kaide, etiketleme, iç kablaj, test ve devreye alma | D29: set | E29: 1 | F29: 1 | G29: - | H29: =F29 | I29: 800 | J29: =H29*I29 | K29: MÜHENDİSLİK TAHMİNİ | L29: TAHMIN | M29: Montaj/test götürü
A30: 183 | B30: 2006.D | C30: Eyüp Peygamber İstasyonu Ag Ana Dağıtım Panoları (400 V) (1 set) | H30: RFQ tutarı → | I30: =SUMPRODUCT(E31:E37,I31:I37) | J30: =SUM(J31:J37)
B31: 2006.D | C31: ADP panosu: metal mahfazalı, TS EN 61439-1/2, IP54, 20x5 Cu bara 3P+N+PE | D31: adet | E31: 1 | F31: 1 | G31: - | H31: =F31 | I31: 2500 | J31: =H31*I31 | K31: MÜHENDİSLİK TAHMİNİ | L31: TAHMIN | M31: Boş pano gövdesi+bara
B32: 2006.D | C32: Ana giriş TMŞ 3x125 A 10 kA + RCD-D 300 mA (toroid) | D32: adet | E32: 1 | F32: 1 | G32: - | H32: =F32 | I32: 550 | J32: =H32*I32 | K32: MÜHENDİSLİK TAHMİNİ | L32: TAHMIN | M32: TMŞ 125A+RCD-D toroid
B33: 2006.D | C33: Çıkış TMŞ 3x32 A (APP, UPS, SK, YMP-01/02/03, ASP-01/02/03) | D33: adet | E33: 9 | F33: 9 | G33: - | H33: =F33 | I33: 130 | J33: =H33*I33 | K33: MÜHENDİSLİK TAHMİNİ | L33: TAHMIN | M33: Çıkış TMŞ 32A montajlı
B34: 2006.D | C34: Çıkış TMŞ 3x40 A (yedek) | D34: adet | E34: 3 | F34: 3 | G34: - | H34: =F34 | I34: 140 | J34: =H34*I34 | K34: MÜHENDİSLİK TAHMİNİ | L34: TAHMIN | M34: Çıkış TMŞ 40A montajlı
B35: 2006.D | C35: Parafudr Tip 1+2 3+N+PE (giriş) | D35: adet | E35: 1 | F35: 1 | G35: - | H35: =F35 | I35: 650 | J35: =H35*I35 | K35: MÜHENDİSLİK TAHMİNİ | L35: TAHMIN | M35: SPD Tip1+2
B36: 2006.D | C36: UPS ana dağıtım panosu (UPS çıkışı, UK01-UK12): giriş AOS 3x25 A, 2 x KAKŞ 4x25 A 30 mA, ~12 AOS 1x10/16 A, 4 yedek | D36: adet | E36: 1 | F36: 1 | G36: - | H36: =F36 | I36: 1800 | J36: =H36*I36 | K36: MÜHENDİSLİK TAHMİNİ | L36: TAHMIN | M36: UDP komple
B37: 2006.D | C37: Pano montaj/kaide, etiketleme, iç kablaj, test ve devreye alma | D37: set | E37: 1 | F37: 1 | G37: - | H37: =F37 | I37: 800 | J37: =H37*I37 | K37: MÜHENDİSLİK TAHMİNİ | L37: TAHMIN | M37: Montaj/test götürü
A38: 184 | B38: 2006.E | C38: Rasathane İstasyonu Ag Ana Dağıtım Panoları (400 V) (1 set) | H38: RFQ tutarı → | I38: =SUMPRODUCT(E39:E45,I39:I45) | J38: =SUM(J39:J45)
B39: 2006.E | C39: ADP panosu: metal mahfazalı, TS EN 61439-1/2, IP54, 20x5 Cu bara 3P+N+PE | D39: adet | E39: 1 | F39: 1 | G39: - | H39: =F39 | I39: 2500 | J39: =H39*I39 | K39: MÜHENDİSLİK TAHMİNİ | L39: TAHMIN | M39: Boş pano gövdesi+bara
B40: 2006.E | C40: Ana giriş TMŞ 3x125 A 10 kA + RCD-D 300 mA (toroid) | D40: adet | E40: 1 | F40: 1 | G40: - | H40: =F40 | I40: 550 | J40: =H40*I40 | K40: MÜHENDİSLİK TAHMİNİ | L40: TAHMIN | M40: TMŞ 125A+RCD-D toroid
B41: 2006.E | C41: Çıkış TMŞ 3x32 A (APP, UPS, SK, YMP-01/02/03, ASP-01/02/03) | D41: adet | E41: 9 | F41: 9 | G41: - | H41: =F41 | I41: 130 | J41: =H41*I41 | K41: MÜHENDİSLİK TAHMİNİ | L41: TAHMIN | M41: Çıkış TMŞ 32A montajlı
...

Sheet Haberlesme
A1: 1 ELEKTRİK (B) – Kontrol ve haberleşme (iletim, telefon, telsiz, anons, CCTV, saat, erişim, SCADA, YBS, ücret toplama)
A2: EUR, KDV hariç, montaj+test+devreye alma dahil (taşeron fiyatı), Ekim 2026. Turuncu miktar: idare cevabıyla (05.10.2026) değişen kalem. Metraj payı: RFQ'daki bilinçli şişirmenin (%10 fire, dağıtık malzemede %30) bütçeden geri alınması. Fiyat türü renkleri: yeşil = 2026 firma teklifi; mavi = geçmiş tekliften uyarlama (ECB kuru + Euro Bölgesi HICP ile Ağu-2026'ya taşınmış, gerekirse montaj/boyut düzeltmeli); sarı = mühendislik tahmini (emsal yok); gri = idare cevabıyla kapsam dışı.
A4: Sıra | B4: Poz | C4: Kalem / Alt kalem | D4: Birim | E4: Miktar (RFQ cetveli) | F4: Miktar (idare cevabına göre) | G4: Metraj payı geri alınan | H4: Net miktar (bütçe) | I4: Birim fiyat EUR (montaj dahil) | J4: Tutar EUR | K4: Fiyat türü | L4: Fiyat kaynağı / emsal (proje, firma, yıl, uyarlama) | M4: Not / düzeltme
A5: 236 | B5: 4001 | C5: İletim Sistemi Tasarımı (1 set) | H5: RFQ tutarı → | I5: =SUMPRODUCT(E6:E7,I6:I7) | J5: =SUM(J6:J7)
B6: 4001 | C6: Uygulama projeleri, sistem mimarisi/blok şemaları, hesaplar (fiber ring, IP/VLAN planı, loss budget +6 dB marj) | D6: set | E6: 1 | F6: 1 | G6: - | H6: =F6 | I6: 18000 | J6: =H6*I6 | K6: MÜHENDİSLİK TAHMİNİ | L6: TAHMIN | M6: Tasarım, küçük tramvay ölçeği
B7: 4001 | C7: Dokümantasyon: malzeme onayı, test prosedürleri, as-built, işletme-bakım el kitapları, eğitim dokümanı | D7: set | E7: 1 | F7: 1 | G7: - | H7: =F7 | I7: 7000 | J7: =H7*I7 | K7: MÜHENDİSLİK TAHMİNİ | L7: TAHMIN | M7: Tasarım, küçük tramvay ölçeği
A8: 237 | B8: 4002.A | C8: Göbekli Tepe İstasyonu İletim Sistemi (1 set) | H8: RFQ tutarı → | I8: =SUMPRODUCT(E9:E19,I9:I19) | J8: =SUM(J9:J19)
B9: 4002.A | C9: Harici tip durak haberleşme dolabı (IP55, kilitli, 19'' raylı, havalandırmalı, pano odasındaki RACK KABİN) | D9: adet | E9: 2 | F9: 2 | G9: - | H9: =F9 | I9: 2800 | J9: =H9*I9 | K9: MÜHENDİSLİK TAHMİNİ | L9: TAHMIN | M9: IP55 dış dolap 19" kurulu
B10: 4002.A | C10: Endüstriyel ağ anahtarı 12 port (8 PoE+ 10/100/1000 + 2 kombo + 2 SFP), L2/L3, DIN/19'' | D10: adet | E10: 4 | F10: 4 | G10: %30 | H10: =F10/IF(Varsayimlar!$B$21=1,1.3,1) | I10: 2800 | J10: =H10*I10 | K10: MÜHENDİSLİK TAHMİNİ | L10: TAHMIN | M10: Endüstriyel L2/L3 PoE switch
B11: 4002.A | C11: SFP optik alıcı-verici modül (1000BASE-LX SM) | D11: adet | E11: 12 | F11: 12 | G11: - | H11: =F11 | I11: 150 | J11: =H11*I11 | K11: MÜHENDİSLİK TAHMİNİ | L11: TAHMIN
B12: 4002.A | C12: Fiber optik ek/terminasyon kutusu (19'' ODF 24 port SC/LC, pigtail+adaptör dahil) | D12: adet | E12: 2 | F12: 2 | G12: %30 | H12: =F12/IF(Varsayimlar!$B$21=1,1.3,1) | I12: 450 | J12: =H12*I12 | K12: MÜHENDİSLİK TAHMİNİ | L12: TAHMIN | M12: ODF 24 port, pigtail dahil
B13: 4002.A | C13: Pigtail LC + füzyon ek (sonlandırma, 24 core MM alt ring) | D13: adet | E13: 125 | F13: 42 | G13: - | H13: =F13 | I13: 18 | J13: =H13*I13 | K13: MÜHENDİSLİK TAHMİNİ | L13: TAHMIN | M13: İdare: 24 ve 8 core SM; alt ring 8 core → ek ×8/24
B14: 4002.A | C14: F/O patch cord SM LC-LC duplex 2 m | D14: adet | E14: 11 | F14: 11 | G14: %30 | H14: =F14/IF(Varsayimlar!$B$21=1,1.3,1) | I14: 12 | J14: =H14*I14 | K14: MÜHENDİSLİK TAHMİNİ | L14: TAHMIN
B15: 4002.A | C15: CAT6 bakır patch panel 24 port + CAT6 patch cord (1 m) seti | D15: set | E15: 2 | F15: 2 | G15: - | H15: =F15 | I15: 220 | J15: =H15*I15 | K15: MÜHENDİSLİK TAHMİNİ | L15: TAHMIN
B16: 4002.A | C16: Dolap içi güç dağıtım (PDU) + PoE/ekipman güç adaptörleri, yıldırım/aşırı gerilim koruyucu (data hattı) | D16: set | E16: 2 | F16: 2 | G16: - | H16: =F16 | I16: 600 | J16: =H16*I16 | K16: MÜHENDİSLİK TAHMİNİ | L16: TAHMIN | M16: PDU+adaptör+SPD
B17: 4002.A | C17: SM F/O kablo 8 core zırhlı (RACK KABİN-1 ↔ RACK KABİN-2, hat altı geçiş) | D17: m | E17: 58 | F17: 58 | G17: fire+%30 | H17: =F17/IF(Varsayimlar!$B$21=1,1.43,1) | I17: 1.8 | J17: =H17*I17 | K17: MÜHENDİSLİK TAHMİNİ | L17: TAHMIN | M17: 8 core SM zırhlı, çekim dahil
B18: 4002.A | C18: Ø110 koruge boru (istasyon zayıf/kuvvetli akım borulama tesisatı, peron altı + yol altı geçiş) | D18: m | E18: 1430 | F18: 1430 | G18: fire+%30 | H18: =F18/IF(Varsayimlar!$B$21=1,1.43,1) | I18: 5.5 | J18: =H18*I18 | K18: MÜHENDİSLİK TAHMİNİ | L18: TAHMIN | M18: Kazı hariç boru döşeme
B19: 4002.A | C19: İletim sistemi test/devreye alma, OTDR ölçümü, dokümantasyon (istasyon) | D19: set | E19: 1 | F19: 1 | G19: - | H19: =F19 | I19: 2500 | J19: =H19*I19 | K19: MÜHENDİSLİK TAHMİNİ | L19: TAHMIN | M19: 2 kabinli istasyon
A20: 238 | B20: 4002.B | C20: Hızmalı Köprüsü İstasyonu İletim Sistemi (1 set) | H20: RFQ tutarı → | I20: =SUMPRODUCT(E21:E30,I21:I30) | J20: =SUM(J21:J30)
B21: 4002.B | C21: Harici tip durak haberleşme dolabı (IP55, kilitli, 19'' raylı, havalandırmalı, pano odasındaki RACK KABİN) | D21: adet | E21: 1 | F21: 1 | G21: - | H21: =F21 | I21: 2800 | J21: =H21*I21 | K21: MÜHENDİSLİK TAHMİNİ | L21: TAHMIN | M21: IP55 dış dolap 19" kurulu
B22: 4002.B | C22: Endüstriyel ağ anahtarı 12 port (8 PoE+ 10/100/1000 + 2 kombo + 2 SFP), L2/L3, DIN/19'' | D22: adet | E22: 3 | F22: 3 | G22: %30 | H22: =F22/IF(Varsayimlar!$B$21=1,1.3,1) | I22: 2800 | J22: =H22*I22 | K22: MÜHENDİSLİK TAHMİNİ | L22: TAHMIN | M22: Endüstriyel L2/L3 PoE switch
B23: 4002.B | C23: SFP optik alıcı-verici modül (1000BASE-LX SM) | D23: adet | E23: 8 | F23: 8 | G23: - | H23: =F23 | I23: 150 | J23: =H23*I23 | K23: MÜHENDİSLİK TAHMİNİ | L23: TAHMIN
B24: 4002.B | C24: Fiber optik ek/terminasyon kutusu (19'' ODF 24 port SC/LC, pigtail+adaptör dahil) | D24: adet | E24: 1 | F24: 1 | G24: %30 | H24: =F24/IF(Varsayimlar!$B$21=1,1.3,1) | I24: 450 | J24: =H24*I24 | K24: MÜHENDİSLİK TAHMİNİ | L24: TAHMIN | M24: ODF 24 port, pigtail dahil
B25: 4002.B | C25: Pigtail LC + füzyon ek (sonlandırma, 24 core MM alt ring) | D25: adet | E25: 63 | F25: 21 | G25: - | H25: =F25 | I25: 18 | J25: =H25*I25 | K25: MÜHENDİSLİK TAHMİNİ | L25: TAHMIN | M25: İdare: 24 ve 8 core SM; alt ring 8 core → ek ×8/24
B26: 4002.B | C26: F/O patch cord SM LC-LC duplex 2 m | D26: adet | E26: 6 | F26: 6 | G26: %30 | H26: =F26/IF(Varsayimlar!$B$21=1,1.3,1) | I26: 12 | J26: =H26*I26 | K26: MÜHENDİSLİK TAHMİNİ | L26: TAHMIN
B27: 4002.B | C27: CAT6 bakır patch panel 24 port + CAT6 patch cord (1 m) seti | D27: set | E27: 1 | F27: 1 | G27: - | H27: =F27 | I27: 220 | J27: =H27*I27 | K27: MÜHENDİSLİK TAHMİNİ | L27: TAHMIN
B28: 4002.B | C28: Dolap içi güç dağıtım (PDU) + PoE/ekipman güç adaptörleri, yıldırım/aşırı gerilim koruyucu (data hattı) | D28: set | E28: 1 | F28: 1 | G28: - | H28: =F28 | I28: 600 | J28: =H28*I28 | K28: MÜHENDİSLİK TAHMİNİ | L28: TAHMIN | M28: PDU+adaptör+SPD
B29: 4002.B | C29: Ø110 koruge boru (istasyon zayıf/kuvvetli akım borulama tesisatı, peron altı + yol altı geçiş) | D29: m | E29: 1210 | F29: 1210 | G29: fire+%30 | H29: =F29/IF(Varsayimlar!$B$21=1,1.43,1) | I29: 5.5 | J29: =H29*I29 | K29: MÜHENDİSLİK TAHMİNİ | L29: TAHMIN | M29: Kazı hariç boru döşeme
B30: 4002.B | C30: İletim sistemi test/devreye alma, OTDR ölçümü, dokümantasyon (istasyon) | D30: set | E30: 1 | F30: 1 | G30: - | H30: =F30 | I30: 1800 | J30: =H30*I30 | K30: MÜHENDİSLİK TAHMİNİ | L30: TAHMIN
A31: 239 | B31: 4002.C | C31: Balıklıgöl İstasyonu İletim Sistemi (1 set) | H31: RFQ tutarı → | I31: =SUMPRODUCT(E32:E41,I32:I41) | J31: =SUM(J32:J41)
B32: 4002.C | C32: Harici tip durak haberleşme dolabı (IP55, kilitli, 19'' raylı, havalandırmalı, pano odasındaki RACK KABİN) | D32: adet | E32: 1 | F32: 1 | G32: - | H32: =F32 | I32: 2800 | J32: =H32*I32 | K32: MÜHENDİSLİK TAHMİNİ | L32: TAHMIN | M32: IP55 dış dolap 19" kurulu
B33: 4002.C | C33: Endüstriyel ağ anahtarı 12 port (8 PoE+ 10/100/1000 + 2 kombo + 2 SFP), L2/L3, DIN/19'' | D33: adet | E33: 3 | F33: 3 | G33: %30 | H33: =F33/IF(Varsayimlar!$B$21=1,1.3,1) | I33: 2800 | J33: =H33*I33 | K33: MÜHENDİSLİK TAHMİNİ | L33: TAHMIN | M33: Endüstriyel L2/L3 PoE switch
B34: 4002.C | C34: SFP optik alıcı-verici modül (1000BASE-LX SM) | D34: adet | E34: 8 | F34: 8 | G34: - | H34: =F34 | I34: 150 | J34: =H34*I34 | K34: MÜHENDİSLİK TAHMİNİ | L34: TAHMIN
B35: 4002.C | C35: Fiber optik ek/terminasyon kutusu (19'' ODF 24 port SC/LC, pigtail+adaptör dahil) | D35: adet | E35: 1 | F35: 1 | G35: %30 | H35: =F35/IF(Varsayimlar!$B$21=1,1.3,1) | I35: 450 | J35: =H35*I35 | K35: MÜHENDİSLİK TAHMİNİ | L35: TAHMIN | M35: ODF 24 port, pigtail dahil
B36: 4002.C | C36: Pigtail LC + füzyon ek (sonlandırma, 24 core MM alt ring) | D36: adet | E36: 63 | F36: 21 | G36: - | H36: =F36 | I36: 18 | J36: =H36*I36 | K36: MÜHENDİSLİK TAHMİNİ | L36: TAHMIN | M36: İdare: 24 ve 8 core SM; alt ring 8 core → ek ×8/24
B37: 4002.C | C37: F/O patch cord SM LC-LC duplex 2 m | D37: adet | E37: 6 | F37: 6 | G37: %30 | H37: =F37/IF(Varsayimlar!$B$21=1,1.3,1) | I37: 12 | J37: =H37*I37 | K37: MÜHENDİSLİK TAHMİNİ | L37: TAHMIN
B38: 4002.C | C38: CAT6 bakır patch panel 24 port + CAT6 patch cord (1 m) seti | D38: set | E38: 1 | F38: 1 | G38: - | H38: =F38 | I38: 220 | J38: =H38*I38 | K38: MÜHENDİSLİK TAHMİNİ | L38: TAHMIN
B39: 4002.C | C39: Dolap içi güç dağıtım (PDU) + PoE/ekipman güç adaptörleri, yıldırım/aşırı gerilim koruyucu (data hattı) | D39: set | E39: 1 | F39: 1 | G39: - | H39: =F39 | I39: 600 | J39: =H39*I39 | K39: MÜHENDİSLİK TAHMİNİ | L39: TAHMIN | M39: PDU+adaptör+SPD
B40: 4002.C | C40: Ø110 koruge boru (istasyon zayıf/kuvvetli akım borulama tesisatı, peron altı + yol altı geçiş) | D40: m | E40: 1210 | F40: 1210 | G40: fire+%30 | H40: =F40/IF(Varsayimlar!$B$21=1,1.43,1) | I40: 5.5 | J40: =H40*I40 | K40: MÜHENDİSLİK TAHMİNİ | L40: TAHMIN | M40: Kazı hariç boru döşeme
B41: 4002.C | C41: İletim sistemi test/devreye alma, OTDR ölçümü, dokümantasyon (istasyon) | D41: set | E41: 1 | F41: 1 | G41: - | H41: =F41 | I41: 1800 | J41: =H41*I41 | K41: MÜHENDİSLİK TAHMİNİ | L41: TAHMIN
...

Sheet Mekanik
A1: 2 MEKANİK – Sıra 159–168, 343–363 (HVAC, yangın, drenaj, sıhhi, basınçlı hava)
A2: EUR, KDV hariç, montaj+test+devreye alma dahil (taşeron fiyatı), Ekim 2026. Turuncu miktar: idare cevabıyla (05.10.2026) değişen kalem. Metraj payı: RFQ'daki bilinçli şişirmenin (%10 fire, dağıtık malzemede %30) bütçeden geri alınması. Fiyat türü renkleri: yeşil = 2026 firma teklifi; mavi = geçmiş tekliften uyarlama (ECB kuru + Euro Bölgesi HICP ile Ağu-2026'ya taşınmış, gerekirse montaj/boyut düzeltmeli); sarı = mühendislik tahmini (emsal yok); gri = idare cevabıyla kapsam dışı.
A4: Sıra | B4: Poz | C4: Kalem / Alt kalem | D4: Birim | E4: Miktar (RFQ cetveli) | F4: Miktar (idare cevabına göre) | G4: Metraj payı geri alınan | H4: Net miktar (bütçe) | I4: Birim fiyat EUR (montaj dahil) | J4: Tutar EUR | K4: Fiyat türü | L4: Fiyat kaynağı / emsal (proje, firma, yıl, uyarlama) | M4: Not / düzeltme
A5: 159 | B5: 6001.A | C5: Harran İstasyonu Isıtma Soğutma Sistemi (1 set) | H5: RFQ tutarı → | I5: =SUMPRODUCT(E6:E13,I6:I13) | J5: =SUM(J6:J13)
B6: 6001.A | C6: Split klima duvar tipi inverter IU-1/DU-1, 5 kW soğutma, R410A, dış ünite dahil komple (pano odası) | D6: adet | E6: 2 | F6: 2 | G6: - | H6: =F6 | I6: 1885.16 | J6: =H6*I6 | K6: GEÇMİŞ TEKLİF UYARLAMA | L6: REF
B7: 6001.A | C7: Split klima bakır boru izolasyonlu (sıvı+gaz çifti 1/4"-1/2") + bağlantı kablosu | D7: m | E7: 6 | F7: 6 | G7: fire+%30 | H7: =F7/IF(Varsayimlar!$B$21=1,1.43,1) | I7: 22 | J7: =H7*I7 | K7: MÜHENDİSLİK TAHMİNİ | L7: TAHMIN
B8: 6001.A | C8: Klima yoğuşma drenaj borusu PVC/PPRC Ø20-25 (hatta bırakılacak) | D8: m | E8: 5 | F8: 5 | G8: fire+%30 | H8: =F8/IF(Varsayimlar!$B$21=1,1.43,1) | I8: 5 | J8: =H8*I8 | K8: GEÇMİŞ TEKLİF UYARLAMA | L8: REF-duz [ref 2.17] | M8: Ref malzeme fiyatı; montajlı
B9: 6001.A | C9: DU montaj konsolu + titreşim takozu, kablolu kumanda, montaj-test-devreye alma | D9: takım | E9: 1 | F9: 1 | G9: - | H9: =F9 | I9: 150 | J9: =H9*I9 | K9: MÜHENDİSLİK TAHMİNİ | L9: TAHMIN
B10: 6001.A | C10: Güvenlik kabini split klima inverter ~2,5 kW duvar tipi, R410A, dış ünite dahil + kapı/pencere kontak sistemi | D10: adet | E10: 2 | F10: 0 | G10: %30 | H10: =F10/IF(Varsayimlar!$B$21=1,1.3,1) | I10: 950 | J10: =H10*I10 | K10: KAPSAM DIŞI (0) | L10: REF-duz [ref 553.26] | M10: İdare: kabin splitleri sıra 143 kabin fiyatında
B11: 6001.A | C11: Güvenlik kabini split bakır boru izolasyonlu (1/4"-3/8") + bağlantı kablosu | D11: m | E11: 6 | F11: 0 | G11: fire+%30 | H11: =F11/IF(Varsayimlar!$B$21=1,1.43,1) | I11: 18 | J11: =H11*I11 | K11: KAPSAM DIŞI (0) | L11: TAHMIN | M11: İdare: kabin splitleri sıra 143 kabin fiyatında
B12: 6001.A | C12: Güvenlik kabini split yoğuşma drenaj borusu PVC Ø20 | D12: m | E12: 5 | F12: 0 | G12: fire+%30 | H12: =F12/IF(Varsayimlar!$B$21=1,1.43,1) | I12: 5 | J12: =H12*I12 | K12: KAPSAM DIŞI (0) | L12: REF-duz [ref 1.91] | M12: İdare: kabin splitleri sıra 143 kabin fiyatında
B13: 6001.A | C13: Güvenlik kabini split DU konsolu + titreşim takozu + kablolu kumanda + kontak rölesi, montaj-devreye alma | D13: takım | E13: 1 | F13: 0 | G13: - | H13: =F13 | I13: 120 | J13: =H13*I13 | K13: KAPSAM DIŞI (0) | L13: TAHMIN | M13: İdare: kabin splitleri sıra 143 kabin fiyatında
A14: 160 | B14: 6001.B | C14: Rasathane İstasyonu Isıtma Soğutma Sistemi (1 set) | H14: RFQ tutarı → | I14: =SUMPRODUCT(E15:E22,I15:I22) | J14: =SUM(J15:J22)
B15: 6001.B | C15: Split klima duvar tipi inverter IU-1/DU-1, 5 kW soğutma, R410A, dış ünite dahil komple (pano odası) | D15: adet | E15: 2 | F15: 2 | G15: - | H15: =F15 | I15: 1885.16 | J15: =H15*I15 | K15: GEÇMİŞ TEKLİF UYARLAMA | L15: REF
B16: 6001.B | C16: Split klima bakır boru izolasyonlu (sıvı+gaz çifti 1/4"-1/2") + bağlantı kablosu | D16: m | E16: 6 | F16: 6 | G16: fire+%30 | H16: =F16/IF(Varsayimlar!$B$21=1,1.43,1) | I16: 22 | J16: =H16*I16 | K16: MÜHENDİSLİK TAHMİNİ | L16: TAHMIN
B17: 6001.B | C17: Klima yoğuşma drenaj borusu PVC/PPRC Ø20-25 (hatta bırakılacak) | D17: m | E17: 5 | F17: 5 | G17: fire+%30 | H17: =F17/IF(Varsayimlar!$B$21=1,1.43,1) | I17: 5 | J17: =H17*I17 | K17: GEÇMİŞ TEKLİF UYARLAMA | L17: REF-duz [ref 2.17] | M17: Ref malzeme fiyatı; montajlı
B18: 6001.B | C18: DU montaj konsolu + titreşim takozu, kablolu kumanda, montaj-test-devreye alma | D18: takım | E18: 1 | F18: 1 | G18: - | H18: =F18 | I18: 150 | J18: =H18*I18 | K18: MÜHENDİSLİK TAHMİNİ | L18: TAHMIN
B19: 6001.B | C19: Güvenlik kabini split klima inverter ~2,5 kW duvar tipi, R410A, dış ünite dahil + kapı/pencere kontak sistemi | D19: adet | E19: 2 | F19: 0 | G19: %30 | H19: =F19/IF(Varsayimlar!$B$21=1,1.3,1) | I19: 950 | J19: =H19*I19 | K19: KAPSAM DIŞI (0) | L19: REF-duz [ref 553.26] | M19: İdare: kabin splitleri sıra 143 kabin fiyatında
B20: 6001.B | C20: Güvenlik kabini split bakır boru izolasyonlu (1/4"-3/8") + bağlantı kablosu | D20: m | E20: 6 | F20: 0 | G20: fire+%30 | H20: =F20/IF(Varsayimlar!$B$21=1,1.43,1) | I20: 18 | J20: =H20*I20 | K20: KAPSAM DIŞI (0) | L20: TAHMIN | M20: İdare: kabin splitleri sıra 143 kabin fiyatında
B21: 6001.B | C21: Güvenlik kabini split yoğuşma drenaj borusu PVC Ø20 | D21: m | E21: 5 | F21: 0 | G21: fire+%30 | H21: =F21/IF(Varsayimlar!$B$21=1,1.43,1) | I21: 5 | J21: =H21*I21 | K21: KAPSAM DIŞI (0) | L21: REF-duz [ref 1.91] | M21: İdare: kabin splitleri sıra 143 kabin fiyatında
B22: 6001.B | C22: Güvenlik kabini split DU konsolu + titreşim takozu + kablolu kumanda + kontak rölesi, montaj-devreye alma | D22: takım | E22: 1 | F22: 0 | G22: - | H22: =F22 | I22: 120 | J22: =H22*I22 | K22: KAPSAM DIŞI (0) | L22: TAHMIN | M22: İdare: kabin splitleri sıra 143 kabin fiyatında
A23: 161 | B23: 6001.C | C23: Eyüp Peygamber İstasyonu Isıtma Soğutma Sistemi (1 set) | H23: RFQ tutarı → | I23: =SUMPRODUCT(E24:E31,I24:I31) | J23: =SUM(J24:J31)
B24: 6001.C | C24: Split klima duvar tipi inverter IU-1/DU-1, 5 kW soğutma, R410A, dış ünite dahil komple (pano odası) | D24: adet | E24: 2 | F24: 2 | G24: - | H24: =F24 | I24: 1885.16 | J24: =H24*I24 | K24: GEÇMİŞ TEKLİF UYARLAMA | L24: REF
B25: 6001.C | C25: Split klima bakır boru izolasyonlu (sıvı+gaz çifti 1/4"-1/2") + bağlantı kablosu | D25: m | E25: 6 | F25: 6 | G25: fire+%30 | H25: =F25/IF(Varsayimlar!$B$21=1,1.43,1) | I25: 22 | J25: =H25*I25 | K25: MÜHENDİSLİK TAHMİNİ | L25: TAHMIN
B26: 6001.C | C26: Klima yoğuşma drenaj borusu PVC/PPRC Ø20-25 (hatta bırakılacak) | D26: m | E26: 5 | F26: 5 | G26: fire+%30 | H26: =F26/IF(Varsayimlar!$B$21=1,1.43,1) | I26: 5 | J26: =H26*I26 | K26: GEÇMİŞ TEKLİF UYARLAMA | L26: REF-duz [ref 2.17] | M26: Ref malzeme fiyatı; montajlı
B27: 6001.C | C27: DU montaj konsolu + titreşim takozu, kablolu kumanda, montaj-test-devreye alma | D27: takım | E27: 1 | F27: 1 | G27: - | H27: =F27 | I27: 150 | J27: =H27*I27 | K27: MÜHENDİSLİK TAHMİNİ | L27: TAHMIN
B28: 6001.C | C28: Güvenlik kabini split klima inverter ~2,5 kW duvar tipi, R410A, dış ünite dahil + kapı/pencere kontak sistemi | D28: adet | E28: 2 | F28: 0 | G28: %30 | H28: =F28/IF(Varsayimlar!$B$21=1,1.3,1) | I28: 950 | J28: =H28*I28 | K28: KAPSAM DIŞI (0) | L28: REF-duz [ref 553.26] | M28: İdare: kabin splitleri sıra 143 kabin fiyatında
B29: 6001.C | C29: Güvenlik kabini split bakır boru izolasyonlu (1/4"-3/8") + bağlantı kablosu | D29: m | E29: 6 | F29: 0 | G29: fire+%30 | H29: =F29/IF(Varsayimlar!$B$21=1,1.43,1) | I29: 18 | J29: =H29*I29 | K29: KAPSAM DIŞI (0) | L29: TAHMIN | M29: İdare: kabin splitleri sıra 143 kabin fiyatında
B30: 6001.C | C30: Güvenlik kabini split yoğuşma drenaj borusu PVC Ø20 | D30: m | E30: 5 | F30: 0 | G30: fire+%30 | H30: =F30/IF(Varsayimlar!$B$21=1,1.43,1) | I30: 5 | J30: =H30*I30 | K30: KAPSAM DIŞI (0) | L30: REF-duz [ref 1.91] | M30: İdare: kabin splitleri sıra 143 kabin fiyatında
B31: 6001.C | C31: Güvenlik kabini split DU konsolu + titreşim takozu + kablolu kumanda + kontak rölesi, montaj-devreye alma | D31: takım | E31: 1 | F31: 0 | G31: - | H31: =F31 | I31: 120 | J31: =H31*I31 | K31: KAPSAM DIŞI (0) | L31: TAHMIN | M31: İdare: kabin splitleri sıra 143 kabin fiyatında
A32: 162 | B32: 6001.D | C32: Balıklıgöl İstasyonu Isıtma Soğutma Sistemi (1 set) | H32: RFQ tutarı → | I32: =SUMPRODUCT(E33:E40,I33:I40) | J32: =SUM(J33:J40)
B33: 6001.D | C33: Split klima duvar tipi inverter IU-1/DU-1, 5 kW soğutma, R410A, dış ünite dahil komple (pano odası) | D33: adet | E33: 2 | F33: 2 | G33: - | H33: =F33 | I33: 1885.16 | J33: =H33*I33 | K33: GEÇMİŞ TEKLİF UYARLAMA | L33: REF
B34: 6001.D | C34: Split klima bakır boru izolasyonlu (sıvı+gaz çifti 1/4"-1/2") + bağlantı kablosu | D34: m | E34: 6 | F34: 6 | G34: fire+%30 | H34: =F34/IF(Varsayimlar!$B$21=1,1.43,1) | I34: 22 | J34: =H34*I34 | K34: MÜHENDİSLİK TAHMİNİ | L34: TAHMIN
B35: 6001.D | C35: Klima yoğuşma drenaj borusu PVC/PPRC Ø20-25 (hatta bırakılacak) | D35: m | E35: 5 | F35: 5 | G35: fire+%30 | H35: =F35/IF(Varsayimlar!$B$21=1,1.43,1) | I35: 5 | J35: =H35*I35 | K35: GEÇMİŞ TEKLİF UYARLAMA | L35: REF-duz [ref 2.17] | M35: Ref malzeme fiyatı; montajlı
B36: 6001.D | C36: DU montaj konsolu + titreşim takozu, kablolu kumanda, montaj-test-devreye alma | D36: takım | E36: 1 | F36: 1 | G36: - | H36: =F36 | I36: 150 | J36: =H36*I36 | K36: MÜHENDİSLİK TAHMİNİ | L36: TAHMIN
B37: 6001.D | C37: Güvenlik kabini split klima inverter ~2,5 kW duvar tipi, R410A, dış ünite dahil + kapı/pencere kontak sistemi | D37: adet | E37: 2 | F37: 0 | G37: %30 | H37: =F37/IF(Varsayimlar!$B$21=1,1.3,1) | I37: 950 | J37: =H37*I37 | K37: KAPSAM DIŞI (0) | L37: REF-duz [ref 553.26] | M37: İdare: kabin splitleri sıra 143 kabin fiyatında
B38: 6001.D | C38: Güvenlik kabini split bakır boru izolasyonlu (1/4"-3/8") + bağlantı kablosu | D38: m | E38: 6 | F38: 0 | G38: fire+%30 | H38: =F38/IF(Varsayimlar!$B$21=1,1.43,1) | I38: 18 | J38: =H38*I38 | K38: KAPSAM DIŞI (0) | L38: TAHMIN | M38: İdare: kabin splitleri sıra 143 kabin fiyatında
B39: 6001.D | C39: Güvenlik kabini split yoğuşma drenaj borusu PVC Ø20 | D39: m | E39: 5 | F39: 0 | G39: fire+%30 | H39: =F39/IF(Varsayimlar!$B$21=1,1.43,1) | I39: 5 | J39: =H39*I39 | K39: KAPSAM DIŞI (0) | L39: REF-duz [ref 1.91] | M39: İdare: kabin splitleri sıra 143 kabin fiyatında
B40: 6001.D | C40: Güvenlik kabini split DU konsolu + titreşim takozu + kablolu kumanda + kontak rölesi, montaj-devreye alma | D40: takım | E40: 1 | F40: 0 | G40: - | H40: =F40 | I40: 120 | J40: =H40*I40 | K40: KAPSAM DIŞI (0) | L40: TAHMIN | M40: İdare: kabin splitleri sıra 143 kabin fiyatında
A41: 163 | B41: 6001.E | C41: Hızmalı Köprüsü İstasyonu Isıtma Soğutma Sistemi (1 set) | H41: RFQ tutarı → | I41: =SUMPRODUCT(E42:E49,I42:I49) | J41: =SUM(J42:J49)
...

Sheet Asansor
A1: 3 ASANSÖR – Sıra 364–365 (13 asansör)
A2: EUR, KDV hariç, montaj+test+devreye alma dahil (taşeron fiyatı), Ekim 2026. Turuncu miktar: idare cevabıyla (05.10.2026) değişen kalem. Metraj payı: RFQ'daki bilinçli şişirmenin (%10 fire, dağıtık malzemede %30) bütçeden geri alınması. Fiyat türü renkleri: yeşil = 2026 firma teklifi; mavi = geçmiş tekliften uyarlama (ECB kuru + Euro Bölgesi HICP ile Ağu-2026'ya taşınmış, gerekirse montaj/boyut düzeltmeli); sarı = mühendislik tahmini (emsal yok); gri = idare cevabıyla kapsam dışı.
A4: Sıra | B4: Poz | C4: Kalem / Alt kalem | D4: Birim | E4: Miktar (RFQ cetveli) | F4: Miktar (idare cevabına göre) | G4: Metraj payı geri alınan | H4: Net miktar (bütçe) | I4: Birim fiyat EUR (montaj dahil) | J4: Tutar EUR | K4: Fiyat türü | L4: Fiyat kaynağı / emsal (proje, firma, yıl, uyarlama) | M4: Not / düzeltme
A5: 364 | B5: 5010.A | C5: 2 Duraklı 13 Kişilik Asansör (12 adet – 4 üst geçit × 3) | H5: RFQ tutarı → | I5: =SUMPRODUCT(E6:E9,I6:I9) | J5: =SUM(J6:J9)
B6: 5010.A | C6: Asansör 1000 kg, 2 durak, MRL dişlisiz, VVVF, 1 m/s, cam+paslanmaz kabin – S09 Hızmalı Köprüsü | D6: adet | E6: 3 | F6: 3 | G6: - | H6: =F6 | I6: =MEDIAN(Teklifler!$G$4:$G$6) | J6: =H6*I6 | K6: 2026 TEKLİF | L6: TEKLİF medyanı (Schindler, TK, Emlift) | M6: Bakım hariç; yeşil etiket, eğitim dahil
B7: 5010.A | C7: Asansör 1000 kg – S10 Balıklıgöl | D7: adet | E7: 3 | F7: 3 | G7: - | H7: =F7 | I7: =MEDIAN(Teklifler!$G$4:$G$6) | J7: =H7*I7 | K7: 2026 TEKLİF | L7: TEKLİF medyanı
B8: 5010.A | C8: Asansör 1000 kg – S11 Eyyüp Peygamber | D8: adet | E8: 3 | F8: 3 | G8: - | H8: =F8 | I8: =MEDIAN(Teklifler!$G$4:$G$6) | J8: =H8*I8 | K8: 2026 TEKLİF | L8: TEKLİF medyanı
B9: 5010.A | C9: Asansör 1000 kg – S12 Rasathane | D9: adet | E9: 3 | F9: 3 | G9: - | H9: =F9 | I9: =MEDIAN(Teklifler!$G$4:$G$6) | J9: =H9*I9 | K9: 2026 TEKLİF | L9: TEKLİF medyanı
A10: 365 | B10: 5010.B | C10: 2 Duraklı 10 Kişilik 800 kg Asansör (D01 idari bina) | H10: RFQ tutarı → | I10: =SUMPRODUCT(E11:E11,I11:I11) | J10: =SUM(J11:J11)
B11: 5010.B | C11: Asansör 800 kg, 2 durak (zemin/1. kat), MRL, VVVF, 1 m/s – D01 | D11: adet | E11: 1 | F11: 1 | G11: - | H11: =F11 | I11: =MEDIAN(Teklifler!$H$4:$H$6) | J11: =H11*I11 | K11: 2026 TEKLİF | L11: TEKLİF medyanı
C13: TOPLAM (net metraj, idare cevaplarına göre) | J13: =J5+J10
C14: Karşılaştırma: RFQ cetvel miktarlarıyla (şişirmeli, düzeltmesiz) tutar | J14: =I5+I10
C15: Fark (metraj payları + idare cevapları) | J15: =J13-J14
C17: FİYAT TÜRÜNE GÖRE DAĞILIM
C18: 2026 TEKLİF | J18: =SUMIF($K$5:$K$11,"2026 TEKLİF",$J$5:$J$11) | K18: =IF($J$13=0,0,J18/$J$13)
C19: GEÇMİŞ TEKLİF UYARLAMA | J19: =SUMIF($K$5:$K$11,"GEÇMİŞ TEKLİF UYARLAMA",$J$5:$J$11) | K19: =IF($J$13=0,0,J19/$J$13)
C20: MÜHENDİSLİK TAHMİNİ | J20: =SUMIF($K$5:$K$11,"MÜHENDİSLİK TAHMİNİ",$J$5:$J$11) | K20: =IF($J$13=0,0,J20/$J$13)

Sheet Sinyal
A1: 4 SİNYALİZASYON VE ARAÇ TAKİP (AVLS) – Sıra 228–235
A2: EUR, KDV hariç, montaj+test+devreye alma dahil (taşeron fiyatı), Ekim 2026. Turuncu miktar: idare cevabıyla (05.10.2026) değişen kalem. Metraj payı: RFQ'daki bilinçli şişirmenin (%10 fire, dağıtık malzemede %30) bütçeden geri alınması. Fiyat türü renkleri: yeşil = 2026 firma teklifi; mavi = geçmiş tekliften uyarlama (ECB kuru + Euro Bölgesi HICP ile Ağu-2026'ya taşınmış, gerekirse montaj/boyut düzeltmeli); sarı = mühendislik tahmini (emsal yok); gri = idare cevabıyla kapsam dışı.
A4: Sıra | B4: Poz | C4: Kalem / Alt kalem | D4: Birim | E4: Miktar (RFQ cetveli) | F4: Miktar (idare cevabına göre) | G4: Metraj payı geri alınan | H4: Net miktar (bütçe) | I4: Birim fiyat EUR (montaj dahil) | J4: Tutar EUR | K4: Fiyat türü | L4: Fiyat kaynağı / emsal (proje, firma, yıl, uyarlama) | M4: Not / düzeltme
A5: 228 | B5: 3001 | C5: Sinyalizasyon Sistemi Tasarımı | H5: RFQ tutarı → | I5: =SUMPRODUCT(E6:E6,I6:I6) | J5: =SUM(J6:J6)
B6: 3001 | C6: Tasarım paketi: simülasyon, mimari/kilitleme tabloları, uygulama ve kablo projeleri, RAMS/Safety Case (SIL3/SIL2), ISA, test prosedürleri, KET izin dosyası | D6: set | E6: 1 | F6: 1 | G6: - | H6: =F6 | I6: 207246 | J6: =H6*I6 | K6: GEÇMİŞ TEKLİF UYARLAMA | L6: REF (4 ref; seçilen BF) | M6: İdare: sıra 228 yalnız tasarım; ekipman 229–232'den
A7: 229 | B7: 3001.A | C7: Hat Boyu Sinyalizasyon Sistemi | H7: RFQ tutarı → | I7: =SUMPRODUCT(E8:E46,I8:I46) | J7: =SUM(J8:J46)
B8: 3001.A | C8: Elektrikli makas motoru (IP67, iç kilitli, uç konum dedektörlü) – ana hat | D8: takım | E8: 12 | F8: 16 | G8: - | H8: =F8 | I8: 17785 | J8: =H8*I8 | K8: GEÇMİŞ TEKLİF UYARLAMA | L8: REF (CONTEC CSV24 / H&K HW61 / Elektroline TSH102: 15.255–19.316) | M8: İdare soru 3: ana hattaki tüm makaslar motorlu (+4, C4 kruvazmanı)
B9: 3001.A | C9: Makas motoru tahrik/dedeksiyon çubukları + dil kilidi seti | D9: takım | E9: 12 | F9: 16 | G9: - | H9: =F9 | I9: 2969 | J9: =H9*I9 | K9: GEÇMİŞ TEKLİF UYARLAMA | L9: REF (Bombardier bars) | M9: Motor adedine bağlı
B10: 3001.A | C10: Manuel makas hareket mekanizması (ana hat) | D10: takım | E10: 4 | F10: 0 | G10: - | H10: =F10 | I10: 5484 | J10: =H10*I10 | K10: KAPSAM DIŞI (0) | L10: REF | M10: İdare soru 3: manuel makas yok
B11: 3001.A | C11: Manuel makas konum izleme kutusu (IO/RTU) | D11: adet | E11: 1 | F11: 0 | G11: - | H11: =F11 | I11: 3000 | J11: =H11*I11 | K11: KAPSAM DIŞI (0) | L11: TAHMİN | M11: Manuel makas kalmadı
B12: 3001.A | C12: Lokal kontrol ve kumanda kabini SKP (SIL3, GRP IP54) | D12: adet | E12: 3 | F12: 4 | G12: - | H12: =F12 | I12: 88734 | J12: =H12*I12 | K12: GEÇMİŞ TEKLİF UYARLAMA | L12: REF (12 ref, medyan) | M12: C4 kruvazmanı motorlu olduğundan ilave kontrol birimi (temkinli kabul)
B13: 3001.A | C13: Sorgulayıcı (interrogator) birimi – SKP içi | D13: adet | E13: 4 | F13: 5 | G13: - | H13: =F13 | I13: 6000 | J13: =H13*I13 | K13: MÜHENDİSLİK TAHMİNİ | L13: TAHMİN | M13: SKP ile birlikte +1
B14: 3001.A | C14: Alıcı endüktif lup (güzergah talep) – makas bölgeleri | D14: adet | E14: 11 | F14: 11 | G14: - | H14: =F14 | I14: 2814 | J14: =H14*I14 | K14: GEÇMİŞ TEKLİF UYARLAMA | L14: REF (4 ref)
B15: 3001.A | C15: Ray devresi / kütle dedektörü (makas kilitleme, bölge meşgul) | D15: adet | E15: 34 | F15: 34 | G15: - | H15: =F15 | I15: 5614 | J15: =H15*I15 | K15: GEÇMİŞ TEKLİF UYARLAMA | L15: REF (4 ref)
B16: 3001.A | C16: Ana hat makas sinyal lambası 3 ışıklı LED + talep alındı lambası | D16: takım | E16: 11 | F16: 11 | G16: - | H16: =F16 | I16: 5173 | J16: =H16*I16 | K16: GEÇMİŞ TEKLİF UYARLAMA | L16: REF (3 ref)
B17: 3001.A | C17: Sinyal lamba direği – makas bölgeleri | D17: adet | E17: 11 | F17: 11 | G17: - | H17: =F17 | I17: 1200 | J17: =H17*I17 | K17: MÜHENDİSLİK TAHMİNİ | L17: TAHMİN
B18: 3001.A | C18: Lokal talep anahtarı – makas bölgeleri | D18: adet | E18: 11 | F18: 11 | G18: - | H18: =F18 | I18: 800 | J18: =H18*I18 | K18: MÜHENDİSLİK TAHMİNİ | L18: TAHMİN
B19: 3001.A | C19: Karayolu kavşağı sinyalizasyon kontrol kabini TSP (tramvay öncelik) | D19: adet | E19: 5 | F19: 5 | G19: - | H19: =F19 | I19: 8627 | J19: =H19*I19 | K19: GEÇMİŞ TEKLİF UYARLAMA | L19: REF (3 ref) | M19: Tramvay tarafı; kapsamda kalır
B20: 3001.A | C20: Alıcı endüktif lup (ON/OFF öncelik talep) – kavşaklar | D20: adet | E20: 24 | F20: 24 | G20: - | H20: =F20 | I20: 2814 | J20: =H20*I20 | K20: GEÇMİŞ TEKLİF UYARLAMA | L20: REF (makas lupu BF)
B21: 3001.A | C21: Tramvay sinyal lambası 2 ışıklı LED – kavşaklar | D21: adet | E21: 12 | F21: 12 | G21: - | H21: =F21 | I21: 3600 | J21: =H21*I21 | K21: MÜHENDİSLİK TAHMİNİ | L21: TAHMİN (tek ref 7.268 aykırı)
B22: 3001.A | C22: Tramvay sinyal direği – kavşaklar | D22: adet | E22: 12 | F22: 12 | G22: - | H22: =F22 | I22: 1200 | J22: =H22*I22 | K22: MÜHENDİSLİK TAHMİNİ | L22: TAHMİN
B23: 3001.A | C23: Lokal kumanda anahtarı – kavşaklar | D23: adet | E23: 12 | F23: 12 | G23: - | H23: =F23 | I23: 800 | J23: =H23*I23 | K23: MÜHENDİSLİK TAHMİNİ | L23: TAHMİN
B24: 3001.A | C24: Yaya geçidi tramvay uyarı seti (flaşör + levha) | D24: adet | E24: 6 | F24: 6 | G24: - | H24: =F24 | I24: 2500 | J24: =H24*I24 | K24: MÜHENDİSLİK TAHMİNİ | L24: TAHMİN
B25: 3001.A | C25: Yaya geçidi uyarı kontrol kutusu + aktivasyon lupu | D25: takım | E25: 3 | F25: 3 | G25: - | H25: =F25 | I25: 6000 | J25: =H25*I25 | K25: MÜHENDİSLİK TAHMİNİ | L25: TAHMİN
B26: 3001.A | C26: TSKP karayolu kavşak kontrol cihazı | D26: adet | E26: 6 | F26: 0 | G26: - | H26: =F26 | I26: 18000 | J26: =H26*I26 | K26: KAPSAM DIŞI (0) | L26: TAHMİN | M26: İdare soru 1: TSKP kapsam dışı
B27: 3001.A | C27: Karayolu trafik lambası 300'lük başüstü | D27: adet | E27: 20 | F27: 0 | G27: - | H27: =F27 | I27: 900 | J27: =H27*I27 | K27: KAPSAM DIŞI (0) | L27: TAHMİN | M27: İdare soru 1: kapsam dışı
B28: 3001.A | C28: Karayolu trafik lambası 200'lük direk tipi | D28: adet | E28: 44 | F28: 0 | G28: - | H28: =F28 | I28: 450 | J28: =H28*I28 | K28: KAPSAM DIŞI (0) | L28: TAHMİN | M28: İdare soru 1: kapsam dışı
B29: 3001.A | C29: Yaya lambası + yaya butonu | D29: takım | E29: 44 | F29: 0 | G29: - | H29: =F29 | I29: 500 | J29: =H29*I29 | K29: KAPSAM DIŞI (0) | L29: TAHMİN | M29: İdare soru 1: kapsam dışı
B30: 3001.A | C30: Trafik lambası direği 3,5 m / 6 m konsollu | D30: adet | E30: 64 | F30: 0 | G30: - | H30: =F30 | I30: 900 | J30: =H30*I30 | K30: KAPSAM DIŞI (0) | L30: TAHMİN | M30: İdare soru 1: kapsam dışı
B31: 3001.A | C31: Karayolu trafik sinyal kabloları (TSKP–lambalar) | D31: m | E31: 2695 | F31: 0 | G31: fire %10 | H31: =F31/IF(Varsayimlar!$B$21=1,1.1,1) | I31: 6 | J31: =H31*I31 | K31: KAPSAM DIŞI (0) | L31: TAHMİN | M31: İdare soru 1: kapsam dışı
B32: 3001.A | C32: Karayolu sinyal kablo borusu HDPE Ø63 | D32: m | E32: 1210 | F32: 0 | G32: fire %10 | H32: =F32/IF(Varsayimlar!$B$21=1,1.1,1) | I32: 4 | J32: =H32*I32 | K32: KAPSAM DIŞI (0) | L32: TAHMİN | M32: İdare soru 1: kapsam dışı
B33: 3001.A | C33: Lup besleme kablosu 2x2x1,0 ekranlı | D33: m | E33: 5468 | F33: =5468*Varsayimlar!$B$8 | G33: fire %10 | H33: =F33/IF(Varsayimlar!$B$21=1,1.1,1) | I33: 4 | J33: =H33*I33 | K33: MÜHENDİSLİK TAHMİNİ | L33: TAHMİN | M33: Hat boyu 6,44/6,56
B34: 3001.A | C34: Lup kablosu (hat yatağı içi iletken + koruma kanalı) | D34: adet | E34: 41 | F34: 41 | G34: - | H34: =F34 | I34: 400 | J34: =H34*I34 | K34: MÜHENDİSLİK TAHMİNİ | L34: TAHMİN
B35: 3001.A | C35: Ray devresi / dedektör kablosu 2x2x1,0 | D35: m | E35: 2673 | F35: =2673*Varsayimlar!$B$8 | G35: fire %10 | H35: =F35/IF(Varsayimlar!$B$21=1,1.1,1) | I35: 4 | J35: =H35*I35 | K35: MÜHENDİSLİK TAHMİNİ | L35: TAHMİN | M35: Hat boyu oranı
B36: 3001.A | C36: Makas motoru güç+kumanda kablosu 12x2,5 | D36: m | E36: 541 | F36: =ROUND(541*16/12,0) | G36: fire %10 | H36: =F36/IF(Varsayimlar!$B$21=1,1.1,1) | I36: 9 | J36: =H36*I36 | K36: MÜHENDİSLİK TAHMİNİ | L36: TAHMİN | M36: +4 motor oranında
B37: 3001.A | C37: Sinyal lambası kablosu 12x1,5 | D37: m | E37: 1348 | F37: =1348*Varsayimlar!$B$8 | G37: fire %10 | H37: =F37/IF(Varsayimlar!$B$21=1,1.1,1) | I37: 7 | J37: =H37*I37 | K37: MÜHENDİSLİK TAHMİNİ | L37: TAHMİN
B38: 3001.A | C38: Lokal kumanda anahtarı kablosu 7x1,5 | D38: m | E38: 1348 | F38: =1348*Varsayimlar!$B$8 | G38: fire %10 | H38: =F38/IF(Varsayimlar!$B$21=1,1.1,1) | I38: 4.5 | J38: =H38*I38 | K38: MÜHENDİSLİK TAHMİNİ | L38: TAHMİN
B39: 3001.A | C39: TSP/SKP–TSKP arayüz kablosu 19x1,5 | D39: m | E39: 198 | F39: 198 | G39: fire %10 | H39: =F39/IF(Varsayimlar!$B$21=1,1.1,1) | I39: 10 | J39: =H39*I39 | K39: MÜHENDİSLİK TAHMİNİ | L39: TAHMİN | M39: İdare: irtibat kablolaması kapsamda
B40: 3001.A | C40: Manuel makas konum kontağı kablosu 7x1,5 | D40: m | E40: 117 | F40: 0 | G40: fire %10 | H40: =F40/IF(Varsayimlar!$B$21=1,1.1,1) | I40: 4.5 | J40: =H40*I40 | K40: KAPSAM DIŞI (0) | L40: TAHMİN | M40: Manuel makas yok
B41: 3001.A | C41: Yaya geçidi flaş lamba kablosu 3x1,5 | D41: m | E41: 264 | F41: 264 | G41: fire %10 | H41: =F41/IF(Varsayimlar!$B$21=1,1.1,1) | I41: 2.5 | J41: =H41*I41 | K41: MÜHENDİSLİK TAHMİNİ | L41: TAHMİN
...

Sheet Cer_Guc
A1: 5 ELEKTRİFİKASYON (A) – GÜÇ TEMİNİ / CER GÜCÜ / ENERJİ TEMİNİ (5 TM, OG ring, TEİAŞ bağlantısı)
A2: EUR, KDV hariç, montaj+test+devreye alma dahil (taşeron fiyatı), Ekim 2026. Turuncu miktar: idare cevabıyla (05.10.2026) değişen kalem. Metraj payı: RFQ'daki bilinçli şişirmenin (%10 fire, dağıtık malzemede %30) bütçeden geri alınması. Fiyat türü renkleri: yeşil = 2026 firma teklifi; mavi = geçmiş tekliften uyarlama (ECB kuru + Euro Bölgesi HICP ile Ağu-2026'ya taşınmış, gerekirse montaj/boyut düzeltmeli); sarı = mühendislik tahmini (emsal yok); gri = idare cevabıyla kapsam dışı.
A4: Sıra | B4: Poz | C4: Kalem / Alt kalem | D4: Birim | E4: Miktar (RFQ cetveli) | F4: Miktar (idare cevabına göre) | G4: Metraj payı geri alınan | H4: Net miktar (bütçe) | I4: Birim fiyat EUR (montaj dahil) | J4: Tutar EUR | K4: Fiyat türü | L4: Fiyat kaynağı / emsal (proje, firma, yıl, uyarlama) | M4: Not / düzeltme
A5: 169 | B5: 2001 | C5: Güç Temini ve Cer Gücü Tasarımı | H5: RFQ tutarı → | I5: =SUMPRODUCT(E6:E7,I6:I7) | J5: =SUM(J6:J7)
B6: 2001 | C6: Uygulama projeleri (OG ring, TEİAŞ bağlantısı, 5 TM), cer gücü simülasyonu, kısa devre/selektivite, topraklama ve kaçak akım (EN 50122), kompanzasyon raporları, as-built | D6: set | E6: 1 | F6: 1 | G6: - | H6: =F6 | I6: 150000 | J6: =H6*I6 | K6: GEÇMİŞ TEKLİF UYARLAMA | L6: REF (metro: 133.738–620.171; tramvay ölçeğine indirildi)
B7: 2001 | C7: DEDAŞ/TEİAŞ bağlantı projesi onayı ve kurum masrafları | D7: set | E7: 1 | F7: 1 | G7: - | H7: =F7 | I7: 40000 | J7: =H7*I7 | K7: MÜHENDİSLİK TAHMİNİ | L7: TAHMİN
A8: 170 | B8: 2002.A | C8: OG Ring Şebekesi 3×1×240/25 mm² 20,3/35 kV Al XLPE | H8: RFQ tutarı → | I8: =SUMPRODUCT(E9:E15,I9:I15) | J8: =SUM(J9:J15)
B9: 2002.A | C9: YAXC7V-R (NA2XSY) 1×240/25 Al XLPE LSHF tek damar kablo – çekme dahil | D9: m | E9: 21000 | F9: =3*Varsayimlar!$B$12 | G9: - | H9: =F9 | I9: 11 | J9: =H9*I9 | K9: GEÇMİŞ TEKLİF UYARLAMA | L9: REF (Prysmian 1×400 15 €/m; Haluk 1×150 11 €/m) | M9: İdare soru 21: güzergah 7.964 m
B10: 2002.A | C10: 36 kV 1×240 kablo başlığı | D10: adet | E10: 24 | F10: 24 | G10: - | H10: =F10 | I10: 450 | J10: =H10*I10 | K10: MÜHENDİSLİK TAHMİNİ | L10: TAHMİN
B11: 2002.A | C11: 36 kV 1×240 ek mufu | D11: adet | E11: 33 | F11: =ROUND(33*Varsayimlar!$B$12/Varsayimlar!$B$11,0) | G11: - | H11: =F11 | I11: 400 | J11: =H11*I11 | K11: MÜHENDİSLİK TAHMİNİ | L11: TAHMİN | M11: Güzergah oranında
B12: 2002.A | C12: Trefoil kelepçe / kanal içi askı | D12: adet | E12: 6500 | F12: =ROUND(6500*Varsayimlar!$B$12/Varsayimlar!$B$11,0) | G12: - | H12: =F12 | I12: 6 | J12: =H12*I12 | K12: MÜHENDİSLİK TAHMİNİ | L12: TAHMİN | M12: Güzergah oranında
B13: 2002.A | C13: Yangın durdurucu (TM geçişleri) | D13: adet | E13: 10 | F13: 10 | G13: - | H13: =F13 | I13: 200 | J13: =H13*I13 | K13: MÜHENDİSLİK TAHMİNİ | L13: TAHMİN
B14: 2002.A | C14: Kablo etiket / güzergah markörü | D14: adet | E14: 140 | F14: =ROUND(140*Varsayimlar!$B$12/Varsayimlar!$B$11,0) | G14: - | H14: =F14 | I14: 15 | J14: =H14*I14 | K14: MÜHENDİSLİK TAHMİNİ | L14: TAHMİN
B15: 2002.A | C15: OG kablo saha testleri (VLF, kılıf) | D15: set | E15: 4 | F15: 4 | G15: - | H15: =F15 | I15: 3000 | J15: =H15*I15 | K15: MÜHENDİSLİK TAHMİNİ | L15: TAHMİN
A16: 171 | B16: 2002.B | C16: TEİAŞ Bağlantısı 2×4×(1×400+35) mm² 20,3/35 kV – transe dahil | H16: RFQ tutarı → | I16: =SUMPRODUCT(E17:E30,I17:I30) | J16: =SUM(J17:J30)
B17: 2002.B | C17: YAXC7V-R 1×400/35 Al XLPE zırhlı LSHF – çekme dahil | D17: m | E17: 35424 | F17: 35424 | G17: - | H17: =F17 | I17: 16 | J17: =H17*I17 | K17: GEÇMİŞ TEKLİF UYARLAMA | L17: REF (Prysmian 15 €/m malzeme) + çekme | M17: İdare: 8.856 m × 4 kablo – uyumlu
