Workbook

Sheet Elektrik Güç Tablosu
A1: MEKANİK EKİPMAN ELEKTRİK GÜÇ TABLOSU
A2: TMO MARDİN BAŞMÜDÜRLÜĞÜ HİZMET BİNASI — Mekanik Tesisat — Elektrik projesine esas cihaz güç, gerilim ve faz bilgileri
A4: No | B4: Cihaz Kodu | C4: Sistem | D4: Cihaz Adı | E4: Teknik Özellik | F4: Mahal | G4: Kat | H4: Adet (Toplam) | I4: Çalışan Adet | J4: Birim Güç (kW) | K4: Kurulu Güç (kW) | L4: Talep Güç (kW) | M4: Gerilim (V) | N4: Faz | O4: cos φ | P4: Birim Akım Ib (A) | Q4: Önerilen Sigorta (A) | R4: Önerilen Kablo (Cu) | S4: Besleyen Pano | T4: Plan Gösterimi | U4: Kaynak / Not
A5: 1 | B5: KZ-1 | C5: ISITMA | D5: Yoğuşmalı Duvar Tipi Doğalgaz Kazanı | E5: 80 kW, kaskad, 70/55 °C, dahili primer pompa | F5: TESHİN MERKEZİ | G5: ZEMİN KAT | H5: 1 | I5: 1 | J5: 0.3 | K5: =H5*J5 -> 0.3 | L5: =I5*J5 -> 0.3 | M5: 230 | N5: 1 | O5: 0.9 | P5: =IF(OR(J5=0,M5=0),0,IF(N5=3,J5*1000/(SQRT(3)*M5*O5),J5*1000/(M5*O5))) -> 1.4492754 | Q5: =IF(P5=0,"-",INDEX(Tablolar!$I$6:$I$14,MATCH(P5*1.25-0.001,Tablolar!$H$6:$H$14,1))) -> 10 | R5: =IF(P5=0,"-",IF(N5=3,"5x","3x")&INDEX(Tablolar!$J$6:$J$14,MATCH(P5*1.25-0.001,Tablolar!$H$6:$H$14,1))&" mm²") -> 3x2,5 mm² | S5: MP | T5: ZEMİN KAT planı | U5: KAZAN_BORU_POMPA_HESABI: 2x80 kW
A6: 2 | B6: KZ-2 | C6: ISITMA | D6: Yoğuşmalı Duvar Tipi Doğalgaz Kazanı | E6: 80 kW, kaskad, 70/55 °C, dahili primer pompa | F6: TESHİN MERKEZİ | G6: ZEMİN KAT | H6: 1 | I6: 1 | J6: 0.3 | K6: =H6*J6 -> 0.3 | L6: =I6*J6 -> 0.3 | M6: 230 | N6: 1 | O6: 0.9 | P6: =IF(OR(J6=0,M6=0),0,IF(N6=3,J6*1000/(SQRT(3)*M6*O6),J6*1000/(M6*O6))) -> 1.4492754 | Q6: =IF(P6=0,"-",INDEX(Tablolar!$I$6:$I$14,MATCH(P6*1.25-0.001,Tablolar!$H$6:$H$14,1))) -> 10 | R6: =IF(P6=0,"-",IF(N6=3,"5x","3x")&INDEX(Tablolar!$J$6:$J$14,MATCH(P6*1.25-0.001,Tablolar!$H$6:$H$14,1))&" mm²") -> 3x2,5 mm² | S6: MP | T6: ZEMİN KAT planı | U6: KAZAN_BORU_POMPA_HESABI: 2x80 kW
A7: 3 | B7: KP-1 | C7: ISITMA | D7: Kaskad Kontrol Paneli | E7: Dış hava kompanzasyonlu, BMS bağlantılı | F7: TESHİN MERKEZİ | G7: ZEMİN KAT | H7: 1 | I7: 1 | J7: 0.05 | K7: =H7*J7 -> 0.05 | L7: =I7*J7 -> 0.05 | M7: 230 | N7: 1 | O7: 0.9 | P7: =IF(OR(J7=0,M7=0),0,IF(N7=3,J7*1000/(SQRT(3)*M7*O7),J7*1000/(M7*O7))) -> 0.24154589 | Q7: =IF(P7=0,"-",INDEX(Tablolar!$I$6:$I$14,MATCH(P7*1.25-0.001,Tablolar!$H$6:$H$14,1))) -> 10 | R7: =IF(P7=0,"-",IF(N7=3,"5x","3x")&INDEX(Tablolar!$J$6:$J$14,MATCH(P7*1.25-0.001,Tablolar!$H$6:$H$14,1))&" mm²") -> 3x2,5 mm² | S7: MP | T7: ZEMİN KAT planı | U7: Isıtma v11 kazan dairesi şeması
A8: 4 | B8: P-1 | C8: ISITMA | D8: Radyatör Devresi Sirkülasyon Pompası | E8: İkiz, frekans kontrollü ıslak rotorlu; Q=4,43 m³/h, H=2,24 mSS | F8: TESHİN MERKEZİ | G8: ZEMİN KAT | H8: 2 | I8: 1 | J8: 0.2 | K8: =H8*J8 -> 0.4 | L8: =I8*J8 -> 0.2 | M8: 230 | N8: 1 | O8: 0.85 | P8: =IF(OR(J8=0,M8=0),0,IF(N8=3,J8*1000/(SQRT(3)*M8*O8),J8*1000/(M8*O8))) -> 1.0230179 | Q8: =IF(P8=0,"-",INDEX(Tablolar!$I$6:$I$14,MATCH(P8*1.25-0.001,Tablolar!$H$6:$H$14,1))) -> 10 | R8: =IF(P8=0,"-",IF(N8=3,"5x","3x")&INDEX(Tablolar!$J$6:$J$14,MATCH(P8*1.25-0.001,Tablolar!$H$6:$H$14,1))&" mm²") -> 3x2,5 mm² | S8: MP | T8: ZEMİN KAT planı | U8: KAZAN_BORU_POMPA_HESABI sf.4
A9: 5 | B9: P-2 | C9: ISITMA | D9: Boyler Devresi Sirkülasyon Pompası | E9: İkiz, ıslak rotorlu; Q=3,5 m³/h (60,7 kW, ΔT=15 K), H≈3 mSS | F9: TESHİN MERKEZİ | G9: ZEMİN KAT | H9: 2 | I9: 1 | J9: 0.15 | K9: =H9*J9 -> 0.3 | L9: =I9*J9 -> 0.15 | M9: 230 | N9: 1 | O9: 0.85 | P9: =IF(OR(J9=0,M9=0),0,IF(N9=3,J9*1000/(SQRT(3)*M9*O9),J9*1000/(M9*O9))) -> 0.76726343 | Q9: =IF(P9=0,"-",INDEX(Tablolar!$I$6:$I$14,MATCH(P9*1.25-0.001,Tablolar!$H$6:$H$14,1))) -> 10 | R9: =IF(P9=0,"-",IF(N9=3,"5x","3x")&INDEX(Tablolar!$J$6:$J$14,MATCH(P9*1.25-0.001,Tablolar!$H$6:$H$14,1))&" mm²") -> 3x2,5 mm² | S9: MP | T9: ZEMİN KAT planı | U9: BOYLER_HESABI: 60,7 kW
A10: 6 | B10: GD-1 | C10: ISITMA | D10: Doğalgaz Kaçak Dedektörü + Selenoid Vana | E10: Sesli/ışıklı alarm, NC selenoid | F10: TESHİN MERKEZİ | G10: ZEMİN KAT | H10: 1 | I10: 1 | J10: 0.02 | K10: =H10*J10 -> 0.02 | L10: =I10*J10 -> 0.02 | M10: 230 | N10: 1 | O10: 0.9 | P10: =IF(OR(J10=0,M10=0),0,IF(N10=3,J10*1000/(SQRT(3)*M10*O10),J10*1000/(M10*O10))) -> 0.096618357 | Q10: =IF(P10=0,"-",INDEX(Tablolar!$I$6:$I$14,MATCH(P10*1.25-0.001,Tablolar!$H$6:$H$14,1))) -> 10 | R10: =IF(P10=0,"-",IF(N10=3,"5x","3x")&INDEX(Tablolar!$J$6:$J$14,MATCH(P10*1.25-0.001,Tablolar!$H$6:$H$14,1))&" mm²") -> 3x2,5 mm² | S10: MP | T10: ZEMİN KAT planı | U10: Doğalgaz iç tesisat esasları
A11: 7 | B11: SP-1 | C11: SIHHİ TESİSAT | D11: Kullanım Sıcak Suyu Resirkülasyon Pompası | E11: Q=0,4 m³/h, H=0,5 mSS, bronz gövde | F11: TESHİN MERKEZİ | G11: ZEMİN KAT | H11: 1 | I11: 1 | J11: 0.05 | K11: =H11*J11 -> 0.05 | L11: =I11*J11 -> 0.05 | M11: 230 | N11: 1 | O11: 0.85 | P11: =IF(OR(J11=0,M11=0),0,IF(N11=3,J11*1000/(SQRT(3)*M11*O11),J11*1000/(M11*O11))) -> 0.25575448 | Q11: =IF(P11=0,"-",INDEX(Tablolar!$I$6:$I$14,MATCH(P11*1.25-0.001,Tablolar!$H$6:$H$14,1))) -> 10 | R11: =IF(P11=0,"-",IF(N11=3,"5x","3x")&INDEX(Tablolar!$J$6:$J$14,MATCH(P11*1.25-0.001,Tablolar!$H$6:$H$14,1))&" mm²") -> 3x2,5 mm² | S11: MP | T11: ZEMİN KAT planı | U11: SİRKÜLASYON_POMPASI_HESABI
A12: 8 | B12: B-1 | C12: SIHHİ TESİSAT | D12: Serpantinli Boyler | E12: 500 L, kazan beslemeli (elektriksiz) | F12: TESHİN MERKEZİ | G12: ZEMİN KAT | H12: 1 | I12: 1 | J12: 0 | K12: =H12*J12 -> 0 | L12: =I12*J12 -> 0 | M12: 0 | N12: 0 | O12: 1 | P12: =IF(OR(J12=0,M12=0),0,IF(N12=3,J12*1000/(SQRT(3)*M12*O12),J12*1000/(M12*O12))) -> 0 | Q12: =IF(P12=0,"-",INDEX(Tablolar!$I$6:$I$14,MATCH(P12*1.25-0.001,Tablolar!$H$6:$H$14,1))) -> - | R12: =IF(P12=0,"-",IF(N12=3,"5x","3x")&INDEX(Tablolar!$J$6:$J$14,MATCH(P12*1.25-0.001,Tablolar!$H$6:$H$14,1))&" mm²") -> - | S12: - | T12: ZEMİN KAT planı | U12: BOYLER_HESABI: 500 L
A13: 9 | B13: HD-1 | C13: SIHHİ TESİSAT | D13: Temiz Su Hidroforu (Paket) | E13: 2 pompalı, frekans konv.; Q=2x1,12 m³/h, Palt=2,9 / Püst=4,4 bar, 100 L tank | F13: YAĞ.SİS. VE GENEL SU DEPOSU | G13: ZEMİN KAT | H13: 2 | I13: 2 | J13: 0.75 | K13: =H13*J13 -> 1.5 | L13: =I13*J13 -> 1.5 | M13: 400 | N13: 3 | O13: 0.85 | P13: =IF(OR(J13=0,M13=0),0,IF(N13=3,J13*1000/(SQRT(3)*M13*O13),J13*1000/(M13*O13))) -> 1.2735668 | Q13: =IF(P13=0,"-",INDEX(Tablolar!$I$6:$I$14,MATCH(P13*1.25-0.001,Tablolar!$H$6:$H$14,1))) -> 10 | R13: =IF(P13=0,"-",IF(N13=3,"5x","3x")&INDEX(Tablolar!$J$6:$J$14,MATCH(P13*1.25-0.001,Tablolar!$H$6:$H$14,1))&" mm²") -> 5x2,5 mm² | S13: MP | T13: ZEMİN KAT planı | U13: TEMİZ_SU_DEPO_HİDROFOR_HESABI
A14: 10 | B14: SH-1 | C14: YAĞMUR SUYU | D14: Bahçe Sulama Hidroforu | E14: 2 pompalı, yağmur suyu deposundan; 1000 m² bahçe | F14: MANEVRA ODASI (BAHÇE) | G14: ZEMİN KAT | H14: 2 | I14: 1 | J14: 0.75 | K14: =H14*J14 -> 1.5 | L14: =I14*J14 -> 0.75 | M14: 230 | N14: 1 | O14: 0.85 | P14: =IF(OR(J14=0,M14=0),0,IF(N14=3,J14*1000/(SQRT(3)*M14*O14),J14*1000/(M14*O14))) -> 3.8363171 | Q14: =IF(P14=0,"-",INDEX(Tablolar!$I$6:$I$14,MATCH(P14*1.25-0.001,Tablolar!$H$6:$H$14,1))) -> 10 | R14: =IF(P14=0,"-",IF(N14=3,"5x","3x")&INDEX(Tablolar!$J$6:$J$14,MATCH(P14*1.25-0.001,Tablolar!$H$6:$H$14,1))&" mm²") -> 3x2,5 mm² | S14: MP | T14: ZEMİN KAT planı | U14: YAĞMUR_SUYU_HESABI / mardin_2
A15: 11 | B15: YP-1 | C15: YAĞMUR SUYU | D15: Yağmur Suyu Deposu Taşma/Boşaltma Dalgıç Pompası | E15: 12 m³ gömülü depo, flatörlü | F15: YAĞMUR SUYU DEPOSU (BAHÇE) | G15: ZEMİN KAT | H15: 1 | I15: 1 | J15: 1.1 | K15: =H15*J15 -> 1.1 | L15: =I15*J15 -> 1.1 | M15: 230 | N15: 1 | O15: 0.85 | P15: =IF(OR(J15=0,M15=0),0,IF(N15=3,J15*1000/(SQRT(3)*M15*O15),J15*1000/(M15*O15))) -> 5.6265985 | Q15: =IF(P15=0,"-",INDEX(Tablolar!$I$6:$I$14,MATCH(P15*1.25-0.001,Tablolar!$H$6:$H$14,1))) -> 10 | R15: =IF(P15=0,"-",IF(N15=3,"5x","3x")&INDEX(Tablolar!$J$6:$J$14,MATCH(P15*1.25-0.001,Tablolar!$H$6:$H$14,1))&" mm²") -> 3x2,5 mm² | S15: MP | T15: ZEMİN KAT planı | U15: Edirne yağmur suyu (1-1,5 kW)
A16: 12 | B16: EF-01 | C16: HAVALANDIRMA | D16: Teshin Merkezi Taze Hava Fanı | E16: Kanal tipi aksiyal, ex-proof, 750 m³/h | F16: TESHİN MERKEZİ | G16: ZEMİN KAT | H16: 1 | I16: 1 | J16: 0.2 | K16: =H16*J16 -> 0.2 | L16: =I16*J16 -> 0.2 | M16: 230 | N16: 1 | O16: 0.85 | P16: =IF(OR(J16=0,M16=0),0,IF(N16=3,J16*1000/(SQRT(3)*M16*O16),J16*1000/(M16*O16))) -> 1.0230179 | Q16: =IF(P16=0,"-",INDEX(Tablolar!$I$6:$I$14,MATCH(P16*1.25-0.001,Tablolar!$H$6:$H$14,1))) -> 10 | R16: =IF(P16=0,"-",IF(N16=3,"5x","3x")&INDEX(Tablolar!$J$6:$J$14,MATCH(P16*1.25-0.001,Tablolar!$H$6:$H$14,1))&" mm²") -> 3x2,5 mm² | S16: MP | T16: ZEMİN KAT planı | U16: Edirne HVL EF-01 eşdeğeri
... A25: 21 | B25: SPLT-1 | C25: KLİMA | D25: Server Odası Split Klima (İç+Dış) | E25: 12.000 Btu/h (3,5 kW), 7/24, 1 asıl + 1 yedek | F25: SERVER ODASI | G25: ZEMİN KAT | H25: 2 | I25: 1 | J25: 1.1 | K25: =H25*J25 -> 2.2 | L25: =I25*J25 -> 1.1 | M25: 230 | N25: 1 | O25: 0.9 | P25: =IF(OR(J25=0,M25=0),0,IF(N25=3,J25*1000/(SQRT(3)*M25*O25),J25*1000/(M25*O25))) -> 5.3140097 | Q25: =IF(P25=0,"-",INDEX(Tablolar!$I$6:$I$14,MATCH(P25*1.25-0.001,Tablolar!$H$6:$H$14,1))) -> 10 | R25: =IF(P25=0,"-",IF(N25=3,"5x","3x")&INDEX(Tablolar!$J$6:$J$14,MATCH(P25*1.25-0.001,Tablolar!$H$6:$H$14,1))&" mm²") -> 3x2,5 mm² | S25: ZKTP | T25: ZEMİN KAT planı | U25: Edirne SPLT-1 eşdeğeri
A26: 22 | B26: VRF-1A | C26: KLİMA (VRF) | D26: VRF Dış Ünite (VRF-1) | E26: 12 HP, 33.5 kW soğutma, tam DC inverter; Zemin Kat + 1. Kat | F26: BAHÇE - BETON KAİDE (KUZEY) | G26: ZEMİN KAT | H26: 1 | I26: 1 | J26: ='VRF Dış Üniteler'!E5 -> 13.8 | K26: =H26*J26 -> 13.8 | L26: =I26*J26 -> 13.8 | M26: 400 | N26: 3 | O26: 0.95 | P26: =IF(OR(J26=0,M26=0),0,IF(N26=3,J26*1000/(SQRT(3)*M26*O26),J26*1000/(M26*O26))) -> 20.966931 | Q26: =IF(P26=0,"-",INDEX(Tablolar!$I$6:$I$14,MATCH(P26*1.25-0.001,Tablolar!$H$6:$H$14,1))) -> 32 | R26: =IF(P26=0,"-",IF(N26=3,"5x","3x")&INDEX(Tablolar!$J$6:$J$14,MATCH(P26*1.25-0.001,Tablolar!$H$6:$H$14,1))&" mm²") -> 5x6 mm² | S26: VRF-P | T26: ZEMİN KAT planı | U26: VRF Dış Üniteler sayfası
A27: 23 | B27: VRF-1B | C27: KLİMA (VRF) | D27: VRF Dış Ünite (VRF-1) | E27: 12 HP, 33.5 kW soğutma, tam DC inverter; Zemin Kat + 1. Kat | F27: BAHÇE - BETON KAİDE (KUZEY) | G27: ZEMİN KAT | H27: 1 | I27: 1 | J27: ='VRF Dış Üniteler'!E6 -> 13.8 | K27: =H27*J27 -> 13.8 | L27: =I27*J27 -> 13.8 | M27: 400 | N27: 3 | O27: 0.95 | P27: =IF(OR(J27=0,M27=0),0,IF(N27=3,J27*1000/(SQRT(3)*M27*O27),J27*1000/(M27*O27))) -> 20.966931 | Q27: =IF(P27=0,"-",INDEX(Tablolar!$I$6:$I$14,MATCH(P27*1.25-0.001,Tablolar!$H$6:$H$14,1))) -> 32 | R27: =IF(P27=0,"-",IF(N27=3,"5x","3x")&INDEX(Tablolar!$J$6:$J$14,MATCH(P27*1.25-0.001,Tablolar!$H$6:$H$14,1))&" mm²") -> 5x6 mm² | S27: VRF-P | T27: ZEMİN KAT planı | U27: VRF Dış Üniteler sayfası
A28: 24 | B28: VRF-2A | C28: KLİMA (VRF) | D28: VRF Dış Ünite (VRF-2) | E28: 18 HP, 50.0 kW soğutma, tam DC inverter; 2. Kat | F28: BAHÇE - BETON KAİDE (KUZEY) | G28: ZEMİN KAT | H28: 1 | I28: 1 | J28: ='VRF Dış Üniteler'!E7 -> 21 | K28: =H28*J28 -> 21 | L28: =I28*J28 -> 21 | M28: 400 | N28: 3 | O28: 0.95 | P28: =IF(OR(J28=0,M28=0),0,IF(N28=3,J28*1000/(SQRT(3)*M28*O28),J28*1000/(M28*O28))) -> 31.906199 | Q28: =IF(P28=0,"-",INDEX(Tablolar!$I$6:$I$14,MATCH(P28*1.25-0.001,Tablolar!$H$6:$H$14,1))) -> 40 | R28: =IF(P28=0,"-",IF(N28=3,"5x","3x")&INDEX(Tablolar!$J$6:$J$14,MATCH(P28*1.25-0.001,Tablolar!$H$6:$H$14,1))&" mm²") -> 5x10 mm² | S28: VRF-P | T28: ZEMİN KAT planı | U28: VRF Dış Üniteler sayfası
A29: 25 | B29: TİP-21 | C29: KLİMA (VRF) | D29: VRF İç Ünite (VRF-1) | E29: Kaset Tip 4 Yöne Üflemeli, 2.2 kW soğ. / 2.5 kW ısıtma | F29: ZEMİN KAT ofis/çalışma mahalleri | G29: ZEMİN KAT | H29: =SUMIFS('VRF İç Üniteler'!$H$5:$H$34,'VRF İç Üniteler'!$A$5:$A$34,G29,'VRF İç Üniteler'!$G$5:$G$34,B29,'VRF İç Üniteler'!$O$5:$O$34,"VRF-1") -> 3 | I29: =H29 -> 3 | J29: =INDEX(Tablolar!$E$5:$E$10,MATCH(B29,Tablolar!$A$5:$A$10,0))/1000 -> 0.05 | K29: =H29*J29 -> 0.15 | L29: =I29*J29 -> 0.15 | M29: 230 | N29: 1 | O29: 0.9 | P29: =IF(OR(J29=0,M29=0),0,IF(N29=3,J29*1000/(SQRT(3)*M29*O29),J29*1000/(M29*O29))) -> 0.24154589 | Q29: =IF(P29=0,"-",INDEX(Tablolar!$I$6:$I$14,MATCH(P29*1.25-0.001,Tablolar!$H$6:$H$14,1))) -> 10 | R29: =IF(P29=0,"-",IF(N29=3,"5x","3x")&INDEX(Tablolar!$J$6:$J$14,MATCH(P29*1.25-0.001,Tablolar!$H$6:$H$14,1))&" mm²") -> 3x2,5 mm² | S29: ZKTP | T29: ZEMİN KAT planı | U29: VRF İç Üniteler sayfası (adet mahal listesinden)
A30: 26 | B30: TİP-25 | C30: KLİMA (VRF) | D30: VRF İç Ünite (VRF-1) | E30: Kaset Tip 4 Yöne Üflemeli, 5.6 kW soğ. / 6.3 kW ısıtma | F30: ZEMİN KAT ofis/çalışma mahalleri | G30: ZEMİN KAT | H30: =SUMIFS('VRF İç Üniteler'!$H$5:$H$34,'VRF İç Üniteler'!$A$5:$A$34,G30,'VRF İç Üniteler'!$G$5:$G$34,B30,'VRF İç Üniteler'!$O$5:$O$34,"VRF-1") -> 2 | I30: =H30 -> 2 | J30: =INDEX(Tablolar!$E$5:$E$10,MATCH(B30,Tablolar!$A$5:$A$10,0))/1000 -> 0.062 | K30: =H30*J30 -> 0.124 | L30: =I30*J30 -> 0.124 | M30: 230 | N30: 1 | O30: 0.9 | P30: =IF(OR(J30=0,M30=0),0,IF(N30=3,J30*1000/(SQRT(3)*M30*O30),J30*1000/(M30*O30))) -> 0.29951691 | Q30: =IF(P30=0,"-",INDEX(Tablolar!$I$6:$I$14,MATCH(P30*1.25-0.001,Tablolar!$H$6:$H$14,1))) -> 10 | R30: =IF(P30=0,"-",IF(N30=3,"5x","3x")&INDEX(Tablolar!$J$6:$J$14,MATCH(P30*1.25-0.001,Tablolar!$H$6:$H$14,1))&" mm²") -> 3x2,5 mm² | S30: ZKTP | T30: ZEMİN KAT planı | U30: VRF İç Üniteler sayfası (adet mahal listesinden)
A31: 27 | B31: TİP-22 | C31: KLİMA (VRF) | D31: VRF İç Ünite (VRF-1) | E31: Kaset Tip 4 Yöne Üflemeli, 2.8 kW soğ. / 3.2 kW ısıtma | F31: ZEMİN KAT ofis/çalışma mahalleri | G31: ZEMİN KAT | H31: =SUMIFS('VRF İç Üniteler'!$H$5:$H$34,'VRF İç Üniteler'!$A$5:$A$34,G31,'VRF İç Üniteler'!$G$5:$G$34,B31,'VRF İç Üniteler'!$O$5:$O$34,"VRF-1") -> 2 | I31: =H31 -> 2 | J31: =INDEX(Tablolar!$E$5:$E$10,MATCH(B31,Tablolar!$A$5:$A$10,0))/1000 -> 0.05 | K31: =H31*J31 -> 0.1 | L31: =I31*J31 -> 0.1 | M31: 230 | N31: 1 | O31: 0.9 | P31: =IF(OR(J31=0,M31=0),0,IF(N31=3,J31*1000/(SQRT(3)*M31*O31),J31*1000/(M31*O31))) -> 0.24154589 | Q31: =IF(P31=0,"-",INDEX(Tablolar!$I$6:$I$14,MATCH(P31*1.25-0.001,Tablolar!$H$6:$H$14,1))) -> 10 | R31: =IF(P31=0,"-",IF(N31=3,"5x","3x")&INDEX(Tablolar!$J$6:$J$14,MATCH(P31*1.25-0.001,Tablolar!$H$6:$H$14,1))&" mm²") -> 3x2,5 mm² | S31: ZKTP | T31: ZEMİN KAT planı | U31: VRF İç Üniteler sayfası (adet mahal listesinden)
A32: 28 | B32: TİP-23 | C32: KLİMA (VRF) | D32: VRF İç Ünite (VRF-1) | E32: Kaset Tip 4 Yöne Üflemeli, 3.6 kW soğ. / 4.0 kW ısıtma | F32: ZEMİN KAT ofis/çalışma mahalleri | G32: ZEMİN KAT | H32: =SUMIFS('VRF İç Üniteler'!$H$5:$H$34,'VRF İç Üniteler'!$A$5:$A$34,G32,'VRF İç Üniteler'!$G$5:$G$34,B32,'VRF İç Üniteler'!$O$5:$O$34,"VRF-1") -> 1 | I32: =H32 -> 1 | J32: =INDEX(Tablolar!$E$5:$E$10,MATCH(B32,Tablolar!$A$5:$A$10,0))/1000 -> 0.06 | K32: =H32*J32 -> 0.06 | L32: =I32*J32 -> 0.06 | M32: 230 | N32: 1 | O32: 0.9 | P32: =IF(OR(J32=0,M32=0),0,IF(N32=3,J32*1000/(SQRT(3)*M32*O32),J32*1000/(M32*O32))) -> 0.28985507 | Q32: =IF(P32=0,"-",INDEX(Tablolar!$I$6:$I$14,MATCH(P32*1.25-0.001,Tablolar!$H$6:$H$14,1))) -> 10 | R32: =IF(P32=0,"-",IF(N32=3,"5x","3x")&INDEX(Tablolar!$J$6:$J$14,MATCH(P32*1.25-0.001,Tablolar!$H$6:$H$14,1))&" mm²") -> 3x2,5 mm² | S32: ZKTP | T32: ZEMİN KAT planı | U32: VRF İç Üniteler sayfası (adet mahal listesinden)
A33: 29 | B33: TİP-22 | C33: KLİMA (VRF) | D33: VRF İç Ünite (VRF-1) | E33: Kaset Tip 4 Yöne Üflemeli, 2.8 kW soğ. / 3.2 kW ısıtma | F33: 1. KAT ofis/çalışma mahalleri | G33: 1. KAT | H33: =SUMIFS('VRF İç Üniteler'!$H$5:$H$34,'VRF İç Üniteler'!$A$5:$A$34,G33,'VRF İç Üniteler'!$G$5:$G$34,B33,'VRF İç Üniteler'!$O$5:$O$34,"VRF-1") -> 7 | I33: =H33 -> 7 | J33: =INDEX(Tablolar!$E$5:$E$10,MATCH(B33,Tablolar!$A$5:$A$10,0))/1000 -> 0.05 | K33: =H33*J33 -> 0.35 | L33: =I33*J33 -> 0.35 | M33: 230 | N33: 1 | O33: 0.9 | P33: =IF(OR(J33=0,M33=0),0,IF(N33=3,J33*1000/(SQRT(3)*M33*O33),J33*1000/(M33*O33))) -> 0.24154589 | Q33: =IF(P33=0,"-",INDEX(Tablolar!$I$6:$I$14,MATCH(P33*1.25-0.001,Tablolar!$H$6:$H$14,1))) -> 10 | R33: =IF(P33=0,"-",IF(N33=3,"5x","3x")&INDEX(Tablolar!$J$6:$J$14,MATCH(P33*1.25-0.001,Tablolar!$H$6:$H$14,1))&" mm²") -> 3x2,5 mm² | S33: 1KTP | T33: 1. KAT planı | U33: VRF İç Üniteler sayfası (adet mahal listesinden)
A34: 30 | B34: TİP-24 | C34: KLİMA (VRF) | D34: VRF İç Ünite (VRF-1) | E34: Kaset Tip 4 Yöne Üflemeli, 4.5 kW soğ. / 5.0 kW ısıtma | F34: 1. KAT ofis/çalışma mahalleri | G34: 1. KAT | H34: =SUMIFS('VRF İç Üniteler'!$H$5:$H$34,'VRF İç Üniteler'!$A$5:$A$34,G34,'VRF İç Üniteler'!$G$5:$G$34,B34,'VRF İç Üniteler'!$O$5:$O$34,"VRF-1") -> 2 | I34: =H34 -> 2 | J34: =INDEX(Tablolar!$E$5:$E$10,MATCH(B34,Tablolar!$A$5:$A$10,0))/1000 -> 0.06 | K34: =H34*J34 -> 0.12 | L34: =I34*J34 -> 0.12 | M34: 230 | N34: 1 | O34: 0.9 | P34: =IF(OR(J34=0,M34=0),0,IF(N34=3,J34*1000/(SQRT(3)*M34*O34),J34*1000/(M34*O34))) -> 0.28985507 | Q34: =IF(P34=0,"-",INDEX(Tablolar!$I$6:$I$14,MATCH(P34*1.25-0.001,Tablolar!$H$6:$H$14,1))) -> 10 | R34: =IF(P34=0,"-",IF(N34=3,"5x","3x")&INDEX(Tablolar!$J$6:$J$14,MATCH(P34*1.25-0.001,Tablolar!$H$6:$H$14,1))&" mm²") -> 3x2,5 mm² | S34: 1KTP | T34: 1. KAT planı | U34: VRF İç Üniteler sayfası (adet mahal listesinden)
A35: 31 | B35: TİP-23 | C35: KLİMA (VRF) | D35: VRF İç Ünite (VRF-1) | E35: Kaset Tip 4 Yöne Üflemeli, 3.6 kW soğ. / 4.0 kW ısıtma | F35: 1. KAT ofis/çalışma mahalleri | G35: 1. KAT | H35: =SUMIFS('VRF İç Üniteler'!$H$5:$H$34,'VRF İç Üniteler'!$A$5:$A$34,G35,'VRF İç Üniteler'!$G$5:$G$34,B35,'VRF İç Üniteler'!$O$5:$O$34,"VRF-1") -> 4 | I35: =H35 -> 4 | J35: =INDEX(Tablolar!$E$5:$E$10,MATCH(B35,Tablolar!$A$5:$A$10,0))/1000 -> 0.06 | K35: =H35*J35 -> 0.24 | L35: =I35*J35 -> 0.24 | M35: 230 | N35: 1 | O35: 0.9 | P35: =IF(OR(J35=0,M35=0),0,IF(N35=3,J35*1000/(SQRT(3)*M35*O35),J35*1000/(M35*O35))) -> 0.28985507 | Q35: =IF(P35=0,"-",INDEX(Tablolar!$I$6:$I$14,MATCH(P35*1.25-0.001,Tablolar!$H$6:$H$14,1))) -> 10 | R35: =IF(P35=0,"-",IF(N35=3,"5x","3x")&INDEX(Tablolar!$J$6:$J$14,MATCH(P35*1.25-0.001,Tablolar!$H$6:$H$14,1))&" mm²") -> 3x2,5 mm² | S35: 1KTP | T35: 1. KAT planı | U35: VRF İç Üniteler sayfası (adet mahal listesinden)
A36: 32 | B36: TİP-21 | C36: KLİMA (VRF) | D36: VRF İç Ünite (VRF-1) | E36: Kaset Tip 4 Yöne Üflemeli, 2.2 kW soğ. / 2.5 kW ısıtma | F36: 1. KAT ofis/çalışma mahalleri | G36: 1. KAT | H36: =SUMIFS('VRF İç Üniteler'!$H$5:$H$34,'VRF İç Üniteler'!$A$5:$A$34,G36,'VRF İç Üniteler'!$G$5:$G$34,B36,'VRF İç Üniteler'!$O$5:$O$34,"VRF-1") -> 1 | I36: =H36 -> 1 | J36: =INDEX(Tablolar!$E$5:$E$10,MATCH(B36,Tablolar!$A$5:$A$10,0))/1000 -> 0.05 | K36: =H36*J36 -> 0.05 | L36: =I36*J36 -> 0.05 | M36: 230 | N36: 1 | O36: 0.9 | P36: =IF(OR(J36=0,M36=0),0,IF(N36=3,J36*1000/(SQRT(3)*M36*O36),J36*1000/(M36*O36))) -> 0.24154589 | Q36: =IF(P36=0,"-",INDEX(Tablolar!$I$6:$I$14,MATCH(P36*1.25-0.001,Tablolar!$H$6:$H$14,1))) -> 10 | R36: =IF(P36=0,"-",IF(N36=3,"5x","3x")&INDEX(Tablolar!$J$6:$J$14,MATCH(P36*1.25-0.001,Tablolar!$H$6:$H$14,1))&" mm²") -> 3x2,5 mm² | S36: 1KTP | T36: 1. KAT planı | U36: VRF İç Üniteler sayfası (adet mahal listesinden)
A37: 33 | B37: TİP-23 | C37: KLİMA (VRF) | D37: VRF İç Ünite (VRF-2) | E37: Kaset Tip 4 Yöne Üflemeli, 3.6 kW soğ. / 4.0 kW ısıtma | F37: 2. KAT ofis/çalışma mahalleri | G37: 2. KAT | H37: =SUMIFS('VRF İç Üniteler'!$H$5:$H$34,'VRF İç Üniteler'!$A$5:$A$34,G37,'VRF İç Üniteler'!$G$5:$G$34,B37,'VRF İç Üniteler'!$O$5:$O$34,"VRF-2") -> 9 | I37: =H37 -> 9 | J37: =INDEX(Tablolar!$E$5:$E$10,MATCH(B37,Tablolar!$A$5:$A$10,0))/1000 -> 0.06 | K37: =H37*J37 -> 0.54 | L37: =I37*J37 -> 0.54 | M37: 230 | N37: 1 | O37: 0.9 | P37: =IF(OR(J37=0,M37=0),0,IF(N37=3,J37*1000/(SQRT(3)*M37*O37),J37*1000/(M37*O37))) -> 0.28985507 | Q37: =IF(P37=0,"-",INDEX(Tablolar!$I$6:$I$14,MATCH(P37*1.25-0.001,Tablolar!$H$6:$H$14,1))) -> 10 | R37: =IF(P37=0,"-",IF(N37=3,"5x","3x")&INDEX(Tablolar!$J$6:$J$14,MATCH(P37*1.25-0.001,Tablolar!$H$6:$H$14,1))&" mm²") -> 3x2,5 mm² | S37: 2KTP | T37: 2. KAT planı | U37: VRF İç Üniteler sayfası (adet mahal listesinden)
A38: 34 | B38: TİP-24 | C38: KLİMA (VRF) | D38: VRF İç Ünite (VRF-2) | E38: Kaset Tip 4 Yöne Üflemeli, 4.5 kW soğ. / 5.0 kW ısıtma | F38: 2. KAT ofis/çalışma mahalleri | G38: 2. KAT | H38: =SUMIFS('VRF İç Üniteler'!$H$5:$H$34,'VRF İç Üniteler'!$A$5:$A$34,G38,'VRF İç Üniteler'!$G$5:$G$34,B38,'VRF İç Üniteler'!$O$5:$O$34,"VRF-2") -> 4 | I38: =H38 -> 4 | J38: =INDEX(Tablolar!$E$5:$E$10,MATCH(B38,Tablolar!$A$5:$A$10,0))/1000 -> 0.06 | K38: =H38*J38 -> 0.24 | L38: =I38*J38 -> 0.24 | M38: 230 | N38: 1 | O38: 0.9 | P38: =IF(OR(J38=0,M38=0),0,IF(N38=3,J38*1000/(SQRT(3)*M38*O38),J38*1000/(M38*O38))) -> 0.28985507 | Q38: =IF(P38=0,"-",INDEX(Tablolar!$I$6:$I$14,MATCH(P38*1.25-0.001,Tablolar!$H$6:$H$14,1))) -> 10 | R38: =IF(P38=0,"-",IF(N38=3,"5x","3x")&INDEX(Tablolar!$J$6:$J$14,MATCH(P38*1.25-0.001,Tablolar!$H$6:$H$14,1))&" mm²") -> 3x2,5 mm² | S38: 2KTP | T38: 2. KAT planı | U38: VRF İç Üniteler sayfası (adet mahal listesinden)
A39: 35 | B39: TİP-22 | C39: KLİMA (VRF) | D39: VRF İç Ünite (VRF-2) | E39: Kaset Tip 4 Yöne Üflemeli, 2.8 kW soğ. / 3.2 kW ısıtma | F39: 2. KAT ofis/çalışma mahalleri | G39: 2. KAT | H39: =SUMIFS('VRF İç Üniteler'!$H$5:$H$34,'VRF İç Üniteler'!$A$5:$A$34,G39,'VRF İç Üniteler'!$G$5:$G$34,B39,'VRF İç Üniteler'!$O$5:$O$34,"VRF-2") -> 2 | I39: =H39 -> 2 | J39: =INDEX(Tablolar!$E$5:$E$10,MATCH(B39,Tablolar!$A$5:$A$10,0))/1000 -> 0.05 | K39: =H39*J39 -> 0.1 | L39: =I39*J39 -> 0.1 | M39: 230 | N39: 1 | O39: 0.9 | P39: =IF(OR(J39=0,M39=0),0,IF(N39=3,J39*1000/(SQRT(3)*M39*O39),J39*1000/(M39*O39))) -> 0.24154589 | Q39: =IF(P39=0,"-",INDEX(Tablolar!$I$6:$I$14,MATCH(P39*1.25-0.001,Tablolar!$H$6:$H$14,1))) -> 10 | R39: =IF(P39=0,"-",IF(N39=3,"5x","3x")&INDEX(Tablolar!$J$6:$J$14,MATCH(P39*1.25-0.001,Tablolar!$H$6:$H$14,1))&" mm²") -> 3x2,5 mm² | S39: 2KTP | T39: 2. KAT planı | U39: VRF İç Üniteler sayfası (adet mahal listesinden)
C41: SİSTEM BAZINDA TOPLAMLAR
C42: ISITMA | H42: =SUMIF($C$5:$C$39,C42,$H$5:$H$39) -> 8 | K42: =SUMIF($C$5:$C$39,C42,$K$5:$K$39) -> 1.37 | L42: =SUMIF($C$5:$C$39,C42,$L$5:$L$39) -> 1.02
C43: SIHHİ TESİSAT | H43: =SUMIF($C$5:$C$39,C43,$H$5:$H$39) -> 4 | K43: =SUMIF($C$5:$C$39,C43,$K$5:$K$39) -> 1.55 | L43: =SUMIF($C$5:$C$39,C43,$L$5:$L$39) -> 1.55
C44: YAĞMUR SUYU | H44: =SUMIF($C$5:$C$39,C44,$H$5:$H$39) -> 3 | K44: =SUMIF($C$5:$C$39,C44,$K$5:$K$39) -> 2.6 | L44: =SUMIF($C$5:$C$39,C44,$L$5:$L$39) -> 1.85
C45: HAVALANDIRMA | H45: =SUMIF($C$5:$C$39,C45,$H$5:$H$39) -> 8 | K45: =SUMIF($C$5:$C$39,C45,$K$5:$K$39) -> 1.7 | L45: =SUMIF($C$5:$C$39,C45,$L$5:$L$39) -> 1.7
C46: KLİMA | H46: =SUMIF($C$5:$C$39,C46,$H$5:$H$39) -> 3 | K46: =SUMIF($C$5:$C$39,C46,$K$5:$K$39) -> 2.22 | L46: =SUMIF($C$5:$C$39,C46,$L$5:$L$39) -> 1.12
C47: KLİMA (VRF) | H47: =SUMIF($C$5:$C$39,C47,$H$5:$H$39) -> 40 | K47: =SUMIF($C$5:$C$39,C47,$K$5:$K$39) -> 50.674 | L47: =SUMIF($C$5:$C$39,C47,$L$5:$L$39) -> 50.674
C48: GENEL TOPLAM (MEKANİK) | H48: =SUM(H42:H47) -> 66 | K48: =SUM(K42:K47) -> 60.114 | L48: =SUM(L42:L47) -> 57.914
A50: LEJANT: Mavi yazı = değiştirilebilir girdi (adet, birim güç, gerilim, faz, cos φ) · Yeşil yazı = diğer sayfadan bağlantı · Siyah = formül.
A51: Kurulu Güç = Adet × Birim Güç · Talep Güç = Çalışan Adet × Birim Güç (yedek/stand-by cihazlar hariç).
...

Sheet Pano ve Kat Özeti
A1: PANO VE KAT BAZINDA MEKANİK YÜK ÖZETİ
A2: TMO MARDİN BAŞMÜDÜRLÜĞÜ HİZMET BİNASI — Mekanik Tesisat
A4: Besleyen Pano | B4: Açıklama | C4: Cihaz Adedi | D4: Kurulu Güç (kW) | E4: Talep Güç (kW) | F4: Pay (Talep)
A5: MP | B5: Mekanik Pano - Teshin Merkezi (ısıtma, hidrofor, yağmur suyu, teshin fanları) | C5: =SUMIF('Elektrik Güç Tablosu'!$S$5:$S$39,A5,'Elektrik Güç Tablosu'!$H$5:$H$39) -> 16 | D5: =SUMIF('Elektrik Güç Tablosu'!$S$5:$S$39,A5,'Elektrik Güç Tablosu'!$K$5:$K$39) -> 5.92 | E5: =SUMIF('Elektrik Güç Tablosu'!$S$5:$S$39,A5,'Elektrik Güç Tablosu'!$L$5:$L$39) -> 4.82 | F5: =IF($E$10=0,0,E5/$E$10) -> 0.083226854
A6: VRF-P | B6: VRF Dış Ünite Panosu (400V 3N~) | C6: =SUMIF('Elektrik Güç Tablosu'!$S$5:$S$39,A6,'Elektrik Güç Tablosu'!$H$5:$H$39) -> 3 | D6: =SUMIF('Elektrik Güç Tablosu'!$S$5:$S$39,A6,'Elektrik Güç Tablosu'!$K$5:$K$39) -> 48.6 | E6: =SUMIF('Elektrik Güç Tablosu'!$S$5:$S$39,A6,'Elektrik Güç Tablosu'!$L$5:$L$39) -> 48.6 | F6: =IF($E$10=0,0,E6/$E$10) -> 0.83917533
A7: ZKTP | B7: Zemin Kat Tali Panosu | C7: =SUMIF('Elektrik Güç Tablosu'!$S$5:$S$39,A7,'Elektrik Güç Tablosu'!$H$5:$H$39) -> 14 | D7: =SUMIF('Elektrik Güç Tablosu'!$S$5:$S$39,A7,'Elektrik Güç Tablosu'!$K$5:$K$39) -> 3.254 | E7: =SUMIF('Elektrik Güç Tablosu'!$S$5:$S$39,A7,'Elektrik Güç Tablosu'!$L$5:$L$39) -> 2.154 | F7: =IF($E$10=0,0,E7/$E$10) -> 0.037193079
A8: 1KTP | B8: 1. Kat Tali Panosu | C8: =SUMIF('Elektrik Güç Tablosu'!$S$5:$S$39,A8,'Elektrik Güç Tablosu'!$H$5:$H$39) -> 15 | D8: =SUMIF('Elektrik Güç Tablosu'!$S$5:$S$39,A8,'Elektrik Güç Tablosu'!$K$5:$K$39) -> 1.01 | E8: =SUMIF('Elektrik Güç Tablosu'!$S$5:$S$39,A8,'Elektrik Güç Tablosu'!$L$5:$L$39) -> 1.01 | F8: =IF($E$10=0,0,E8/$E$10) -> 0.017439652
A9: 2KTP | B9: 2. Kat Tali Panosu | C9: =SUMIF('Elektrik Güç Tablosu'!$S$5:$S$39,A9,'Elektrik Güç Tablosu'!$H$5:$H$39) -> 17 | D9: =SUMIF('Elektrik Güç Tablosu'!$S$5:$S$39,A9,'Elektrik Güç Tablosu'!$K$5:$K$39) -> 1.33 | E9: =SUMIF('Elektrik Güç Tablosu'!$S$5:$S$39,A9,'Elektrik Güç Tablosu'!$L$5:$L$39) -> 1.33 | F9: =IF($E$10=0,0,E9/$E$10) -> 0.022965086
A10: TOPLAM | C10: =SUM(C5:C9) -> 65 | D10: =SUM(D5:D9) -> 60.114 | E10: =SUM(E5:E9) -> 57.914 | F10: =SUM(F5:F9) -> 1
A11: Kontrol: genel toplam ile fark (0 olmalı) | D11: =D10-'Elektrik Güç Tablosu'!K48 -> 0
A13: Kat | B13: Açıklama | C13: Cihaz Adedi | D13: Kurulu Güç (kW) | E13: Talep Güç (kW) | F13: Pay (Talep)
A14: ZEMİN KAT | B14: Teshin merkezi, su deposu, bahçe (VRF dış üniteler dahil) | C14: =SUMIF('Elektrik Güç Tablosu'!$G$5:$G$39,A14,'Elektrik Güç Tablosu'!$H$5:$H$39) -> 34 | D14: =SUMIF('Elektrik Güç Tablosu'!$G$5:$G$39,A14,'Elektrik Güç Tablosu'!$K$5:$K$39) -> 57.774 | E14: =SUMIF('Elektrik Güç Tablosu'!$G$5:$G$39,A14,'Elektrik Güç Tablosu'!$L$5:$L$39) -> 55.574 | F14: =IF($E$17=0,0,E14/$E$17) -> 0.95959526
A15: 1. KAT | B15: Ofisler | C15: =SUMIF('Elektrik Güç Tablosu'!$G$5:$G$39,A15,'Elektrik Güç Tablosu'!$H$5:$H$39) -> 15 | D15: =SUMIF('Elektrik Güç Tablosu'!$G$5:$G$39,A15,'Elektrik Güç Tablosu'!$K$5:$K$39) -> 1.01 | E15: =SUMIF('Elektrik Güç Tablosu'!$G$5:$G$39,A15,'Elektrik Güç Tablosu'!$L$5:$L$39) -> 1.01 | F15: =IF($E$17=0,0,E15/$E$17) -> 0.017439652
A16: 2. KAT | B16: Yönetim, konferans, mescit | C16: =SUMIF('Elektrik Güç Tablosu'!$G$5:$G$39,A16,'Elektrik Güç Tablosu'!$H$5:$H$39) -> 17 | D16: =SUMIF('Elektrik Güç Tablosu'!$G$5:$G$39,A16,'Elektrik Güç Tablosu'!$K$5:$K$39) -> 1.33 | E16: =SUMIF('Elektrik Güç Tablosu'!$G$5:$G$39,A16,'Elektrik Güç Tablosu'!$L$5:$L$39) -> 1.33 | F16: =IF($E$17=0,0,E16/$E$17) -> 0.022965086
A17: TOPLAM | C17: =SUM(C14:C16) -> 66 | D17: =SUM(D14:D16) -> 60.114 | E17: =SUM(E14:E16) -> 57.914 | F17: =SUM(F14:F16) -> 1

Sheet Tablolar
A1: YARDIMCI TABLOLAR
A2: VRF iç ünite tipleri (Edirne TMO VRF projesi tip tablosu ile aynı), sigorta ve kablo seçim tabloları
A4: Tip | B4: Ünite Tipi | C4: Soğutma Kap. (kW) | D4: Isıtma Kap. (kW) | E4: Elk. Gücü (W) | F4: Boyut (mm) | H4: Sigorta seçimi: In ≥ 1,25 × Ib (C eğrisi, min. 10 A)
A5: TİP-21 | B5: Kaset Tip 4 Yöne Üflemeli | C5: 2.2 | D5: 2.5 | E5: 50 | F5: 570x570x260 | H5: Alt sınır (A) | I5: Sigorta (A) | J5: Kablo (mm², Cu)
A6: TİP-22 | B6: Kaset Tip 4 Yöne Üflemeli | C6: 2.8 | D6: 3.2 | E6: 50 | F6: 570x570x260 | H6: 0 | I6: 10 | J6: 2,5
A7: TİP-23 | B7: Kaset Tip 4 Yöne Üflemeli | C7: 3.6 | D7: 4 | E7: 60 | F7: 570x570x260 | H7: 10 | I7: 16 | J7: 2,5
A8: TİP-24 | B8: Kaset Tip 4 Yöne Üflemeli | C8: 4.5 | D8: 5 | E8: 60 | F8: 570x570x260 | H8: 16 | I8: 20 | J8: 2,5
A9: TİP-25 | B9: Kaset Tip 4 Yöne Üflemeli | C9: 5.6 | D9: 6.3 | E9: 62 | F9: 570x570x260 | H9: 20 | I9: 25 | J9: 4
A10: TİP-26 | B10: Kaset Tip 4 Yöne Üflemeli | C10: 7.1 | D10: 8 | E10: 62 | F10: 840x840x204 | H10: 25 | I10: 32 | J10: 6
H11: 32 | I11: 40 | J11: 10
H12: 40 | I12: 50 | J12: 10
H13: 50 | I13: 63 | J13: 16
H14: 63 | I14: 80 | J14: 25
H17: Not: Kablo kesitleri ön değerdir; gerilim düşümü ve döşeme koşullarına göre elektrik projesinde kesinleştirilecektir.

Sheet Soğutma Yükü
A1: OFİS VE ÇALIŞMA MAHALLERİ SOĞUTMA YÜKÜ HESABI
A2: TMO MARDİN BAŞMÜDÜRLÜĞÜ HİZMET BİNASI — Mekanik Tesisat — Ön proje, CLTD/CLF basitleştirilmiş yöntem (ASHRAE), mahal bazında pik yük
A4: TASARIM ŞARTLARI VE KATSAYILAR | H4: CEPHE YÖNLERİ (kuzey oku planda sağ-alt, ≈ -53°) | O4: MAHAL TİPİ İÇ YÜKLERİ
A5: Dış tasarım sıcaklığı (KT) [°C] | D5: 38.5 | E5: Mardin yaz %0,4 tasarım değeri (≈38,5 °C KT / 20,5 °C YT) | H5: Plan cephesi | I5: Yön | J5: Azimut (°) | K5: SHGF maks. (W/m²) | L5: Duvar ΔTeş (K) | O5: Mahal tipi | P5: Kişi yoğ. (m²/kişi) | Q5: Sabit kişi | R5: Duyulur (W/kişi) | S5: Gizli (W/kişi) | T5: Cihaz (W/m²)
A6: İç tasarım sıcaklığı [°C] | D6: 24 | E6: %50 bağıl nem | H6: Alt (giriş) | I6: KD | J6: 37 | K6: 470 | L6: 10 | O6: OFİS | P6: 10 | R6: 75 | S6: 55 | T6: 15
A7: Cam U değeri [W/m²K] | D7: 1.8 | E7: Low-e ısıcam | H7: Üst | I7: GB | J7: 217 | K7: 500 | L7: 17 | O7: MAKAM | Q7: 6 | R7: 75 | S7: 55 | T7: 15
A8: Gölgeleme katsayısı SC [-] | D8: 0.55 | E8: Low-e cam + iç perde/stor | H8: Sağ | I8: KB | J8: 307 | K8: 520 | L8: 15 | O8: SEKRETERYA | Q8: 3 | R8: 75 | S8: 55 | T8: 20
A9: Cam soğutma yükü faktörü CLF [-] | D9: 0.7 | E9: İç gölgelemeli, orta ağırlıkta yapı, pik saat | H9: Sol | I9: GD | J9: 127 | K9: 500 | L9: 13 | O9: KONFERANS | P9: 2 | R9: 70 | S9: 45 | T9: 8
A10: Dış duvar U değeri [W/m²K] | D10: 0.5 | E10: TS 825 2. bölge | O10: MESCİT | P10: 1.5 | R10: 75 | S10: 55 | T10: 0
A11: Çatı arası tavan U değeri [W/m²K] | D11: 0.4 | E11: Sadece 2. kat mahalleri | H11: SHGF: 37° K enlemi, Temmuz, saatlik maksimum güneş ısı kazancı faktörü; ΔTeş: orta ağırlıklı duvar CLTD (renk/enlem düzeltmeli). | O11: YEMEKHANE | P11: 1.5 | R11: 80 | S11: 80 | T11: 5
A12: Çatı eşdeğer sıcaklık farkı [K] | D12: 22 | E12: Havalandırmalı kiremit çatı arası | O12: ÇOCUK | P12: 4 | R12: 65 | S12: 45 | T12: 8
A13: Kat yüksekliği (cephe) [m] | D13: 4 | E13: Kotlar: +1,20 / +5,20 / +9,20 | O13: MİSAFİRHANE | Q13: 2 | R13: 70 | S13: 45 | T13: 6
A14: Net mahal yüksekliği [m] | D14: 3 | E14: Asma tavan altı | O14: DİNLENME | P14: 3 | R14: 70 | S14: 45 | T14: 8
A15: İnfiltrasyon [1/h] | D15: 0.5 | O15: GÜVENLİK | Q15: 2 | R15: 75 | S15: 55 | T15: 25
A16: Aydınlatma yükü [W/m²] | D16: 10 | E16: LED armatür
A17: Emniyet katsayısı [-] | D17: 1.1
A18: Kat | B18: Mahal No | C18: Mahal Adı | D18: Mahal Tipi | E18: Alan (m²) | F18: Kişi Sayısı | G18: Dış Duvar KD (m) | H18: Cam KD (m²) | I18: Dış Duvar GB (m) | J18: Cam GB (m²) | K18: Dış Duvar KB (m) | L18: Cam KB (m²) | M18: Dış Duvar GD (m) | N18: Cam GD (m²) | O18: Çatı Altı (1/0) | P18: Pencereler | Q18: Q Cam Güneş (W) | R18: Q Cam İletim (W) | S18: Q Dış Duvar (W) | T18: Q Çatı (W) | U18: Q İnsan Duyulur (W) | V18: Q Aydınlatma (W) | W18: Q Cihaz (W) | X18: Q İnfiltrasyon (W) | Y18: Toplam Duyulur (W) | Z18: Toplam Gizli (W) | AA18: TOPLAM SOĞUTMA YÜKÜ (kW) (emniyetli) | AB18: Birim Yük (W/m²) | AC18: SHR (-)
A19: ZEMİN KAT | B19: 04 | C19: GÜVENLİK-DANIŞMA | D19: GÜVENLİK | E19: 8.35 | F19: 2 | G19: 0 | H19: 0 | I19: 0 | J19: 0 | K19: 0 | L19: 0 | M19: 0 | N19: 0 | O19: 0 | P19: pencere yok (iç mahal) | Q19: =(H19*$K$6+J19*$K$7+L19*$K$8+N19*$K$9)*$D$8*$D$9 -> 0 | R19: =(H19+J19+L19+N19)*$D$7*($D$5-$D$6) -> 0 | S19: =(MAX(G19*$D$13-H19,0)*$L$6+MAX(I19*$D$13-J19,0)*$L$7+MAX(K19*$D$13-L19,0)*$L$8+MAX(M19*$D$13-N19,0)*$L$9)*$D$10 -> 0 | T19: =O19*E19*$D$11*$D$12 -> 0 | U19: =F19*INDEX($R$6:$R$15,MATCH($D19,$O$6:$O$15,0)) -> 150 | V19: =E19*$D$16 -> 83.5 | W19: =E19*INDEX($T$6:$T$15,MATCH($D19,$O$6:$O$15,0)) -> 208.75 | X19: =0.335*$D$15*E19*$D$14*($D$5-$D$6) -> 60.840187 | Y19: =SUM(Q19:X19) -> 503.09019 | Z19: =F19*INDEX($S$6:$S$15,MATCH($D19,$O$6:$O$15,0)) -> 110 | AA19: =(Y19+Z19)*$D$17/1000 -> 0.67439921 | AB19: =AA19*1000/E19 -> 80.766372 | AC19: =Y19/(Y19+Z19) -> 0.82058105
A20: ZEMİN KAT | B20: 09/A | C20: YEMEKHANE | D20: YEMEKHANE | E20: 42.5 | F20: 29 | G20: 6.6 | H20: 14.7 | I20: 0 | J20: 0 | K20: 0 | L20: 0 | M20: 0 | N20: 0 | O20: 0 | P20: KD: AL1 140x350 + AL1 140x350 + AL1 140x350 | Q20: =(H20*$K$6+J20*$K$7+L20*$K$8+N20*$K$9)*$D$8*$D$9 -> 2659.965 | R20: =(H20+J20+L20+N20)*$D$7*($D$5-$D$6) -> 383.67 | S20: =(MAX(G20*$D$13-H20,0)*$L$6+MAX(I20*$D$13-J20,0)*$L$7+MAX(K20*$D$13-L20,0)*$L$8+MAX(M20*$D$13-N20,0)*$L$9)*$D$10 -> 58.5 | T20: =O20*E20*$D$11*$D$12 -> 0 | U20: =F20*INDEX($R$6:$R$15,MATCH($D20,$O$6:$O$15,0)) -> 2320 | V20: =E20*$D$16 -> 425 | W20: =E20*INDEX($T$6:$T$15,MATCH($D20,$O$6:$O$15,0)) -> 212.5 | X20: =0.335*$D$15*E20*$D$14*($D$5-$D$6) -> 309.66562 | Y20: =SUM(Q20:X20) -> 6369.3006 | Z20: =F20*INDEX($S$6:$S$15,MATCH($D20,$O$6:$O$15,0)) -> 2320 | AA20: =(Y20+Z20)*$D$17/1000 -> 9.5582307 | AB20: =AA20*1000/E20 -> 224.89955 | AC20: =Y20/(Y20+Z20) -> 0.73300498
A21: ZEMİN KAT | B21: 28 | C21: DİNLENME ALANI | D21: DİNLENME | E21: 19.7 | F21: 7 | G21: 2.75 | H21: 4.9 | I21: 0 | J21: 0 | K21: 0 | L21: 0 | M21: 0 | N21: 0 | O21: 0 | P21: KD: AL1 140x350 | Q21: =(H21*$K$6+J21*$K$7+L21*$K$8+N21*$K$9)*$D$8*$D$9 -> 886.655 | R21: =(H21+J21+L21+N21)*$D$7*($D$5-$D$6) -> 127.89 | S21: =(MAX(G21*$D$13-H21,0)*$L$6+MAX(I21*$D$13-J21,0)*$L$7+MAX(K21*$D$13-L21,0)*$L$8+MAX(M21*$D$13-N21,0)*$L$9)*$D$10 -> 30.5 | T21: =O21*E21*$D$11*$D$12 -> 0 | U21: =F21*INDEX($R$6:$R$15,MATCH($D21,$O$6:$O$15,0)) -> 490 | V21: =E21*$D$16 -> 197 | W21: =E21*INDEX($T$6:$T$15,MATCH($D21,$O$6:$O$15,0)) -> 157.6 | X21: =0.335*$D$15*E21*$D$14*($D$5-$D$6) -> 143.53913 | Y21: =SUM(Q21:X21) -> 2033.1841 | Z21: =F21*INDEX($S$6:$S$15,MATCH($D21,$O$6:$O$15,0)) -> 315 | AA21: =(Y21+Z21)*$D$17/1000 -> 2.5830025 | AB21: =AA21*1000/E21 -> 131.11688 | AC21: =Y21/(Y21+Z21) -> 0.86585379
A22: ZEMİN KAT | B22: 24/A | C22: MİSAFİRHANE-1 | D22: MİSAFİRHANE | E22: 17.66 | F22: 2 | G22: 0 | H22: 0 | I22: 3.55 | J22: 5.12 | K22: 0 | L22: 0 | M22: 0 | N22: 0 | O22: 0 | P22: GB: P3 160x320 | Q22: =(H22*$K$6+J22*$K$7+L22*$K$8+N22*$K$9)*$D$8*$D$9 -> 985.6 | R22: =(H22+J22+L22+N22)*$D$7*($D$5-$D$6) -> 133.632 | S22: =(MAX(G22*$D$13-H22,0)*$L$6+MAX(I22*$D$13-J22,0)*$L$7+MAX(K22*$D$13-L22,0)*$L$8+MAX(M22*$D$13-N22,0)*$L$9)*$D$10 -> 77.18 | T22: =O22*E22*$D$11*$D$12 -> 0 | U22: =F22*INDEX($R$6:$R$15,MATCH($D22,$O$6:$O$15,0)) -> 140 | V22: =E22*$D$16 -> 176.6 | W22: =E22*INDEX($T$6:$T$15,MATCH($D22,$O$6:$O$15,0)) -> 105.96 | X22: =0.335*$D$15*E22*$D$14*($D$5-$D$6) -> 128.67517 | Y22: =SUM(Q22:X22) -> 1747.6472 | Z22: =F22*INDEX($S$6:$S$15,MATCH($D22,$O$6:$O$15,0)) -> 90 | AA22: =(Y22+Z22)*$D$17/1000 -> 2.0214119 | AB22: =AA22*1000/E22 -> 114.46273 | AC22: =Y22/(Y22+Z22) -> 0.95102433
A23: ZEMİN KAT | B23: 25/A | C23: MİSAFİRHANE-2 | D23: MİSAFİRHANE | E23: 22.15 | F23: 2 | G23: 0 | H23: 0 | I23: 3.65 | J23: 5.12 | K23: 3.22 | L23: 0 | M23: 0 | N23: 0 | O23: 0 | P23: GB: P3 160x320 | Q23: =(H23*$K$6+J23*$K$7+L23*$K$8+N23*$K$9)*$D$8*$D$9 -> 985.6 | R23: =(H23+J23+L23+N23)*$D$7*($D$5-$D$6) -> 133.632 | S23: =(MAX(G23*$D$13-H23,0)*$L$6+MAX(I23*$D$13-J23,0)*$L$7+MAX(K23*$D$13-L23,0)*$L$8+MAX(M23*$D$13-N23,0)*$L$9)*$D$10 -> 177.18 | T23: =O23*E23*$D$11*$D$12 -> 0 | U23: =F23*INDEX($R$6:$R$15,MATCH($D23,$O$6:$O$15,0)) -> 140 | V23: =E23*$D$16 -> 221.5 | W23: =E23*INDEX($T$6:$T$15,MATCH($D23,$O$6:$O$15,0)) -> 132.9 | X23: =0.335*$D$15*E23*$D$14*($D$5-$D$6) -> 161.39044 | Y23: =SUM(Q23:X23) -> 1952.2024 | Z23: =F23*INDEX($S$6:$S$15,MATCH($D23,$O$6:$O$15,0)) -> 90 | AA23: =(Y23+Z23)*$D$17/1000 -> 2.2464227 | AB23: =AA23*1000/E23 -> 101.41863 | AC23: =Y23/(Y23+Z23) -> 0.95592993
A24: ZEMİN KAT | B24: 26/A | C24: MİSAFİRHANE-3 | D24: MİSAFİRHANE | E24: 16.07 | F24: 2 | G24: 3.15 | H24: 4.9 | I24: 0 | J24: 0 | K24: 2.85 | L24: 0 | M24: 0 | N24: 0 | O24: 0 | P24: KD: AL1 140x350 | Q24: =(H24*$K$6+J24*$K$7+L24*$K$8+N24*$K$9)*$D$8*$D$9 -> 886.655 | R24: =(H24+J24+L24+N24)*$D$7*($D$5-$D$6) -> 127.89 | S24: =(MAX(G24*$D$13-H24,0)*$L$6+MAX(I24*$D$13-J24,0)*$L$7+MAX(K24*$D$13-L24,0)*$L$8+MAX(M24*$D$13-N24,0)*$L$9)*$D$10 -> 124 | T24: =O24*E24*$D$11*$D$12 -> 0 | U24: =F24*INDEX($R$6:$R$15,MATCH($D24,$O$6:$O$15,0)) -> 140 | V24: =E24*$D$16 -> 160.7 | W24: =E24*INDEX($T$6:$T$15,MATCH($D24,$O$6:$O$15,0)) -> 96.42 | X24: =0.335*$D$15*E24*$D$14*($D$5-$D$6) -> 117.09004 | Y24: =SUM(Q24:X24) -> 1652.755 | Z24: =F24*INDEX($S$6:$S$15,MATCH($D24,$O$6:$O$15,0)) -> 90 | AA24: =(Y24+Z24)*$D$17/1000 -> 1.9170305 | AB24: =AA24*1000/E24 -> 119.2925 | AC24: =Y24/(Y24+Z24) -> 0.94835763
A25: ZEMİN KAT | B25: 27/A | C25: MİSAFİRHANE-4 | D25: MİSAFİRHANE | E25: 16.4 | F25: 2 | G25: 3.25 | H25: 9.8 | I25: 0 | J25: 0 | K25: 0 | L25: 0 | M25: 0 | N25: 0 | O25: 0 | P25: KD: AL1 140x350 + AL1 140x350 | Q25: =(H25*$K$6+J25*$K$7+L25*$K$8+N25*$K$9)*$D$8*$D$9 -> 1773.31 | R25: =(H25+J25+L25+N25)*$D$7*($D$5-$D$6) -> 255.78 | S25: =(MAX(G25*$D$13-H25,0)*$L$6+MAX(I25*$D$13-J25,0)*$L$7+MAX(K25*$D$13-L25,0)*$L$8+MAX(M25*$D$13-N25,0)*$L$9)*$D$10 -> 16 | T25: =O25*E25*$D$11*$D$12 -> 0 | U25: =F25*INDEX($R$6:$R$15,MATCH($D25,$O$6:$O$15,0)) -> 140 | V25: =E25*$D$16 -> 164 | W25: =E25*INDEX($T$6:$T$15,MATCH($D25,$O$6:$O$15,0)) -> 98.4 | X25: =0.335*$D$15*E25*$D$14*($D$5-$D$6) -> 119.4945 | Y25: =SUM(Q25:X25) -> 2566.9845 | Z25: =F25*INDEX($S$6:$S$15,MATCH($D25,$O$6:$O$15,0)) -> 90 | AA25: =(Y25+Z25)*$D$17/1000 -> 2.922683 | AB25: =AA25*1000/E25 -> 178.21238 | AC25: =Y25/(Y25+Z25) -> 0.96612701
A26: 1. KAT | B26: 13 | C26: OFİS | D26: OFİS | E26: 42.65 | F26: 5 | G26: 0 | H26: 0 | I26: 6.2 | J26: 10.24 | K26: 0 | L26: 0 | M26: 5.99 | N26: 0 | O26: 0 | P26: GB: P3 160x320 + P3 160x320 | Q26: =(H26*$K$6+J26*$K$7+L26*$K$8+N26*$K$9)*$D$8*$D$9 -> 1971.2 | R26: =(H26+J26+L26+N26)*$D$7*($D$5-$D$6) -> 267.264 | S26: =(MAX(G26*$D$13-H26,0)*$L$6+MAX(I26*$D$13-J26,0)*$L$7+MAX(K26*$D$13-L26,0)*$L$8+MAX(M26*$D$13-N26,0)*$L$9)*$D$10 -> 279.5 | T26: =O26*E26*$D$11*$D$12 -> 0 | U26: =F26*INDEX($R$6:$R$15,MATCH($D26,$O$6:$O$15,0)) -> 375 | V26: =E26*$D$16 -> 426.5 | W26: =E26*INDEX($T$6:$T$15,MATCH($D26,$O$6:$O$15,0)) -> 639.75 | X26: =0.335*$D$15*E26*$D$14*($D$5-$D$6) -> 310.75856 | Y26: =SUM(Q26:X26) -> 4269.9726 | Z26: =F26*INDEX($S$6:$S$15,MATCH($D26,$O$6:$O$15,0)) -> 275 | AA26: =(Y26+Z26)*$D$17/1000 -> 4.9994698 | AB26: =AA26*1000/E26 -> 117.22086 | AC26: =Y26/(Y26+Z26) -> 0.93949358
A27: 1. KAT | B27: 14 | C27: ÇOCUK BAKIM/OYUN | D27: ÇOCUK | E27: 43.8 | F27: 11 | G27: 0 | H27: 0 | I27: 6.8 | J27: 10.24 | K27: 0 | L27: 0 | M27: 0 | N27: 0 | O27: 0 | P27: GB: P3 160x320 + P3 160x320 | Q27: =(H27*$K$6+J27*$K$7+L27*$K$8+N27*$K$9)*$D$8*$D$9 -> 1971.2 | R27: =(H27+J27+L27+N27)*$D$7*($D$5-$D$6) -> 267.264 | S27: =(MAX(G27*$D$13-H27,0)*$L$6+MAX(I27*$D$13-J27,0)*$L$7+MAX(K27*$D$13-L27,0)*$L$8+MAX(M27*$D$13-N27,0)*$L$9)*$D$10 -> 144.16 | T27: =O27*E27*$D$11*$D$12 -> 0 | U27: =F27*INDEX($R$6:$R$15,MATCH($D27,$O$6:$O$15,0)) -> 715 | V27: =E27*$D$16 -> 438 | W27: =E27*INDEX($T$6:$T$15,MATCH($D27,$O$6:$O$15,0)) -> 350.4 | X27: =0.335*$D$15*E27*$D$14*($D$5-$D$6) -> 319.13775 | Y27: =SUM(Q27:X27) -> 4205.1618 | Z27: =F27*INDEX($S$6:$S$15,MATCH($D27,$O$6:$O$15,0)) -> 495 | AA27: =(Y27+Z27)*$D$17/1000 -> 5.1701779 | AB27: =AA27*1000/E27 -> 118.04059 | AC27: =Y27/(Y27+Z27) -> 0.89468448
A28: 1. KAT | B28: 19 | C28: OFİS | D28: OFİS | E28: 27.5 | F28: 3 | G28: 0 | H28: 0 | I28: 4 | J28: 5.12 | K28: 0 | L28: 0 | M28: 0 | N28: 0 | O28: 0 | P28: GB: P3 160x320 | Q28: =(H28*$K$6+J28*$K$7+L28*$K$8+N28*$K$9)*$D$8*$D$9 -> 985.6 | R28: =(H28+J28+L28+N28)*$D$7*($D$5-$D$6) -> 133.632 | S28: =(MAX(G28*$D$13-H28,0)*$L$6+MAX(I28*$D$13-J28,0)*$L$7+MAX(K28*$D$13-L28,0)*$L$8+MAX(M28*$D$13-N28,0)*$L$9)*$D$10 -> 92.48 | T28: =O28*E28*$D$11*$D$12 -> 0 | U28: =F28*INDEX($R$6:$R$15,MATCH($D28,$O$6:$O$15,0)) -> 225 | V28: =E28*$D$16 -> 275 | W28: =E28*INDEX($T$6:$T$15,MATCH($D28,$O$6:$O$15,0)) -> 412.5 | X28: =0.335*$D$15*E28*$D$14*($D$5-$D$6) -> 200.37187 | Y28: =SUM(Q28:X28) -> 2324.5839 | Z28: =F28*INDEX($S$6:$S$15,MATCH($D28,$O$6:$O$15,0)) -> 165 | AA28: =(Y28+Z28)*$D$17/1000 -> 2.7385423 | AB28: =AA28*1000/E28 -> 99.583355 | AC28: =Y28/(Y28+Z28) -> 0.93372386
A29: 1. KAT | B29: 20 | C29: OFİS | D29: OFİS | E29: 24.15 | F29: 3 | G29: 0 | H29: 0 | I29: 3.5 | J29: 5.12 | K29: 6.77 | L29: 5.12 | M29: 0 | N29: 0 | O29: 0 | P29: GB: P3 160x320; KB: P3 160x320 | Q29: =(H29*$K$6+J29*$K$7+L29*$K$8+N29*$K$9)*$D$8*$D$9 -> 2010.624 | R29: =(H29+J29+L29+N29)*$D$7*($D$5-$D$6) -> 267.264 | S29: =(MAX(G29*$D$13-H29,0)*$L$6+MAX(I29*$D$13-J29,0)*$L$7+MAX(K29*$D$13-L29,0)*$L$8+MAX(M29*$D$13-N29,0)*$L$9)*$D$10 -> 240.18 | T29: =O29*E29*$D$11*$D$12 -> 0 | U29: =F29*INDEX($R$6:$R$15,MATCH($D29,$O$6:$O$15,0)) -> 225 | V29: =E29*$D$16 -> 241.5 | W29: =E29*INDEX($T$6:$T$15,MATCH($D29,$O$6:$O$15,0)) -> 362.25 | X29: =0.335*$D$15*E29*$D$14*($D$5-$D$6) -> 175.96294 | Y29: =SUM(Q29:X29) -> 3522.7809 | Z29: =F29*INDEX($S$6:$S$15,MATCH($D29,$O$6:$O$15,0)) -> 165 | AA29: =(Y29+Z29)*$D$17/1000 -> 4.056559 | AB29: =AA29*1000/E29 -> 167.97346 | AC29: =Y29/(Y29+Z29) -> 0.95525765
A30: 1. KAT | B30: 06 | C30: OFİS | D30: OFİS | E30: 21.8 | F30: 3 | G30: 3.33 | H30: 4.9 | I30: 0 | J30: 0 | K30: 6.4 | L30: 5.12 | M30: 0 | N30: 0 | O30: 0 | P30: KD: AL1 140x350; KB: P3 160x320 | Q30: =(H30*$K$6+J30*$K$7+L30*$K$8+N30*$K$9)*$D$8*$D$9 -> 1911.679 | R30: =(H30+J30+L30+N30)*$D$7*($D$5-$D$6) -> 261.522 | S30: =(MAX(G30*$D$13-H30,0)*$L$6+MAX(I30*$D$13-J30,0)*$L$7+MAX(K30*$D$13-L30,0)*$L$8+MAX(M30*$D$13-N30,0)*$L$9)*$D$10 -> 195.7 | T30: =O30*E30*$D$11*$D$12 -> 0 | U30: =F30*INDEX($R$6:$R$15,MATCH($D30,$O$6:$O$15,0)) -> 225 | V30: =E30*$D$16 -> 218 | W30: =E30*INDEX($T$6:$T$15,MATCH($D30,$O$6:$O$15,0)) -> 327 | X30: =0.335*$D$15*E30*$D$14*($D$5-$D$6) -> 158.84025 | Y30: =SUM(Q30:X30) -> 3297.7413 | Z30: =F30*INDEX($S$6:$S$15,MATCH($D30,$O$6:$O$15,0)) -> 165 | AA30: =(Y30+Z30)*$D$17/1000 -> 3.8090154 | AB30: =AA30*1000/E30 -> 174.72548 | AC30: =Y30/(Y30+Z30) -> 0.95234989
... A48: 2. KAT | B48: 13 | C48: MÜDÜR YARD. ODASI | D48: MAKAM | E48: 21.92 | F48: 6 | G48: 3.42 | H48: 4.9 | I48: 0 | J48: 0 | K48: 0 | L48: 0 | M48: 6.4 | N48: 5.12 | O48: 1 | P48: KD: AL1 140x350; GD: P3 160x320 | Q48: =(H48*$K$6+J48*$K$7+L48*$K$8+N48*$K$9)*$D$8*$D$9 -> 1872.255 | R48: =(H48+J48+L48+N48)*$D$7*($D$5-$D$6) -> 261.522 | S48: =(MAX(G48*$D$13-H48,0)*$L$6+MAX(I48*$D$13-J48,0)*$L$7+MAX(K48*$D$13-L48,0)*$L$8+MAX(M48*$D$13-N48,0)*$L$9)*$D$10 -> 177.02 | T48: =O48*E48*$D$11*$D$12 -> 192.896 | U48: =F48*INDEX($R$6:$R$15,MATCH($D48,$O$6:$O$15,0)) -> 450 | V48: =E48*$D$16 -> 219.2 | W48: =E48*INDEX($T$6:$T$15,MATCH($D48,$O$6:$O$15,0)) -> 328.8 | X48: =0.335*$D$15*E48*$D$14*($D$5-$D$6) -> 159.7146 | Y48: =SUM(Q48:X48) -> 3661.4076 | Z48: =F48*INDEX($S$6:$S$15,MATCH($D48,$O$6:$O$15,0)) -> 330 | AA48: =(Y48+Z48)*$D$17/1000 -> 4.3905484 | AB48: =AA48*1000/E48 -> 200.29874 | AC48: =Y48/(Y48+Z48) -> 0.9173224
C49: TOPLAM | E49: =SUM(E19:E48) -> 763.04 | F49: =SUM(F19:F48) -> 175 | Q49: =SUM(Q19:Q48) -> 44516.241 | R49: =SUM(R19:R48) -> 6244.686 | S49: =SUM(S19:S48) -> 3050.18 | T49: =SUM(T19:T48) -> 2752.2 | U49: =SUM(U19:U48) -> 12975 | V49: =SUM(V19:V48) -> 7630.4 | W49: =SUM(W19:W48) -> 9305.53 | X49: =SUM(X19:X48) -> 5559.7002 | ... AA49: =SUM(AA19:AA48) -> 112.09433 | AB49: =AA49*1000/E49 -> 146.90492
A51: Yöntem: Q güneş = A·SHGF·SC·CLF ; Q iletim = U·A·ΔT ; Q duvar = U·A_net·ΔTeş ; Q insan = n·(qd+qg) ; Q infiltrasyon = 0,335·n·V·ΔT. Toplam = (duyulur + gizli) × emniyet.
A52: Mardin yaz havası kurudur (dış ≈ 8 g/kg < iç 24 °C %50 ≈ 9,3 g/kg); infiltrasyon gizli yükü ihmal edilmiştir.
A53: Dış duvar boyları ve pencere alanları TEMİZ_1.dxf planından (mahal sınırı, P3 160x320, AL1/AL5 140 genişlik şerit pencere — kat başına 3,50 m etkin cam yüksekliği) alınmıştır.
A54: Yük mahal bazında pik (eş zamansız) değerdir; dış ünite seçiminde iç ünite toplamı / dış ünite kombinasyon oranı %100-%115 alınmıştır.
A55: Mavi hücreler girdi olup değiştirildiğinde tüm yükler ve "VRF İç Üniteler" sayfasındaki kapasite kontrolü yeniden hesaplanır.

Sheet VRF İç Üniteler
A1: VRF İÇ ÜNİTE SEÇİM TABLOSU (KASET TİP 4 YÖNE ÜFLEMELİ)
A2: TMO MARDİN BAŞMÜDÜRLÜĞÜ HİZMET BİNASI — Mekanik Tesisat — Ofis ve çalışma mahalleri
A4: Kat | B4: Mahal No | C4: Mahal Adı | D4: Alan (m²) | E4: Birim Soğ. Yükü (W/m²) | F4: Hesaplanan Soğ. Yükü (kW) | G4: Ünite Tipi | H4: Adet | I4: Birim Soğ. Kap. (kW) | J4: Toplam Soğ. Kap. (kW) | K4: Kontrol | L4: Toplam Isıt. Kap. (kW) | M4: Birim Elk. (W) | N4: Toplam Elk. (kW) | O4: VRF Sistemi | P4: Pano
A5: ZEMİN KAT | B5: 04 | C5: GÜVENLİK-DANIŞMA | D5: 8.35 | E5: ='Soğutma Yükü'!AB19 -> 80.766372 | F5: ='Soğutma Yükü'!AA19 -> 0.67439921 | G5: TİP-21 | H5: 1 | I5: =INDEX(Tablolar!$C$5:$C$10,MATCH(G5,Tablolar!$A$5:$A$10,0)) -> 2.2 | J5: =H5*I5 -> 2.2 | K5: =IF(J5>=F5,"UYGUN","KAPASİTE ARTIR") -> UYGUN | L5: =H5*INDEX(Tablolar!$D$5:$D$10,MATCH(G5,Tablolar!$A$5:$A$10,0)) -> 2.5 | M5: =INDEX(Tablolar!$E$5:$E$10,MATCH(G5,Tablolar!$A$5:$A$10,0)) -> 50 | N5: =H5*M5/1000 -> 0.05 | O5: VRF-1 | P5: ZKTP
A6: ZEMİN KAT | B6: 09/A | C6: YEMEKHANE | D6: 42.5 | E6: ='Soğutma Yükü'!AB20 -> 224.89955 | F6: ='Soğutma Yükü'!AA20 -> 9.5582307 | G6: TİP-25 | H6: 2 | I6: =INDEX(Tablolar!$C$5:$C$10,MATCH(G6,Tablolar!$A$5:$A$10,0)) -> 5.6 | J6: =H6*I6 -> 11.2 | K6: =IF(J6>=F6,"UYGUN","KAPASİTE ARTIR") -> UYGUN | L6: =H6*INDEX(Tablolar!$D$5:$D$10,MATCH(G6,Tablolar!$A$5:$A$10,0)) -> 12.6 | M6: =INDEX(Tablolar!$E$5:$E$10,MATCH(G6,Tablolar!$A$5:$A$10,0)) -> 62 | N6: =H6*M6/1000 -> 0.124 | O6: VRF-1 | P6: ZKTP
A7: ZEMİN KAT | B7: 28 | C7: DİNLENME ALANI | D7: 19.7 | E7: ='Soğutma Yükü'!AB21 -> 131.11688 | F7: ='Soğutma Yükü'!AA21 -> 2.5830025 | G7: TİP-22 | H7: 1 | I7: =INDEX(Tablolar!$C$5:$C$10,MATCH(G7,Tablolar!$A$5:$A$10,0)) -> 2.8 | J7: =H7*I7 -> 2.8 | K7: =IF(J7>=F7,"UYGUN","KAPASİTE ARTIR") -> UYGUN | L7: =H7*INDEX(Tablolar!$D$5:$D$10,MATCH(G7,Tablolar!$A$5:$A$10,0)) -> 3.2 | M7: =INDEX(Tablolar!$E$5:$E$10,MATCH(G7,Tablolar!$A$5:$A$10,0)) -> 50 | N7: =H7*M7/1000 -> 0.05 | O7: VRF-1 | P7: ZKTP
A8: ZEMİN KAT | B8: 24/A | C8: MİSAFİRHANE-1 | D8: 17.66 | E8: ='Soğutma Yükü'!AB22 -> 114.46273 | F8: ='Soğutma Yükü'!AA22 -> 2.0214119 | G8: TİP-21 | H8: 1 | I8: =INDEX(Tablolar!$C$5:$C$10,MATCH(G8,Tablolar!$A$5:$A$10,0)) -> 2.2 | J8: =H8*I8 -> 2.2 | K8: =IF(J8>=F8,"UYGUN","KAPASİTE ARTIR") -> UYGUN | L8: =H8*INDEX(Tablolar!$D$5:$D$10,MATCH(G8,Tablolar!$A$5:$A$10,0)) -> 2.5 | M8: =INDEX(Tablolar!$E$5:$E$10,MATCH(G8,Tablolar!$A$5:$A$10,0)) -> 50 | N8: =H8*M8/1000 -> 0.05 | O8: VRF-1 | P8: ZKTP
A9: ZEMİN KAT | B9: 25/A | C9: MİSAFİRHANE-2 | D9: 22.15 | E9: ='Soğutma Yükü'!AB23 -> 101.41863 | F9: ='Soğutma Yükü'!AA23 -> 2.2464227 | G9: TİP-22 | H9: 1 | I9: =INDEX(Tablolar!$C$5:$C$10,MATCH(G9,Tablolar!$A$5:$A$10,0)) -> 2.8 | J9: =H9*I9 -> 2.8 | K9: =IF(J9>=F9,"UYGUN","KAPASİTE ARTIR") -> UYGUN | L9: =H9*INDEX(Tablolar!$D$5:$D$10,MATCH(G9,Tablolar!$A$5:$A$10,0)) -> 3.2 | M9: =INDEX(Tablolar!$E$5:$E$10,MATCH(G9,Tablolar!$A$5:$A$10,0)) -> 50 | N9: =H9*M9/1000 -> 0.05 | O9: VRF-1 | P9: ZKTP
A10: ZEMİN KAT | B10: 26/A | C10: MİSAFİRHANE-3 | D10: 16.07 | E10: ='Soğutma Yükü'!AB24 -> 119.2925 | F10: ='Soğutma Yükü'!AA24 -> 1.9170305 | G10: TİP-21 | H10: 1 | I10: =INDEX(Tablolar!$C$5:$C$10,MATCH(G10,Tablolar!$A$5:$A$10,0)) -> 2.2 | J10: =H10*I10 -> 2.2 | K10: =IF(J10>=F10,"UYGUN","KAPASİTE ARTIR") -> UYGUN | L10: =H10*INDEX(Tablolar!$D$5:$D$10,MATCH(G10,Tablolar!$A$5:$A$10,0)) -> 2.5 | M10: =INDEX(Tablolar!$E$5:$E$10,MATCH(G10,Tablolar!$A$5:$A$10,0)) -> 50 | N10: =H10*M10/1000 -> 0.05 | O10: VRF-1 | P10: ZKTP
A11: ZEMİN KAT | B11: 27/A | C11: MİSAFİRHANE-4 | D11: 16.4 | E11: ='Soğutma Yükü'!AB25 -> 178.21238 | F11: ='Soğutma Yükü'!AA25 -> 2.922683 | G11: TİP-23 | H11: 1 | I11: =INDEX(Tablolar!$C$5:$C$10,MATCH(G11,Tablolar!$A$5:$A$10,0)) -> 3.6 | J11: =H11*I11 -> 3.6 | K11: =IF(J11>=F11,"UYGUN","KAPASİTE ARTIR") -> UYGUN | L11: =H11*INDEX(Tablolar!$D$5:$D$10,MATCH(G11,Tablolar!$A$5:$A$10,0)) -> 4 | M11: =INDEX(Tablolar!$E$5:$E$10,MATCH(G11,Tablolar!$A$5:$A$10,0)) -> 60 | N11: =H11*M11/1000 -> 0.06 | O11: VRF-1 | P11: ZKTP
A12: 1. KAT | B12: 13 | C12: OFİS | D12: 42.65 | E12: ='Soğutma Yükü'!AB26 -> 117.22086 | F12: ='Soğutma Yükü'!AA26 -> 4.9994698 | G12: TİP-22 | H12: 2 | I12: =INDEX(Tablolar!$C$5:$C$10,MATCH(G12,Tablolar!$A$5:$A$10,0)) -> 2.8 | J12: =H12*I12 -> 5.6 | K12: =IF(J12>=F12,"UYGUN","KAPASİTE ARTIR") -> UYGUN | L12: =H12*INDEX(Tablolar!$D$5:$D$10,MATCH(G12,Tablolar!$A$5:$A$10,0)) -> 6.4 | M12: =INDEX(Tablolar!$E$5:$E$10,MATCH(G12,Tablolar!$A$5:$A$10,0)) -> 50 | N12: =H12*M12/1000 -> 0.1 | O12: VRF-1 | P12: 1KTP
A13: 1. KAT | B13: 14 | C13: ÇOCUK BAKIM/OYUN | D13: 43.8 | E13: ='Soğutma Yükü'!AB27 -> 118.04059 | F13: ='Soğutma Yükü'!AA27 -> 5.1701779 | G13: TİP-22 | H13: 2 | I13: =INDEX(Tablolar!$C$5:$C$10,MATCH(G13,Tablolar!$A$5:$A$10,0)) -> 2.8 | J13: =H13*I13 -> 5.6 | K13: =IF(J13>=F13,"UYGUN","KAPASİTE ARTIR") -> UYGUN | L13: =H13*INDEX(Tablolar!$D$5:$D$10,MATCH(G13,Tablolar!$A$5:$A$10,0)) -> 6.4 | M13: =INDEX(Tablolar!$E$5:$E$10,MATCH(G13,Tablolar!$A$5:$A$10,0)) -> 50 | N13: =H13*M13/1000 -> 0.1 | O13: VRF-1 | P13: 1KTP
A14: 1. KAT | B14: 19 | C14: OFİS | D14: 27.5 | E14: ='Soğutma Yükü'!AB28 -> 99.583355 | F14: ='Soğutma Yükü'!AA28 -> 2.7385423 | G14: TİP-22 | H14: 1 | I14: =INDEX(Tablolar!$C$5:$C$10,MATCH(G14,Tablolar!$A$5:$A$10,0)) -> 2.8 | J14: =H14*I14 -> 2.8 | K14: =IF(J14>=F14,"UYGUN","KAPASİTE ARTIR") -> UYGUN | L14: =H14*INDEX(Tablolar!$D$5:$D$10,MATCH(G14,Tablolar!$A$5:$A$10,0)) -> 3.2 | M14: =INDEX(Tablolar!$E$5:$E$10,MATCH(G14,Tablolar!$A$5:$A$10,0)) -> 50 | N14: =H14*M14/1000 -> 0.05 | O14: VRF-1 | P14: 1KTP
A15: 1. KAT | B15: 20 | C15: OFİS | D15: 24.15 | E15: ='Soğutma Yükü'!AB29 -> 167.97346 | F15: ='Soğutma Yükü'!AA29 -> 4.056559 | G15: TİP-24 | H15: 1 | I15: =INDEX(Tablolar!$C$5:$C$10,MATCH(G15,Tablolar!$A$5:$A$10,0)) -> 4.5 | J15: =H15*I15 -> 4.5 | K15: =IF(J15>=F15,"UYGUN","KAPASİTE ARTIR") -> UYGUN | L15: =H15*INDEX(Tablolar!$D$5:$D$10,MATCH(G15,Tablolar!$A$5:$A$10,0)) -> 5 | M15: =INDEX(Tablolar!$E$5:$E$10,MATCH(G15,Tablolar!$A$5:$A$10,0)) -> 60 | N15: =H15*M15/1000 -> 0.06 | O15: VRF-1 | P15: 1KTP
A16: 1. KAT | B16: 06 | C16: OFİS | D16: 21.8 | E16: ='Soğutma Yükü'!AB30 -> 174.72548 | F16: ='Soğutma Yükü'!AA30 -> 3.8090154 | G16: TİP-24 | H16: 1 | I16: =INDEX(Tablolar!$C$5:$C$10,MATCH(G16,Tablolar!$A$5:$A$10,0)) -> 4.5 | J16: =H16*I16 -> 4.5 | K16: =IF(J16>=F16,"UYGUN","KAPASİTE ARTIR") -> UYGUN | L16: =H16*INDEX(Tablolar!$D$5:$D$10,MATCH(G16,Tablolar!$A$5:$A$10,0)) -> 5 | M16: =INDEX(Tablolar!$E$5:$E$10,MATCH(G16,Tablolar!$A$5:$A$10,0)) -> 60 | N16: =H16*M16/1000 -> 0.06 | O16: VRF-1 | P16: 1KTP
... A34: 2. KAT | B34: 13 | C34: MÜDÜR YARD. ODASI | D34: 21.92 | E34: ='Soğutma Yükü'!AB48 -> 200.29874 | F34: ='Soğutma Yükü'!AA48 -> 4.3905484 | G34: TİP-24 | H34: 1 | I34: =INDEX(Tablolar!$C$5:$C$10,MATCH(G34,Tablolar!$A$5:$A$10,0)) -> 4.5 | J34: =H34*I34 -> 4.5 | K34: =IF(J34>=F34,"UYGUN","KAPASİTE ARTIR") -> UYGUN | L34: =H34*INDEX(Tablolar!$D$5:$D$10,MATCH(G34,Tablolar!$A$5:$A$10,0)) -> 5 | M34: =INDEX(Tablolar!$E$5:$E$10,MATCH(G34,Tablolar!$A$5:$A$10,0)) -> 60 | N34: =H34*M34/1000 -> 0.06 | O34: VRF-2 | P34: 2KTP
C35: TOPLAM | D35: =SUM(D5:D34) -> 763.04 | F35: =SUM(F5:F34) -> 112.09433 | H35: =SUM(H5:H34) -> 37 | J35: =SUM(J5:J34) -> 128.2 | L35: =SUM(L5:L34) -> 143.8 | N35: =SUM(N5:N34) -> 2.074
A37: Soğutma yükü değerleri "Soğutma Yükü" sayfasındaki mahal bazında hesaptan bağlantılıdır (yeşil). Ünite tipi/adet mavi hücreleri değiştirilebilir; Kontrol sütunu kapasite yeterliliğini gösterir.
A38: Kaynak: Mahal alanları TEMİZ_1.dxf mimari mahal etiketleri; ünite tip/kapasite/güç değerleri TMO Edirne Hizmet Binası VRF projesi iç ünite seçim tablosu.

Sheet VRF Dış Üniteler
A1: VRF DIŞ ÜNİTE SEÇİM TABLOSU
A2: TMO MARDİN BAŞMÜDÜRLÜĞÜ HİZMET BİNASI — Mekanik Tesisat — Hava soğutmalı, tam DC inverter, üstten hava atışlı (bahçe, beton kaide)
A4: Sistem | B4: Modül | C4: Kapasite (HP) | D4: Soğutma Kap. (kW) | E4: Elk. Gücü (kW) | F4: Gerilim | G4: Ölçü WxDxH (mm) | H4: Hizmet Ettiği Katlar | I4: Sistem İç Ünite Toplamı (kW) | J4: Sistem Dış Ünite Toplamı (kW) | K4: Kombinasyon Oranı
A5: VRF-1 | B5: VRF-1A | C5: 12 | D5: 33.5 | E5: 13.8 | F5: 400V 3N~ 50Hz | G5: 1240x765x1690 | H5: Zemin Kat + 1. Kat | I5: =SUMIF('VRF İç Üniteler'!$O$5:$O$34,A5,'VRF İç Üniteler'!$J$5:$J$34) -> 72.2 | J5: =SUMIF($A$5:$A$7,A5,$D$5:$D$7) -> 67 | K5: =IF(J5=0,0,I5/J5) -> 1.0776119
A6: VRF-1 | B6: VRF-1B | C6: 12 | D6: 33.5 | E6: 13.8 | F6: 400V 3N~ 50Hz | G6: 1240x765x1690 | H6: Zemin Kat + 1. Kat | I6: =SUMIF('VRF İç Üniteler'!$O$5:$O$34,A6,'VRF İç Üniteler'!$J$5:$J$34) -> 72.2 | J6: =SUMIF($A$5:$A$7,A6,$D$5:$D$7) -> 67 | K6: =IF(J6=0,0,I6/J6) -> 1.0776119
A7: VRF-2 | B7: VRF-2A | C7: 18 | D7: 50 | E7: 21 | F7: 400V 3N~ 50Hz | G7: 1240x765x1690 | H7: 2. Kat | I7: =SUMIF('VRF İç Üniteler'!$O$5:$O$34,A7,'VRF İç Üniteler'!$J$5:$J$34) -> 56 | J7: =SUMIF($A$5:$A$7,A7,$D$5:$D$7) -> 50 | K7: =IF(J7=0,0,I7/J7) -> 1.12
B8: TOPLAM | C8: =SUM(C5:C7) -> 42 | D8: =SUM(D5:D7) -> 117 | E8: =SUM(E5:E7) -> 48.6
A10: Kombinasyon oranı (iç ünite toplamı / dış ünite toplamı) %50-%130 aralığında olmalıdır; Mardin yüksek dış sıcaklığı nedeniyle %110 altı tercih edilmiştir.
A11: Elektrik güçleri TMO Edirne VRF projesi dış ünite tablosundaki oran ile (≈0,42 kW elektrik / kW soğutma; 12 HP: 13,80 kW) alınmıştır; seçilen markanın katalog değeri esas alınacaktır.
A12: Dış üniteler 10 cm beton kaide üzerine, çelik kafes içinde, kuzey cephe bahçesine konulacaktır. Merkezi kumanda Z-04 Güvenlik-Danışma mahallindedir.
